Workbook

Sheet Start here
B1: ACH-04 Conductivity calibration, detection limit, and standard addition
B2: Excel version of the card. It does the same calculations as the R script ach04_conductivity_calibration.R, so you can use either.
B4: How to use this workbook
B5: 1. Go to the 'Enter data' sheet. Type only in the yellow cells with blue numbers. Everything grey is calculated for you.
B6: 2. Fill the four blocks: standards (concentration, reading, temperature), blank readings, the unknown, and the standard addition series.
B7: 3. Open the 'Results' sheet. The calibration line, detection limit, unknown concentration and the standard addition check appear there, with two charts.
B8: 4. Leave a row empty if you did not use it. You need at least 3 standards and 2 blank readings before results appear.
B10: What the colours mean
B11: Yellow cell, blue number: you type here.
B12: Grey cell: a formula. The sheets are protected without a password so formulas cannot be overwritten by accident (Review > Unprotect Sheet if you need to change one).
B13: Grey italic row above each table: an example of the format. It is not used in any calculation.
B15: Assumptions and sources
... B22: Compiled by Emmanuel G. Lozano, Department of Biology, College of Arts and Sciences, Pampanga State University. Original material is licensed CC BY-NC 4.0: credit required, non-commercial use only.

Sheet Enter data
A1: Enter your data
A2: Type only in yellow cells. Temperature is in degrees C, conductivity in microsiemens per cm (uS/cm), concentrations in mg/L.
A4: 1. Standards (salt solutions of known concentration)
A5: Concentration (mg/L) | B5: Conductivity (uS/cm) | C5: Temperature (C) | D5: Reading at 25 C (calculated)
A6: 100 | B6: 203.4 | C6: 26.5 | D6: 199.4
D7: =IF(AND(ISNUMBER(B7),ISNUMBER(C7)),B7/(1+Results!$C$5*(C7-25)),"")
D8: =IF(AND(ISNUMBER(B8),ISNUMBER(C8)),B8/(1+Results!$C$5*(C8-25)),"")
D9: =IF(AND(ISNUMBER(B9),ISNUMBER(C9)),B9/(1+Results!$C$5*(C9-25)),"")
D10: =IF(AND(ISNUMBER(B10),ISNUMBER(C10)),B10/(1+Results!$C$5*(C10-25)),"")
D11: =IF(AND(ISNUMBER(B11),ISNUMBER(C11)),B11/(1+Results!$C$5*(C11-25)),"")
D12: =IF(AND(ISNUMBER(B12),ISNUMBER(C12)),B12/(1+Results!$C$5*(C12-25)),"")
D13: =IF(AND(ISNUMBER(B13),ISNUMBER(C13)),B13/(1+Results!$C$5*(C13-25)),"")
D14: =IF(AND(ISNUMBER(B14),ISNUMBER(C14)),B14/(1+Results!$C$5*(C14-25)),"")
D15: =IF(AND(ISNUMBER(B15),ISNUMBER(C15)),B15/(1+Results!$C$5*(C15-25)),"")
D16: =IF(AND(ISNUMBER(B16),ISNUMBER(C16)),B16/(1+Results!$C$5*(C16-25)),"")
D17: =IF(AND(ISNUMBER(B17),ISNUMBER(C17)),B17/(1+Results!$C$5*(C17-25)),"")
D18: =IF(AND(ISNUMBER(B18),ISNUMBER(C18)),B18/(1+Results!$C$5*(C18-25)),"")
A21: 2. Blank readings (the clean water, several separate portions)
A22: Blank | B22: Conductivity (uS/cm) | C22: Temperature (C) | D22: Reading at 25 C (calculated)
A23: Example | B23: 3.4 | C23: 26.5 | D23: 3.3
A24: Blank 1 | D24: =IF(AND(ISNUMBER(B24),ISNUMBER(C24)),B24/(1+Results!$C$5*(C24-25)),"")
A25: Blank 2 | D25: =IF(AND(ISNUMBER(B25),ISNUMBER(C25)),B25/(1+Results!$C$5*(C25-25)),"")
A26: Blank 3 | D26: =IF(AND(ISNUMBER(B26),ISNUMBER(C26)),B26/(1+Results!$C$5*(C26-25)),"")
A27: Blank 4 | D27: =IF(AND(ISNUMBER(B27),ISNUMBER(C27)),B27/(1+Results!$C$5*(C27-25)),"")
A28: Blank 5 | D28: =IF(AND(ISNUMBER(B28),ISNUMBER(C28)),B28/(1+Results!$C$5*(C28-25)),"")
A29: Blank 6 | D29: =IF(AND(ISNUMBER(B29),ISNUMBER(C29)),B29/(1+Results!$C$5*(C29-25)),"")
A30: Blank 7 | D30: =IF(AND(ISNUMBER(B30),ISNUMBER(C30)),B30/(1+Results!$C$5*(C30-25)),"")
A31: Blank 8 | D31: =IF(AND(ISNUMBER(B31),ISNUMBER(C31)),B31/(1+Results!$C$5*(C31-25)),"")
A32: Blank 9 | D32: =IF(AND(ISNUMBER(B32),ISNUMBER(C32)),B32/(1+Results!$C$5*(C32-25)),"")
A33: Blank 10 | D33: =IF(AND(ISNUMBER(B33),ISNUMBER(C33)),B33/(1+Results!$C$5*(C33-25)),"")
A36: 3. Unknown solution (replicate readings)
A37: Reading | B37: Conductivity (uS/cm) | C37: Temperature (C) | D37: Reading at 25 C (calculated)
A38: Example | B38: 480.6 | C38: 26.5 | D38: 466.6
A39: Reading 1 | D39: =IF(AND(ISNUMBER(B39),ISNUMBER(C39)),B39/(1+Results!$C$5*(C39-25)),"")
A40: Reading 2 | D40: =IF(AND(ISNUMBER(B40),ISNUMBER(C40)),B40/(1+Results!$C$5*(C40-25)),"")
A41: Reading 3 | D41: =IF(AND(ISNUMBER(B41),ISNUMBER(C41)),B41/(1+Results!$C$5*(C41-25)),"")
A42: Reading 4 | D42: =IF(AND(ISNUMBER(B42),ISNUMBER(C42)),B42/(1+Results!$C$5*(C42-25)),"")
A43: Reading 5 | D43: =IF(AND(ISNUMBER(B43),ISNUMBER(C43)),B43/(1+Results!$C$5*(C43-25)),"")
A44: Reading 6 | D44: =IF(AND(ISNUMBER(B44),ISNUMBER(C44)),B44/(1+Results!$C$5*(C44-25)),"")
A47: 4. Standard addition (natural water sample with known amounts added)
...

Sheet Results
B1: Results
B2: Everything on this sheet is calculated. Change only the yellow settings.
B4: Settings
B5: Temperature coefficient (fraction per degree C) | C5: 0.02 | D5: Approximation from card ACH-04. Use your meter's value if known.
B6: Confidence level for the interval | C6: 0.95 | D6: 0.95 = 95 percent.
B7: Detection limit multiplier | C7: 3 | D7: Common convention: 3 x sd of blank / slope.
B8: Quantitation limit multiplier | C8: 10 | D8: Common convention: 10 x sd of blank / slope.
B10: 1. Calibration line (reading at 25 C = intercept + slope x concentration)
B11: Standards used | C11: =SUMPRODUCT(--ISNUMBER('Enter data'!$A$7:$A$18),--ISNUMBER('Enter data'!$D$7:$D$18)) -> 0
B12: Check on the rows | C12: =IF(COUNT('Enter data'!$A$7:$A$18)<>COUNT('Enter data'!$D$7:$D$18),"Some rows have a concentration or a reading but not both","OK") -> OK
B13: Slope (uS/cm per mg/L) | C13: =IF(C11<3,"Need 3+ standards",SLOPE('Enter data'!$D$7:$D$18,'Enter data'!$A$7:$A$18)) -> Need 3+ standards
B14: Intercept (uS/cm) | C14: =IF(C11<3,"",INTERCEPT('Enter data'!$D$7:$D$18,'Enter data'!$A$7:$A$18))
B15: R squared | C15: =IF(C11<3,"",RSQ('Enter data'!$D$7:$D$18,'Enter data'!$A$7:$A$18))
B16: Residual standard deviation (uS/cm) | C16: =IF(C11<3,"",STEYX('Enter data'!$D$7:$D$18,'Enter data'!$A$7:$A$18))
B18: 2. Detection and quantitation limits
B19: Blank readings used | C19: =COUNT('Enter data'!$D$24:$D$33) -> 0
B20: Standard deviation of the blank (uS/cm) | C20: =IF(C19<2,"Need 2+ blanks",STDEV('Enter data'!$D$24:$D$33)) -> Need 2+ blanks
B21: Detection limit (mg/L) | C21: =IF(OR(NOT(ISNUMBER(C20)),NOT(ISNUMBER(C13))),"",C7*C20/C13)
B22: Quantitation limit (mg/L) | C22: =IF(OR(NOT(ISNUMBER(C20)),NOT(ISNUMBER(C13))),"",C8*C20/C13)
B24: 3. Unknown solution (read from the calibration line)
B25: Replicate readings used | C25: =COUNT('Enter data'!$D$39:$D$44) -> 0
B26: Mean reading at 25 C (uS/cm) | C26: =IF(C25<1,"",AVERAGE('Enter data'!$D$39:$D$44))
B27: Concentration (mg/L) | C27: =IF(OR(C25<1,NOT(ISNUMBER(C13))),"",(C26-C14)/C13)
B28: Approximate standard error (mg/L) | C28: =IF(NOT(ISNUMBER(C27)),"",C16*SQRT(1/C25+1/C11+(C27-AVERAGE('Enter data'!$A$7:$A$18))^2/DEVSQ('Enter data'!$A$7:$A$18))/C13)
B29: Interval, lower (mg/L) | C29: =IF(NOT(ISNUMBER(C28)),"",C27-TINV(1-C6,C11-2)*C28)
B30: Interval, upper (mg/L) | C30: =IF(NOT(ISNUMBER(C28)),"",C27+TINV(1-C6,C11-2)*C28)
B32: 4. Standard addition (does the sample matrix change the response?)
B33: Points used | C33: =SUMPRODUCT(--ISNUMBER('Enter data'!$A$50:$A$57),--ISNUMBER('Enter data'!$D$50:$D$57)) -> 0
B34: Slope of the addition line | C34: =IF(C33<3,"Need 3+ points",SLOPE('Enter data'!$D$50:$D$57,'Enter data'!$A$50:$A$57)) -> Need 3+ points
B35: Intercept of the addition line (uS/cm) | C35: =IF(C33<3,"",INTERCEPT('Enter data'!$D$50:$D$57,'Enter data'!$A$50:$A$57))
B36: Ratio of addition slope to calibration slope | C36: =IF(AND(ISNUMBER(C34),ISNUMBER(C13)),C34/C13,"") | D36: 1.00 means no matrix effect.
B37: Sample concentration by standard addition (mg/L) | C37: =IF(ISNUMBER(C34),C35/C34,"")
B38: Same sample read from the calibration line (mg/L) | C38: =IF(AND(ISNUMBER(C35),ISNUMBER(C13)),(C35-C14)/C13,"")
B39: Reading | C39: =IF(NOT(ISNUMBER(C36)),"",IF(ABS(C36-1)>0.05,"The matrix changes the response by more than 5 percent: use the standard addition value.","No matrix effect beyond 5 percent: either value is acceptable."))
B41: Charts
