Workbook

Sheet Start here
B1: ACH-01 Gravimetric calibration of glassware
B2: Excel version of the card. It does the same calculations as the R script ach01_gravimetric_calibration.R.
B4: How to use this workbook
B5: 1. Go to the 'Enter data' sheet. Type only in the yellow cells with blue text. Grey cells are calculated for you.
B6: 2. Fill the blocks that apply. Leave rows you did not use empty. The grey italic row above each table is an example of the format and is not used.
B7: 3. Open the 'Results' sheet. Everything there is calculated. Yellow cells on that sheet are settings you may change.
B9: What the colours mean
B10: Yellow cell, blue text: you type here.
B11: Grey cell: a formula. Sheets are protected without a password so formulas are not overwritten by accident (Review > Unprotect Sheet).
B13: Assumptions and sources
B14: Water density: Tanaka M, Girard G, Davis R, Peuto A, Bignell N (2001) Metrologia 38:301-309 (0 to 40 C).
B15: Volume = mass / (water density - air density) x (1 - air density / density of the balance weights). The air density (0.0012 g/mL) and balance weight density (8.0 g/mL) are on the Results sheet.
... B20: Compiled by Emmanuel G. Lozano, Department of Biology, College of Arts and Sciences, Pampanga State University. Original material is licensed CC BY-NC 4.0: credit required, non-commercial use only.

Sheet Enter data
A1: Enter your data
A2: Type only in yellow cells. Leave unused rows empty.
A4: 1. Devices
A5: Device name | B5: Nominal volume (mL)
A6: 100 mL cylinder | B6: 100
A7: 100 mL cylinder | B7: 100
A8: 25 mL pipette | B8: 25
A9: 10 mL syringe | B9: 10
A12: 2. Deliveries for device 1 (one row per delivery)
A13: Mass of water (g) | B13: Water temperature (C) | C13: Delivered volume (mL)
A14: 99.1 | B14: 27.5
A15: 98.46 | B15: 27.5 | C15: =IF(AND(ISNUMBER(A15),ISNUMBER(B15)),A15/(0.99997495*(1-((B15-3.983035)^2*(B15+301.797))/(522528.9*(B15+69.34881)))-Results!$C$5)*(1-Results!$C$5/Results!$C$6),"") -> 98.922399
A16: 98.03 | B16: 27.5 | C16: =IF(AND(ISNUMBER(A16),ISNUMBER(B16)),A16/(0.99997495*(1-((B16-3.983035)^2*(B16+301.797))/(522528.9*(B16+69.34881)))-Results!$C$5)*(1-Results!$C$5/Results!$C$6),"") -> 98.49038
A17: 98.95 | B17: 27.5 | C17: =IF(AND(ISNUMBER(A17),ISNUMBER(B17)),A17/(0.99997495*(1-((B17-3.983035)^2*(B17+301.797))/(522528.9*(B17+69.34881)))-Results!$C$5)*(1-Results!$C$5/Results!$C$6),"") -> 99.4147
A18: 99 | B18: 27.5 | C18: =IF(AND(ISNUMBER(A18),ISNUMBER(B18)),A18/(0.99997495*(1-((B18-3.983035)^2*(B18+301.797))/(522528.9*(B18+69.34881)))-Results!$C$5)*(1-Results!$C$5/Results!$C$6),"") -> 99.464935
A19: 98.63 | B19: 27.5 | C19: =IF(AND(ISNUMBER(A19),ISNUMBER(B19)),A19/(0.99997495*(1-((B19-3.983035)^2*(B19+301.797))/(522528.9*(B19+69.34881)))-Results!$C$5)*(1-Results!$C$5/Results!$C$6),"") -> 99.093197
A20: 98.86 | B20: 27.5 | C20: =IF(AND(ISNUMBER(A20),ISNUMBER(B20)),A20/(0.99997495*(1-((B20-3.983035)^2*(B20+301.797))/(522528.9*(B20+69.34881)))-Results!$C$5)*(1-Results!$C$5/Results!$C$6),"") -> 99.324278
A21: 99.33 | B21: 27.5 | C21: =IF(AND(ISNUMBER(A21),ISNUMBER(B21)),A21/(0.99997495*(1-((B21-3.983035)^2*(B21+301.797))/(522528.9*(B21+69.34881)))-Results!$C$5)*(1-Results!$C$5/Results!$C$6),"") -> 99.796485
A22: 99.11 | B22: 27.5 | C22: =IF(AND(ISNUMBER(A22),ISNUMBER(B22)),A22/(0.99997495*(1-((B22-3.983035)^2*(B22+301.797))/(522528.9*(B22+69.34881)))-Results!$C$5)*(1-Results!$C$5/Results!$C$6),"") -> 99.575452
A23: 98.98 | B23: 27.5 | C23: =IF(AND(ISNUMBER(A23),ISNUMBER(B23)),A23/(0.99997495*(1-((B23-3.983035)^2*(B23+301.797))/(522528.9*(B23+69.34881)))-Results!$C$5)*(1-Results!$C$5/Results!$C$6),"") -> 99.444841
A24: 98.98 | B24: 27.5 | C24: =IF(AND(ISNUMBER(A24),ISNUMBER(B24)),A24/(0.99997495*(1-((B24-3.983035)^2*(B24+301.797))/(522528.9*(B24+69.34881)))-Results!$C$5)*(1-Results!$C$5/Results!$C$6),"") -> 99.444841
C25: =IF(AND(ISNUMBER(A25),ISNUMBER(B25)),A25/(0.99997495*(1-((B25-3.983035)^2*(B25+301.797))/(522528.9*(B25+69.34881)))-Results!$C$5)*(1-Results!$C$5/Results!$C$6),"")
C26: =IF(AND(ISNUMBER(A26),ISNUMBER(B26)),A26/(0.99997495*(1-((B26-3.983035)^2*(B26+301.797))/(522528.9*(B26+69.34881)))-Results!$C$5)*(1-Results!$C$5/Results!$C$6),"")
A29: 3. Deliveries for device 2 (one row per delivery)
A30: Mass of water (g) | B30: Water temperature (C) | C30: Delivered volume (mL)
A31: 99.1 | B31: 27.5
A32: 24.88 | B32: 27.5 | C32: =IF(AND(ISNUMBER(A32),ISNUMBER(B32)),A32/(0.99997495*(1-((B32-3.983035)^2*(B32+301.797))/(522528.9*(B32+69.34881)))-Results!$C$5)*(1-Results!$C$5/Results!$C$6),"") -> 24.996844
A33: 24.93 | B33: 27.5 | C33: =IF(AND(ISNUMBER(A33),ISNUMBER(B33)),A33/(0.99997495*(1-((B33-3.983035)^2*(B33+301.797))/(522528.9*(B33+69.34881)))-Results!$C$5)*(1-Results!$C$5/Results!$C$6),"") -> 25.047079
A34: 24.85 | B34: 27.5 | C34: =IF(AND(ISNUMBER(A34),ISNUMBER(B34)),A34/(0.99997495*(1-((B34-3.983035)^2*(B34+301.797))/(522528.9*(B34+69.34881)))-Results!$C$5)*(1-Results!$C$5/Results!$C$6),"") -> 24.966703
A35: 24.89 | B35: 27.5 | C35: =IF(AND(ISNUMBER(A35),ISNUMBER(B35)),A35/(0.99997495*(1-((B35-3.983035)^2*(B35+301.797))/(522528.9*(B35+69.34881)))-Results!$C$5)*(1-Results!$C$5/Results!$C$6),"") -> 25.006891
A36: 24.89 | B36: 27.5 | C36: =IF(AND(ISNUMBER(A36),ISNUMBER(B36)),A36/(0.99997495*(1-((B36-3.983035)^2*(B36+301.797))/(522528.9*(B36+69.34881)))-Results!$C$5)*(1-Results!$C$5/Results!$C$6),"") -> 25.006891
A37: 24.85 | B37: 27.5 | C37: =IF(AND(ISNUMBER(A37),ISNUMBER(B37)),A37/(0.99997495*(1-((B37-3.983035)^2*(B37+301.797))/(522528.9*(B37+69.34881)))-Results!$C$5)*(1-Results!$C$5/Results!$C$6),"") -> 24.966703
A38: 24.9 | B38: 27.5 | C38: =IF(AND(ISNUMBER(A38),ISNUMBER(B38)),A38/(0.99997495*(1-((B38-3.983035)^2*(B38+301.797))/(522528.9*(B38+69.34881)))-Results!$C$5)*(1-Results!$C$5/Results!$C$6),"") -> 25.016938
A39: 24.95 | B39: 27.5 | C39: =IF(AND(ISNUMBER(A39),ISNUMBER(B39)),A39/(0.99997495*(1-((B39-3.983035)^2*(B39+301.797))/(522528.9*(B39+69.34881)))-Results!$C$5)*(1-Results!$C$5/Results!$C$6),"") -> 25.067173
A40: 24.89 | B40: 27.5 | C40: =IF(AND(ISNUMBER(A40),ISNUMBER(B40)),A40/(0.99997495*(1-((B40-3.983035)^2*(B40+301.797))/(522528.9*(B40+69.34881)))-Results!$C$5)*(1-Results!$C$5/Results!$C$6),"") -> 25.006891
A41: 24.87 | B41: 27.5 | C41: =IF(AND(ISNUMBER(A41),ISNUMBER(B41)),A41/(0.99997495*(1-((B41-3.983035)^2*(B41+301.797))/(522528.9*(B41+69.34881)))-Results!$C$5)*(1-Results!$C$5/Results!$C$6),"") -> 24.986797
C42: =IF(AND(ISNUMBER(A42),ISNUMBER(B42)),A42/(0.99997495*(1-((B42-3.983035)^2*(B42+301.797))/(522528.9*(B42+69.34881)))-Results!$C$5)*(1-Results!$C$5/Results!$C$6),"")
C43: =IF(AND(ISNUMBER(A43),ISNUMBER(B43)),A43/(0.99997495*(1-((B43-3.983035)^2*(B43+301.797))/(522528.9*(B43+69.34881)))-Results!$C$5)*(1-Results!$C$5/Results!$C$6),"")
A46: 4. Deliveries for device 3 (one row per delivery)
A47: Mass of water (g) | B47: Water temperature (C) | C47: Delivered volume (mL)
...

Sheet Results
B1: Results
B2: Everything on this sheet is calculated. Change only the yellow settings.
B4: Settings
B5: Air density (g/mL) | C5: 0.0012
B6: Density of balance weights (g/mL) | C6: 8
B7: Balance resolution (g) | C7: 0.01 | D7: Readability of your balance.
B9: Results by device
B10: Device | C10: n | D10: Nominal (mL) | E10: Mean (mL) | F10: SD (mL) | G10: RSD (%) | H10: Bias (mL) | I10: Bias (%) | J10: p (bias = 0) | K10: Balance reading uncertainty (mL)
B11: =IFERROR(IF('Enter data'!$A$7="","",'Enter data'!$A$7),"") -> 100 mL cylinder | C11: =IFERROR(COUNT('Enter data'!$C$15:$C$26),"") -> 10 | D11: =IFERROR('Enter data'!$B$7,"") -> 100 | E11: =IFERROR(AVERAGE('Enter data'!$C$15:$C$26),"") -> 99.297151 | F11: =IFERROR(STDEV('Enter data'!$C$15:$C$26),"") -> 0.37208595 | G11: =IFERROR(100*F11/E11,"") -> 0.37471966 | H11: =IFERROR(E11-D11,"") -> -0.70284921 | I11: =IFERROR(100*(E11-D11)/D11,"") -> -0.70284921 | J11: =IFERROR(TDIST(ABS((E11-D11)/(F11/SQRT(C11))),C11-1,2),"") -> 0.00020923345 | K11: =IFERROR(SQRT(2)*Results!$C$7/SQRT(12)/(0.99997495*(1-((AVERAGE('Enter data'!$B$15:$B$26)-3.983035)^2*(AVERAGE('Enter data'!$B$15:$B$26)+301.797))/(522528.9*(AVERAGE('Enter data'!$B$15:$B$26)+69.34881)))-Results!$C$5),"") -> 0.0041022709
B12: =IFERROR(IF('Enter data'!$A$8="","",'Enter data'!$A$8),"") -> 25 mL pipette | C12: =IFERROR(COUNT('Enter data'!$C$32:$C$43),"") -> 10 | D12: =IFERROR('Enter data'!$B$8,"") -> 25 | E12: =IFERROR(AVERAGE('Enter data'!$C$32:$C$43),"") -> 25.006891 | F12: =IFERROR(STDEV('Enter data'!$C$32:$C$43),"") -> 0.031771287 | G12: =IFERROR(100*F12/E12,"") -> 0.12705013 | H12: =IFERROR(E12-D12,"") -> 0.0068912522 | I12: =IFERROR(100*(E12-D12)/D12,"") -> 0.027565009 | J12: =IFERROR(TDIST(ABS((E12-D12)/(F12/SQRT(C12))),C12-1,2),"") -> 0.5100548 | K12: =IFERROR(SQRT(2)*Results!$C$7/SQRT(12)/(0.99997495*(1-((AVERAGE('Enter data'!$B$32:$B$43)-3.983035)^2*(AVERAGE('Enter data'!$B$32:$B$43)+301.797))/(522528.9*(AVERAGE('Enter data'!$B$32:$B$43)+69.34881)))-Results!$C$5),"") -> 0.0041022709
B13: =IFERROR(IF('Enter data'!$A$9="","",'Enter data'!$A$9),"") -> 10 mL syringe | C13: =IFERROR(COUNT('Enter data'!$C$49:$C$60),"") -> 10 | D13: =IFERROR('Enter data'!$B$9,"") -> 10 | E13: =IFERROR(AVERAGE('Enter data'!$C$49:$C$60),"") -> 10.297133 | F13: =IFERROR(STDEV('Enter data'!$C$49:$C$60),"") -> 0.099058732 | G13: =IFERROR(100*F13/E13,"") -> 0.96200308 | H13: =IFERROR(E13-D13,"") -> 0.29713252 | I13: =IFERROR(100*(E13-D13)/D13,"") -> 2.9713252 | J13: =IFERROR(TDIST(ABS((E13-D13)/(F13/SQRT(C13))),C13-1,2),"") -> 5.5444507e-06 | K13: =IFERROR(SQRT(2)*Results!$C$7/SQRT(12)/(0.99997495*(1-((AVERAGE('Enter data'!$B$49:$B$60)-3.983035)^2*(AVERAGE('Enter data'!$B$49:$B$60)+301.797))/(522528.9*(AVERAGE('Enter data'!$B$49:$B$60)+69.34881)))-Results!$C$5),"") -> 0.0041022709
B16: Reference values
B17: Water density at 20 C (g/mL) | C17: =IFERROR(0.99997495*(1-((20-3.983035)^2*(20+301.797))/(522528.9*(20+69.34881))),"") -> 0.99820675
B18: Volume of 1 g of water in air at 20 C (mL) | C18: =IFERROR(1/(0.99997495*(1-((20-3.983035)^2*(20+301.797))/(522528.9*(20+69.34881)))-Results!$C$5)*(1-Results!$C$5/Results!$C$6),"") -> 1.0028518
