Workbook

Sheet Start here
B1: AP-05 Hollow organ walls: layer thickness proportions
B2: Excel version of the card. It does the same calculations as the R script ap05_wall_layers.R.
B4: How to use this workbook
B5: 1. Go to the 'Enter data' sheet. Type only in the yellow cells with blue text. Grey cells are calculated for you.
B6: 2. Fill the blocks that apply. Leave rows you did not use empty. The grey italic row above each table is an example of the format and is not used.
B7: 3. Open the 'Results' sheet. Everything there is calculated. Yellow cells on that sheet are settings you may change.
B9: What the colours mean
B10: Yellow cell, blue text: you type here.
B11: Grey cell: a formula. Sheets are protected without a password so formulas are not overwritten by accident (Review > Unprotect Sheet).
B13: Assumptions and sources
B14: Measure each layer along a line perpendicular to the wall where the wall is cut squarely. Use the same unit for all layers; proportions need no calibration.
B15: Type the layer names in the yellow header cells of each block (for example intima, media, adventitia, or mucosa, submucosa, muscularis, serosa).
... B22: Compiled by Emmanuel G. Lozano, Department of Biology, College of Arts and Sciences, Pampanga State University. Original material is licensed CC BY-NC 4.0: credit required, non-commercial use only.

Sheet Enter data
A1: Enter your data
A2: Type only in yellow cells. Leave unused rows empty.
A4: 1. Organ 1: fields (thickness of each layer)
A5: Field | B5: intima | C5: media | D5: adventitia | E5: (unused) | F5: Wall thickness | G5: Layer 1 share (%) | H5: Layer 2 share (%) | I5: Layer 3 share (%) | J5: Layer 4 share (%)
A6: field 1 | B6: 10 | C6: 60 | D6: 25 | E6: 0
F7: =IF(COUNT(B7:E7)>0,SUM(B7:E7),"") | G7: =IF(ISNUMBER(F7),100*B7/F7,"") | H7: =IF(ISNUMBER(F7),100*C7/F7,"") | I7: =IF(ISNUMBER(F7),100*D7/F7,"") | J7: =IF(ISNUMBER(F7),100*E7/F7,"")
F8: =IF(COUNT(B8:E8)>0,SUM(B8:E8),"") | G8: =IF(ISNUMBER(F8),100*B8/F8,"") | H8: =IF(ISNUMBER(F8),100*C8/F8,"") | I8: =IF(ISNUMBER(F8),100*D8/F8,"") | J8: =IF(ISNUMBER(F8),100*E8/F8,"")
F9: =IF(COUNT(B9:E9)>0,SUM(B9:E9),"") | G9: =IF(ISNUMBER(F9),100*B9/F9,"") | H9: =IF(ISNUMBER(F9),100*C9/F9,"") | I9: =IF(ISNUMBER(F9),100*D9/F9,"") | J9: =IF(ISNUMBER(F9),100*E9/F9,"")
F10: =IF(COUNT(B10:E10)>0,SUM(B10:E10),"") | G10: =IF(ISNUMBER(F10),100*B10/F10,"") | H10: =IF(ISNUMBER(F10),100*C10/F10,"") | I10: =IF(ISNUMBER(F10),100*D10/F10,"") | J10: =IF(ISNUMBER(F10),100*E10/F10,"")
F11: =IF(COUNT(B11:E11)>0,SUM(B11:E11),"") | G11: =IF(ISNUMBER(F11),100*B11/F11,"") | H11: =IF(ISNUMBER(F11),100*C11/F11,"") | I11: =IF(ISNUMBER(F11),100*D11/F11,"") | J11: =IF(ISNUMBER(F11),100*E11/F11,"")
F12: =IF(COUNT(B12:E12)>0,SUM(B12:E12),"") | G12: =IF(ISNUMBER(F12),100*B12/F12,"") | H12: =IF(ISNUMBER(F12),100*C12/F12,"") | I12: =IF(ISNUMBER(F12),100*D12/F12,"") | J12: =IF(ISNUMBER(F12),100*E12/F12,"")
F13: =IF(COUNT(B13:E13)>0,SUM(B13:E13),"") | G13: =IF(ISNUMBER(F13),100*B13/F13,"") | H13: =IF(ISNUMBER(F13),100*C13/F13,"") | I13: =IF(ISNUMBER(F13),100*D13/F13,"") | J13: =IF(ISNUMBER(F13),100*E13/F13,"")
F14: =IF(COUNT(B14:E14)>0,SUM(B14:E14),"") | G14: =IF(ISNUMBER(F14),100*B14/F14,"") | H14: =IF(ISNUMBER(F14),100*C14/F14,"") | I14: =IF(ISNUMBER(F14),100*D14/F14,"") | J14: =IF(ISNUMBER(F14),100*E14/F14,"")
F15: =IF(COUNT(B15:E15)>0,SUM(B15:E15),"") | G15: =IF(ISNUMBER(F15),100*B15/F15,"") | H15: =IF(ISNUMBER(F15),100*C15/F15,"") | I15: =IF(ISNUMBER(F15),100*D15/F15,"") | J15: =IF(ISNUMBER(F15),100*E15/F15,"")
F16: =IF(COUNT(B16:E16)>0,SUM(B16:E16),"") | G16: =IF(ISNUMBER(F16),100*B16/F16,"") | H16: =IF(ISNUMBER(F16),100*C16/F16,"") | I16: =IF(ISNUMBER(F16),100*D16/F16,"") | J16: =IF(ISNUMBER(F16),100*E16/F16,"")
F17: =IF(COUNT(B17:E17)>0,SUM(B17:E17),"") | G17: =IF(ISNUMBER(F17),100*B17/F17,"") | H17: =IF(ISNUMBER(F17),100*C17/F17,"") | I17: =IF(ISNUMBER(F17),100*D17/F17,"") | J17: =IF(ISNUMBER(F17),100*E17/F17,"")
F18: =IF(COUNT(B18:E18)>0,SUM(B18:E18),"") | G18: =IF(ISNUMBER(F18),100*B18/F18,"") | H18: =IF(ISNUMBER(F18),100*C18/F18,"") | I18: =IF(ISNUMBER(F18),100*D18/F18,"") | J18: =IF(ISNUMBER(F18),100*E18/F18,"")
A21: 2. Organ 2: fields (thickness of each layer)
A22: Field | B22: intima | C22: media | D22: adventitia | E22: (unused) | F22: Wall thickness | G22: Layer 1 share (%) | H22: Layer 2 share (%) | I22: Layer 3 share (%) | J22: Layer 4 share (%)
A23: field 1 | B23: 10 | C23: 60 | D23: 25 | E23: 0
F24: =IF(COUNT(B24:E24)>0,SUM(B24:E24),"") | G24: =IF(ISNUMBER(F24),100*B24/F24,"") | H24: =IF(ISNUMBER(F24),100*C24/F24,"") | I24: =IF(ISNUMBER(F24),100*D24/F24,"") | J24: =IF(ISNUMBER(F24),100*E24/F24,"")
F25: =IF(COUNT(B25:E25)>0,SUM(B25:E25),"") | G25: =IF(ISNUMBER(F25),100*B25/F25,"") | H25: =IF(ISNUMBER(F25),100*C25/F25,"") | I25: =IF(ISNUMBER(F25),100*D25/F25,"") | J25: =IF(ISNUMBER(F25),100*E25/F25,"")
F26: =IF(COUNT(B26:E26)>0,SUM(B26:E26),"") | G26: =IF(ISNUMBER(F26),100*B26/F26,"") | H26: =IF(ISNUMBER(F26),100*C26/F26,"") | I26: =IF(ISNUMBER(F26),100*D26/F26,"") | J26: =IF(ISNUMBER(F26),100*E26/F26,"")
F27: =IF(COUNT(B27:E27)>0,SUM(B27:E27),"") | G27: =IF(ISNUMBER(F27),100*B27/F27,"") | H27: =IF(ISNUMBER(F27),100*C27/F27,"") | I27: =IF(ISNUMBER(F27),100*D27/F27,"") | J27: =IF(ISNUMBER(F27),100*E27/F27,"")
F28: =IF(COUNT(B28:E28)>0,SUM(B28:E28),"") | G28: =IF(ISNUMBER(F28),100*B28/F28,"") | H28: =IF(ISNUMBER(F28),100*C28/F28,"") | I28: =IF(ISNUMBER(F28),100*D28/F28,"") | J28: =IF(ISNUMBER(F28),100*E28/F28,"")
F29: =IF(COUNT(B29:E29)>0,SUM(B29:E29),"") | G29: =IF(ISNUMBER(F29),100*B29/F29,"") | H29: =IF(ISNUMBER(F29),100*C29/F29,"") | I29: =IF(ISNUMBER(F29),100*D29/F29,"") | J29: =IF(ISNUMBER(F29),100*E29/F29,"")
F30: =IF(COUNT(B30:E30)>0,SUM(B30:E30),"") | G30: =IF(ISNUMBER(F30),100*B30/F30,"") | H30: =IF(ISNUMBER(F30),100*C30/F30,"") | I30: =IF(ISNUMBER(F30),100*D30/F30,"") | J30: =IF(ISNUMBER(F30),100*E30/F30,"")
F31: =IF(COUNT(B31:E31)>0,SUM(B31:E31),"") | G31: =IF(ISNUMBER(F31),100*B31/F31,"") | H31: =IF(ISNUMBER(F31),100*C31/F31,"") | I31: =IF(ISNUMBER(F31),100*D31/F31,"") | J31: =IF(ISNUMBER(F31),100*E31/F31,"")
F32: =IF(COUNT(B32:E32)>0,SUM(B32:E32),"") | G32: =IF(ISNUMBER(F32),100*B32/F32,"") | H32: =IF(ISNUMBER(F32),100*C32/F32,"") | I32: =IF(ISNUMBER(F32),100*D32/F32,"") | J32: =IF(ISNUMBER(F32),100*E32/F32,"")
F33: =IF(COUNT(B33:E33)>0,SUM(B33:E33),"") | G33: =IF(ISNUMBER(F33),100*B33/F33,"") | H33: =IF(ISNUMBER(F33),100*C33/F33,"") | I33: =IF(ISNUMBER(F33),100*D33/F33,"") | J33: =IF(ISNUMBER(F33),100*E33/F33,"")
F34: =IF(COUNT(B34:E34)>0,SUM(B34:E34),"") | G34: =IF(ISNUMBER(F34),100*B34/F34,"") | H34: =IF(ISNUMBER(F34),100*C34/F34,"") | I34: =IF(ISNUMBER(F34),100*D34/F34,"") | J34: =IF(ISNUMBER(F34),100*E34/F34,"")
F35: =IF(COUNT(B35:E35)>0,SUM(B35:E35),"") | G35: =IF(ISNUMBER(F35),100*B35/F35,"") | H35: =IF(ISNUMBER(F35),100*C35/F35,"") | I35: =IF(ISNUMBER(F35),100*D35/F35,"") | J35: =IF(ISNUMBER(F35),100*E35/F35,"")
A38: 3. Organ 3: fields (thickness of each layer)
A39: Field | B39: mucosa | C39: submucosa | D39: muscularis | E39: serosa | F39: Wall thickness | G39: Layer 1 share (%) | H39: Layer 2 share (%) | I39: Layer 3 share (%) | J39: Layer 4 share (%)
A40: field 1 | B40: 10 | C40: 60 | D40: 25 | E40: 0
F41: =IF(COUNT(B41:E41)>0,SUM(B41:E41),"") | G41: =IF(ISNUMBER(F41),100*B41/F41,"") | H41: =IF(ISNUMBER(F41),100*C41/F41,"") | I41: =IF(ISNUMBER(F41),100*D41/F41,"") | J41: =IF(ISNUMBER(F41),100*E41/F41,"")
F42: =IF(COUNT(B42:E42)>0,SUM(B42:E42),"") | G42: =IF(ISNUMBER(F42),100*B42/F42,"") | H42: =IF(ISNUMBER(F42),100*C42/F42,"") | I42: =IF(ISNUMBER(F42),100*D42/F42,"") | J42: =IF(ISNUMBER(F42),100*E42/F42,"")
F43: =IF(COUNT(B43:E43)>0,SUM(B43:E43),"") | G43: =IF(ISNUMBER(F43),100*B43/F43,"") | H43: =IF(ISNUMBER(F43),100*C43/F43,"") | I43: =IF(ISNUMBER(F43),100*D43/F43,"") | J43: =IF(ISNUMBER(F43),100*E43/F43,"")
F44: =IF(COUNT(B44:E44)>0,SUM(B44:E44),"") | G44: =IF(ISNUMBER(F44),100*B44/F44,"") | H44: =IF(ISNUMBER(F44),100*C44/F44,"") | I44: =IF(ISNUMBER(F44),100*D44/F44,"") | J44: =IF(ISNUMBER(F44),100*E44/F44,"")
F45: =IF(COUNT(B45:E45)>0,SUM(B45:E45),"") | G45: =IF(ISNUMBER(F45),100*B45/F45,"") | H45: =IF(ISNUMBER(F45),100*C45/F45,"") | I45: =IF(ISNUMBER(F45),100*D45/F45,"") | J45: =IF(ISNUMBER(F45),100*E45/F45,"")
...

Sheet Results
B1: Results
B2: Everything on this sheet is calculated. Change only the yellow settings.
B4: Layer share of the wall (percent of total thickness)
B5: Organ | C5: Layer | D5: Fields | E5: Mean share (%) | F5: SD
B6: =IFERROR('Enter data'!$A$57,"") -> 0 | C6: =IFERROR('Enter data'!$B$5,"") -> intima | D6: =IFERROR(COUNT('Enter data'!$G$7:$G$18),"") -> 0 | E6: =IFERROR(AVERAGE('Enter data'!$G$7:$G$18),"") | F6: =IFERROR(STDEV('Enter data'!$G$7:$G$18),"")
B7: =IFERROR('Enter data'!$A$57,"") -> 0 | C7: =IFERROR('Enter data'!$C$5,"") -> media | D7: =IFERROR(COUNT('Enter data'!$H$7:$H$18),"") -> 0 | E7: =IFERROR(AVERAGE('Enter data'!$H$7:$H$18),"") | F7: =IFERROR(STDEV('Enter data'!$H$7:$H$18),"")
B8: =IFERROR('Enter data'!$A$57,"") -> 0 | C8: =IFERROR('Enter data'!$D$5,"") -> adventitia | D8: =IFERROR(COUNT('Enter data'!$I$7:$I$18),"") -> 0 | E8: =IFERROR(AVERAGE('Enter data'!$I$7:$I$18),"") | F8: =IFERROR(STDEV('Enter data'!$I$7:$I$18),"")
B9: =IFERROR('Enter data'!$A$57,"") -> 0 | C9: =IFERROR('Enter data'!$E$5,"") -> (unused) | D9: =IFERROR(COUNT('Enter data'!$J$7:$J$18),"") -> 0 | E9: =IFERROR(AVERAGE('Enter data'!$J$7:$J$18),"") | F9: =IFERROR(STDEV('Enter data'!$J$7:$J$18),"")
B10: =IFERROR('Enter data'!$B$57,"") -> 0 | C10: =IFERROR('Enter data'!$B$22,"") -> intima | D10: =IFERROR(COUNT('Enter data'!$G$24:$G$35),"") -> 0 | E10: =IFERROR(AVERAGE('Enter data'!$G$24:$G$35),"") | F10: =IFERROR(STDEV('Enter data'!$G$24:$G$35),"")
B11: =IFERROR('Enter data'!$B$57,"") -> 0 | C11: =IFERROR('Enter data'!$C$22,"") -> media | D11: =IFERROR(COUNT('Enter data'!$H$24:$H$35),"") -> 0 | E11: =IFERROR(AVERAGE('Enter data'!$H$24:$H$35),"") | F11: =IFERROR(STDEV('Enter data'!$H$24:$H$35),"")
B12: =IFERROR('Enter data'!$B$57,"") -> 0 | C12: =IFERROR('Enter data'!$D$22,"") -> adventitia | D12: =IFERROR(COUNT('Enter data'!$I$24:$I$35),"") -> 0 | E12: =IFERROR(AVERAGE('Enter data'!$I$24:$I$35),"") | F12: =IFERROR(STDEV('Enter data'!$I$24:$I$35),"")
B13: =IFERROR('Enter data'!$B$57,"") -> 0 | C13: =IFERROR('Enter data'!$E$22,"") -> (unused) | D13: =IFERROR(COUNT('Enter data'!$J$24:$J$35),"") -> 0 | E13: =IFERROR(AVERAGE('Enter data'!$J$24:$J$35),"") | F13: =IFERROR(STDEV('Enter data'!$J$24:$J$35),"")
B14: =IFERROR('Enter data'!$C$57,"") -> 0 | C14: =IFERROR('Enter data'!$B$39,"") -> mucosa | D14: =IFERROR(COUNT('Enter data'!$G$41:$G$52),"") -> 0 | E14: =IFERROR(AVERAGE('Enter data'!$G$41:$G$52),"") | F14: =IFERROR(STDEV('Enter data'!$G$41:$G$52),"")
B15: =IFERROR('Enter data'!$C$57,"") -> 0 | C15: =IFERROR('Enter data'!$C$39,"") -> submucosa | D15: =IFERROR(COUNT('Enter data'!$H$41:$H$52),"") -> 0 | E15: =IFERROR(AVERAGE('Enter data'!$H$41:$H$52),"") | F15: =IFERROR(STDEV('Enter data'!$H$41:$H$52),"")
B16: =IFERROR('Enter data'!$C$57,"") -> 0 | C16: =IFERROR('Enter data'!$D$39,"") -> muscularis | D16: =IFERROR(COUNT('Enter data'!$I$41:$I$52),"") -> 0 | E16: =IFERROR(AVERAGE('Enter data'!$I$41:$I$52),"") | F16: =IFERROR(STDEV('Enter data'!$I$41:$I$52),"")
B17: =IFERROR('Enter data'!$C$57,"") -> 0 | C17: =IFERROR('Enter data'!$E$39,"") -> serosa | D17: =IFERROR(COUNT('Enter data'!$J$41:$J$52),"") -> 0 | E17: =IFERROR(AVERAGE('Enter data'!$J$41:$J$52),"") | F17: =IFERROR(STDEV('Enter data'!$J$41:$J$52),"")
B20: Wall thickness (measured units)
B21: Organ | C21: Fields | D21: Mean | E21: SD
B22: =IFERROR('Enter data'!$A$57,"") -> 0 | C22: =IFERROR(COUNT('Enter data'!$F$7:$F$18),"") -> 0 | D22: =IFERROR(AVERAGE('Enter data'!$F$7:$F$18),"") | E22: =IFERROR(STDEV('Enter data'!$F$7:$F$18),"")
B23: =IFERROR('Enter data'!$B$57,"") -> 0 | C23: =IFERROR(COUNT('Enter data'!$F$24:$F$35),"") -> 0 | D23: =IFERROR(AVERAGE('Enter data'!$F$24:$F$35),"") | E23: =IFERROR(STDEV('Enter data'!$F$24:$F$35),"")
B24: =IFERROR('Enter data'!$C$57,"") -> 0 | C24: =IFERROR(COUNT('Enter data'!$F$41:$F$52),"") -> 0 | D24: =IFERROR(AVERAGE('Enter data'!$F$41:$F$52),"") | E24: =IFERROR(STDEV('Enter data'!$F$41:$F$52),"")
B27: Share of layer 2 (for example media): organ 1 against organ 2
B28: Group | C28: n | D28: Mean | E28: SD | F28: SE | G28: Min | H28: Max
B29: =IFERROR('Enter data'!$A$57&" layer 2","") -> layer 2 | C29: =IFERROR(COUNT('Enter data'!$H$7:$H$18),"") -> 0 | D29: =IFERROR(AVERAGE('Enter data'!$H$7:$H$18),"") | E29: =IFERROR(STDEV('Enter data'!$H$7:$H$18),"") | F29: =IFERROR(STDEV('Enter data'!$H$7:$H$18)/SQRT(COUNT('Enter data'!$H$7:$H$18)),"") | G29: =IFERROR(MIN('Enter data'!$H$7:$H$18),"") -> 0 | H29: =IFERROR(MAX('Enter data'!$H$7:$H$18),"") -> 0
B30: =IFERROR('Enter data'!$B$57&" layer 2","") -> layer 2 | C30: =IFERROR(COUNT('Enter data'!$H$24:$H$35),"") -> 0 | D30: =IFERROR(AVERAGE('Enter data'!$H$24:$H$35),"") | E30: =IFERROR(STDEV('Enter data'!$H$24:$H$35),"") | F30: =IFERROR(STDEV('Enter data'!$H$24:$H$35)/SQRT(COUNT('Enter data'!$H$24:$H$35)),"") | G30: =IFERROR(MIN('Enter data'!$H$24:$H$35),"") -> 0 | H30: =IFERROR(MAX('Enter data'!$H$24:$H$35),"") -> 0
B33: Comparison of the two groups (Welch t test)
B34: Difference in means (group 1 minus group 2) | C34: =IFERROR($D$29-$D$30,"")
B35: Standard error of the difference | C35: =IFERROR(SQRT($F$29^2+$F$30^2),"")
B36: Degrees of freedom (Welch) | C36: =IFERROR((($E$29^2/$C$29+$E$30^2/$C$30)^2/(($E$29^2/$C$29)^2/($C$29-1)+($E$30^2/$C$30)^2/($C$30-1))),"")
B37: p value (two-sided) | C37: =IFERROR(TTEST('Enter data'!$H$7:$H$18,'Enter data'!$H$24:$H$35,2,3),"")
B38: 95% interval for the difference, lower | C38: =IFERROR($C$34-TINV(0.05,$C$36)*$C$35,"")
B39: 95% interval for the difference, upper | C39: =IFERROR($C$34+TINV(0.05,$C$36)*$C$35,"")
