Workbook

Sheet Start here
B1: AP-04 Lung volumes with a homemade spirometer
B2: Excel version of the card. It does the same calculations as the R script ap04_spirometer.R.
B4: How to use this workbook
B5: 1. Go to the 'Enter data' sheet. Type only in the yellow cells with blue text. Grey cells are calculated for you.
B6: 2. Fill the blocks that apply. Leave rows you did not use empty. The grey italic row above each table is an example of the format and is not used.
B7: 3. Open the 'Results' sheet. Everything there is calculated. Yellow cells on that sheet are settings you may change.
B9: What the colours mean
B10: Yellow cell, blue text: you type here.
B11: Grey cell: a formula. Sheets are protected without a password so formulas are not overwritten by accident (Review > Unprotect Sheet).
B13: Assumptions and sources
B14: Step 1: calibrate the bottle. Step 2: convert each water-level reading to millilitres. The volume for each measure is the mean of the two largest trials if they agree within 5 percent; otherwise the mean of all trials.
B15: The device cannot measure residual volume or total lung capacity. Readings are for teaching and are not medical advice. Use anonymous codes; approval for student-subject activities is assumed to have been granted.
... B22: Compiled by Emmanuel G. Lozano, Department of Biology, College of Arts and Sciences, Pampanga State University. Original material is licensed CC BY-NC 4.0: credit required, non-commercial use only.

Sheet Enter data
A1: Enter your data
A2: Type only in yellow cells. Leave unused rows empty.
A4: 1. Bottle calibration (add known volumes of water, read the mark)
A5: Volume added (mL) | B5: Water-level mark (cm)
A6: 1000 | B6: 6.7
A7: 500 | B7: 3.3
A8: 1000 | B8: 6.6
A9: 1500 | B9: 10.2
A10: 2000 | B10: 13.4
A11: 2500 | B11: 16.5
A12: 3000 | B12: 20
A13: 3500 | B13: 23.3
A14: 4000 | B14: 26.7
A15: 4500 | B15: 29.8
A21: 2. Students (volumes in mL)
A22: Subject code | B22: Sex (F or M) | C22: Height (cm) | D22: Vital capacity, trial 1 | E22: Trial 2 | F22: Trial 3 | G22: Tidal volume (mean) | H22: Expiratory reserve volume (mean) | I22: Vital capacity (mL) | J22: Inspiratory reserve volume (mL) | K22: Height (model) | L22: Male = 1 (model) | M22: Vital capacity (model) | N22: Row used
A23: S1 | B23: F | C23: 157 | D23: 3400 | E23: 3350 | F23: 3200 | G23: 500 | H23: 900
A24: S1 | B24: F | C24: 158 | D24: 3600 | E24: 3550 | F24: 3450 | G24: 600 | H24: 850 | I24: =IF(COUNT(D24:F24)=0,0,IF(COUNT(D24:F24)<2,D24,IF((LARGE(D24:F24,1)-LARGE(D24:F24,2))/LARGE(D24:F24,1)<=Results!$C$5,(LARGE(D24:F24,1)+LARGE(D24:F24,2))/2,AVERAGE(D24:F24)))) -> 3575 | J24: =IF(AND(I24>0,ISNUMBER(G24),ISNUMBER(H24)),I24-G24-H24,"") -> 2125 | K24: =IF(I24>0,C24,0) -> 158 | L24: =IF(I24>0,IF(B24="M",1,0),0) -> 0 | M24: =IF(I24>0,I24,0) -> 3575 | N24: =IF(I24>0,1,0) -> 1
A25: S2 | B25: F | C25: 158 | D25: 3400 | E25: 3350 | F25: 3250 | G25: 500 | H25: 1050 | I25: =IF(COUNT(D25:F25)=0,0,IF(COUNT(D25:F25)<2,D25,IF((LARGE(D25:F25,1)-LARGE(D25:F25,2))/LARGE(D25:F25,1)<=Results!$C$5,(LARGE(D25:F25,1)+LARGE(D25:F25,2))/2,AVERAGE(D25:F25)))) -> 3375 | J25: =IF(AND(I25>0,ISNUMBER(G25),ISNUMBER(H25)),I25-G25-H25,"") -> 1825 | K25: =IF(I25>0,C25,0) -> 158 | L25: =IF(I25>0,IF(B25="M",1,0),0) -> 0 | M25: =IF(I25>0,I25,0) -> 3375 | N25: =IF(I25>0,1,0) -> 1
A26: S3 | B26: F | C26: 166 | D26: 3850 | E26: 3850 | F26: 3700 | G26: 550 | H26: 1050 | I26: =IF(COUNT(D26:F26)=0,0,IF(COUNT(D26:F26)<2,D26,IF((LARGE(D26:F26,1)-LARGE(D26:F26,2))/LARGE(D26:F26,1)<=Results!$C$5,(LARGE(D26:F26,1)+LARGE(D26:F26,2))/2,AVERAGE(D26:F26)))) -> 3850 | J26: =IF(AND(I26>0,ISNUMBER(G26),ISNUMBER(H26)),I26-G26-H26,"") -> 2250 | K26: =IF(I26>0,C26,0) -> 166 | L26: =IF(I26>0,IF(B26="M",1,0),0) -> 0 | M26: =IF(I26>0,I26,0) -> 3850 | N26: =IF(I26>0,1,0) -> 1
A27: S4 | B27: F | C27: 159 | D27: 3600 | E27: 3600 | F27: 3450 | G27: 500 | H27: 900 | I27: =IF(COUNT(D27:F27)=0,0,IF(COUNT(D27:F27)<2,D27,IF((LARGE(D27:F27,1)-LARGE(D27:F27,2))/LARGE(D27:F27,1)<=Results!$C$5,(LARGE(D27:F27,1)+LARGE(D27:F27,2))/2,AVERAGE(D27:F27)))) -> 3600 | J27: =IF(AND(I27>0,ISNUMBER(G27),ISNUMBER(H27)),I27-G27-H27,"") -> 2200 | K27: =IF(I27>0,C27,0) -> 159 | L27: =IF(I27>0,IF(B27="M",1,0),0) -> 0 | M27: =IF(I27>0,I27,0) -> 3600 | N27: =IF(I27>0,1,0) -> 1
A28: S5 | B28: F | C28: 160 | D28: 3200 | E28: 3150 | F28: 3050 | G28: 500 | H28: 750 | I28: =IF(COUNT(D28:F28)=0,0,IF(COUNT(D28:F28)<2,D28,IF((LARGE(D28:F28,1)-LARGE(D28:F28,2))/LARGE(D28:F28,1)<=Results!$C$5,(LARGE(D28:F28,1)+LARGE(D28:F28,2))/2,AVERAGE(D28:F28)))) -> 3175 | J28: =IF(AND(I28>0,ISNUMBER(G28),ISNUMBER(H28)),I28-G28-H28,"") -> 1925 | K28: =IF(I28>0,C28,0) -> 160 | L28: =IF(I28>0,IF(B28="M",1,0),0) -> 0 | M28: =IF(I28>0,I28,0) -> 3175 | N28: =IF(I28>0,1,0) -> 1
A29: S6 | B29: F | C29: 148 | D29: 2850 | E29: 2850 | F29: 2750 | G29: 550 | H29: 800 | I29: =IF(COUNT(D29:F29)=0,0,IF(COUNT(D29:F29)<2,D29,IF((LARGE(D29:F29,1)-LARGE(D29:F29,2))/LARGE(D29:F29,1)<=Results!$C$5,(LARGE(D29:F29,1)+LARGE(D29:F29,2))/2,AVERAGE(D29:F29)))) -> 2850 | J29: =IF(AND(I29>0,ISNUMBER(G29),ISNUMBER(H29)),I29-G29-H29,"") -> 1500 | K29: =IF(I29>0,C29,0) -> 148 | L29: =IF(I29>0,IF(B29="M",1,0),0) -> 0 | M29: =IF(I29>0,I29,0) -> 2850 | N29: =IF(I29>0,1,0) -> 1
A30: S7 | B30: F | C30: 171 | D30: 3700 | E30: 3700 | F30: 3550 | G30: 400 | H30: 1200 | I30: =IF(COUNT(D30:F30)=0,0,IF(COUNT(D30:F30)<2,D30,IF((LARGE(D30:F30,1)-LARGE(D30:F30,2))/LARGE(D30:F30,1)<=Results!$C$5,(LARGE(D30:F30,1)+LARGE(D30:F30,2))/2,AVERAGE(D30:F30)))) -> 3700 | J30: =IF(AND(I30>0,ISNUMBER(G30),ISNUMBER(H30)),I30-G30-H30,"") -> 2100 | K30: =IF(I30>0,C30,0) -> 171 | L30: =IF(I30>0,IF(B30="M",1,0),0) -> 0 | M30: =IF(I30>0,I30,0) -> 3700 | N30: =IF(I30>0,1,0) -> 1
A31: S8 | B31: F | C31: 146 | D31: 3150 | E31: 3100 | F31: 3000 | G31: 500 | H31: 700 | I31: =IF(COUNT(D31:F31)=0,0,IF(COUNT(D31:F31)<2,D31,IF((LARGE(D31:F31,1)-LARGE(D31:F31,2))/LARGE(D31:F31,1)<=Results!$C$5,(LARGE(D31:F31,1)+LARGE(D31:F31,2))/2,AVERAGE(D31:F31)))) -> 3125 | J31: =IF(AND(I31>0,ISNUMBER(G31),ISNUMBER(H31)),I31-G31-H31,"") -> 1925 | K31: =IF(I31>0,C31,0) -> 146 | L31: =IF(I31>0,IF(B31="M",1,0),0) -> 0 | M31: =IF(I31>0,I31,0) -> 3125 | N31: =IF(I31>0,1,0) -> 1
A32: S9 | B32: F | C32: 164 | D32: 3750 | E32: 3700 | F32: 3600 | G32: 600 | H32: 850 | I32: =IF(COUNT(D32:F32)=0,0,IF(COUNT(D32:F32)<2,D32,IF((LARGE(D32:F32,1)-LARGE(D32:F32,2))/LARGE(D32:F32,1)<=Results!$C$5,(LARGE(D32:F32,1)+LARGE(D32:F32,2))/2,AVERAGE(D32:F32)))) -> 3725 | J32: =IF(AND(I32>0,ISNUMBER(G32),ISNUMBER(H32)),I32-G32-H32,"") -> 2275 | K32: =IF(I32>0,C32,0) -> 164 | L32: =IF(I32>0,IF(B32="M",1,0),0) -> 0 | M32: =IF(I32>0,I32,0) -> 3725 | N32: =IF(I32>0,1,0) -> 1
A33: S10 | B33: F | C33: 155 | D33: 3100 | E33: 3050 | F33: 2950 | G33: 550 | H33: 800 | I33: =IF(COUNT(D33:F33)=0,0,IF(COUNT(D33:F33)<2,D33,IF((LARGE(D33:F33,1)-LARGE(D33:F33,2))/LARGE(D33:F33,1)<=Results!$C$5,(LARGE(D33:F33,1)+LARGE(D33:F33,2))/2,AVERAGE(D33:F33)))) -> 3075 | J33: =IF(AND(I33>0,ISNUMBER(G33),ISNUMBER(H33)),I33-G33-H33,"") -> 1725 | K33: =IF(I33>0,C33,0) -> 155 | L33: =IF(I33>0,IF(B33="M",1,0),0) -> 0 | M33: =IF(I33>0,I33,0) -> 3075 | N33: =IF(I33>0,1,0) -> 1
A34: S11 | B34: F | C34: 152 | D34: 3050 | E34: 3000 | F34: 2900 | G34: 500 | H34: 650 | I34: =IF(COUNT(D34:F34)=0,0,IF(COUNT(D34:F34)<2,D34,IF((LARGE(D34:F34,1)-LARGE(D34:F34,2))/LARGE(D34:F34,1)<=Results!$C$5,(LARGE(D34:F34,1)+LARGE(D34:F34,2))/2,AVERAGE(D34:F34)))) -> 3025 | J34: =IF(AND(I34>0,ISNUMBER(G34),ISNUMBER(H34)),I34-G34-H34,"") -> 1875 | K34: =IF(I34>0,C34,0) -> 152 | L34: =IF(I34>0,IF(B34="M",1,0),0) -> 0 | M34: =IF(I34>0,I34,0) -> 3025 | N34: =IF(I34>0,1,0) -> 1
A35: S12 | B35: F | C35: 153 | D35: 3000 | E35: 3000 | F35: 2900 | G35: 400 | H35: 750 | I35: =IF(COUNT(D35:F35)=0,0,IF(COUNT(D35:F35)<2,D35,IF((LARGE(D35:F35,1)-LARGE(D35:F35,2))/LARGE(D35:F35,1)<=Results!$C$5,(LARGE(D35:F35,1)+LARGE(D35:F35,2))/2,AVERAGE(D35:F35)))) -> 3000 | J35: =IF(AND(I35>0,ISNUMBER(G35),ISNUMBER(H35)),I35-G35-H35,"") -> 1850 | K35: =IF(I35>0,C35,0) -> 153 | L35: =IF(I35>0,IF(B35="M",1,0),0) -> 0 | M35: =IF(I35>0,I35,0) -> 3000 | N35: =IF(I35>0,1,0) -> 1
... A47: S24 | B47: M | C47: 160 | D47: 3500 | E47: 3450 | F47: 3350 | G47: 550 | H47: 1250 | I47: =IF(COUNT(D47:F47)=0,0,IF(COUNT(D47:F47)<2,D47,IF((LARGE(D47:F47,1)-LARGE(D47:F47,2))/LARGE(D47:F47,1)<=Results!$C$5,(LARGE(D47:F47,1)+LARGE(D47:F47,2))/2,AVERAGE(D47:F47)))) -> 3475 | J47: =IF(AND(I47>0,ISNUMBER(G47),ISNUMBER(H47)),I47-G47-H47,"") -> 1675 | K47: =IF(I47>0,C47,0) -> 160 | L47: =IF(I47>0,IF(B47="M",1,0),0) -> 1 | M47: =IF(I47>0,I47,0) -> 3475 | N47: =IF(I47>0,1,0) -> 1
I48: =IF(COUNT(D48:F48)=0,0,IF(COUNT(D48:F48)<2,D48,IF((LARGE(D48:F48,1)-LARGE(D48:F48,2))/LARGE(D48:F48,1)<=Results!$C$5,(LARGE(D48:F48,1)+LARGE(D48:F48,2))/2,AVERAGE(D48:F48)))) -> 0 | J48: =IF(AND(I48>0,ISNUMBER(G48),ISNUMBER(H48)),I48-G48-H48,"") | K48: =IF(I48>0,C48,0) -> 0 | L48: =IF(I48>0,IF(B48="M",1,0),0) -> 0 | M48: =IF(I48>0,I48,0) -> 0 | N48: =IF(I48>0,1,0) -> 0
I49: =IF(COUNT(D49:F49)=0,0,IF(COUNT(D49:F49)<2,D49,IF((LARGE(D49:F49,1)-LARGE(D49:F49,2))/LARGE(D49:F49,1)<=Results!$C$5,(LARGE(D49:F49,1)+LARGE(D49:F49,2))/2,AVERAGE(D49:F49)))) -> 0 | J49: =IF(AND(I49>0,ISNUMBER(G49),ISNUMBER(H49)),I49-G49-H49,"") | K49: =IF(I49>0,C49,0) -> 0 | L49: =IF(I49>0,IF(B49="M",1,0),0) -> 0 | M49: =IF(I49>0,I49,0) -> 0 | N49: =IF(I49>0,1,0) -> 0
I50: =IF(COUNT(D50:F50)=0,0,IF(COUNT(D50:F50)<2,D50,IF((LARGE(D50:F50,1)-LARGE(D50:F50,2))/LARGE(D50:F50,1)<=Results!$C$5,(LARGE(D50:F50,1)+LARGE(D50:F50,2))/2,AVERAGE(D50:F50)))) -> 0 | J50: =IF(AND(I50>0,ISNUMBER(G50),ISNUMBER(H50)),I50-G50-H50,"") | K50: =IF(I50>0,C50,0) -> 0 | L50: =IF(I50>0,IF(B50="M",1,0),0) -> 0 | M50: =IF(I50>0,I50,0) -> 0 | N50: =IF(I50>0,1,0) -> 0
I51: =IF(COUNT(D51:F51)=0,0,IF(COUNT(D51:F51)<2,D51,IF((LARGE(D51:F51,1)-LARGE(D51:F51,2))/LARGE(D51:F51,1)<=Results!$C$5,(LARGE(D51:F51,1)+LARGE(D51:F51,2))/2,AVERAGE(D51:F51)))) -> 0 | J51: =IF(AND(I51>0,ISNUMBER(G51),ISNUMBER(H51)),I51-G51-H51,"") | K51: =IF(I51>0,C51,0) -> 0 | L51: =IF(I51>0,IF(B51="M",1,0),0) -> 0 | M51: =IF(I51>0,I51,0) -> 0 | N51: =IF(I51>0,1,0) -> 0
I52: =IF(COUNT(D52:F52)=0,0,IF(COUNT(D52:F52)<2,D52,IF((LARGE(D52:F52,1)-LARGE(D52:F52,2))/LARGE(D52:F52,1)<=Results!$C$5,(LARGE(D52:F52,1)+LARGE(D52:F52,2))/2,AVERAGE(D52:F52)))) -> 0 | J52: =IF(AND(I52>0,ISNUMBER(G52),ISNUMBER(H52)),I52-G52-H52,"") | K52: =IF(I52>0,C52,0) -> 0 | L52: =IF(I52>0,IF(B52="M",1,0),0) -> 0 | M52: =IF(I52>0,I52,0) -> 0 | N52: =IF(I52>0,1,0) -> 0
I53: =IF(COUNT(D53:F53)=0,0,IF(COUNT(D53:F53)<2,D53,IF((LARGE(D53:F53,1)-LARGE(D53:F53,2))/LARGE(D53:F53,1)<=Results!$C$5,(LARGE(D53:F53,1)+LARGE(D53:F53,2))/2,AVERAGE(D53:F53)))) -> 0 | J53: =IF(AND(I53>0,ISNUMBER(G53),ISNUMBER(H53)),I53-G53-H53,"") | K53: =IF(I53>0,C53,0) -> 0 | L53: =IF(I53>0,IF(B53="M",1,0),0) -> 0 | M53: =IF(I53>0,I53,0) -> 0 | N53: =IF(I53>0,1,0) -> 0

Sheet Results
B1: Results
B2: Everything on this sheet is calculated. Change only the yellow settings.
B4: Settings
B5: Agreement allowed between the two largest trials | C5: 0.05
B7: Calibration line (volume = intercept + slope x mark)
B8: Points used | C8: =IFERROR(SUMPRODUCT(--ISNUMBER('Enter data'!$B$7:$B$18),--ISNUMBER('Enter data'!$A$7:$A$18)),"") -> 9
B9: Slope (mL per cm) | C9: =IFERROR(SLOPE('Enter data'!$A$7:$A$18,'Enter data'!$B$7:$B$18),"") -> 150.65478
B10: Intercept (mL per cm) | C10: =IFERROR(INTERCEPT('Enter data'!$A$7:$A$18,'Enter data'!$B$7:$B$18),"") -> -7.565108
B11: R squared | C11: =IFERROR(RSQ('Enter data'!$A$7:$A$18,'Enter data'!$B$7:$B$18),"") -> 0.99984555
B12: Residual standard deviation | C12: =IFERROR(STEYX('Enter data'!$A$7:$A$18,'Enter data'!$B$7:$B$18),"") -> 18.192223
B13: Standard error of the slope | C13: =IFERROR($C$12/SQRT(DEVSQ('Enter data'!$B$7:$B$18)),"") -> 0.70771204
B14: 95% interval for the slope, lower | C14: =IFERROR($C$9-TINV(0.05,$C$8-2)*$C$13,"") -> 148.98131
B15: 95% interval for the slope, upper | C15: =IFERROR($C$9+TINV(0.05,$C$8-2)*$C$13,"") -> 152.32825
B17: Vital capacity by sex (mL)
B18: Name | C18: n | D18: Mean | E18: SD | F18: SE
B19: =IFERROR("F","") -> F | C19: =IFERROR(COUNTIFS('Enter data'!$B$24:$B$53,"F",'Enter data'!$I$24:$I$53,"<>0"),"") -> 12 | D19: =IFERROR(AVERAGEIFS('Enter data'!$I$24:$I$53,'Enter data'!$B$24:$B$53,"F",'Enter data'!$I$24:$I$53,"<>0"),"") -> 3339.5833 | E19: =IFERROR(SQRT(MAX(0,(SUMPRODUCT(('Enter data'!$B$24:$B$53="F")*('Enter data'!$I$24:$I$53<>0)*'Enter data'!$I$24:$I$53^2)-C19*D19^2)/(C19-1))),"") -> 338.52258 | F19: =IFERROR(E19/SQRT(C19),"") -> 97.723052
B20: =IFERROR("M","") -> M | C20: =IFERROR(COUNTIFS('Enter data'!$B$24:$B$53,"M",'Enter data'!$I$24:$I$53,"<>0"),"") -> 12 | D20: =IFERROR(AVERAGEIFS('Enter data'!$I$24:$I$53,'Enter data'!$B$24:$B$53,"M",'Enter data'!$I$24:$I$53,"<>0"),"") -> 4060.4167 | E20: =IFERROR(SQRT(MAX(0,(SUMPRODUCT(('Enter data'!$B$24:$B$53="M")*('Enter data'!$I$24:$I$53<>0)*'Enter data'!$I$24:$I$53^2)-C20*D20^2)/(C20-1))),"") -> 447.65276 | F20: =IFERROR(E20/SQRT(C20),"") -> 129.22622
B23: Vital capacity regressed on height and sex
B24: Rows used | C24: =IFERROR(SUM('Enter data'!$N$24:$N$53),"") -> 24
B25: Mean of x1 | C25: =IFERROR(SUMPRODUCT('Enter data'!$N$24:$N$53,'Enter data'!$K$24:$K$53)/$C$24,"") -> 162.08333
B26: Mean of x2 | C26: =IFERROR(SUMPRODUCT('Enter data'!$N$24:$N$53,'Enter data'!$L$24:$L$53)/$C$24,"") -> 0.5
B27: Mean of y | C27: =IFERROR(SUMPRODUCT('Enter data'!$N$24:$N$53,'Enter data'!$M$24:$M$53)/$C$24,"") -> 3700
B28: Sum of squares of x1 | C28: =IFERROR(SUMPRODUCT('Enter data'!$N$24:$N$53,('Enter data'!$K$24:$K$53-$C$25)*('Enter data'!$K$24:$K$53-$C$25)),"") -> 1551.8333
B29: Sum of squares of x2 | C29: =IFERROR(SUMPRODUCT('Enter data'!$N$24:$N$53,('Enter data'!$L$24:$L$53-$C$26)*('Enter data'!$L$24:$L$53-$C$26)),"") -> 6
B30: Cross products x1, x2 | C30: =IFERROR(SUMPRODUCT('Enter data'!$N$24:$N$53,('Enter data'!$K$24:$K$53-$C$25)*('Enter data'!$L$24:$L$53-$C$26)),"") -> 55
B31: Cross products x1, y | C31: =IFERROR(SUMPRODUCT('Enter data'!$N$24:$N$53,('Enter data'!$K$24:$K$53-$C$25)*('Enter data'!$M$24:$M$53-$C$27)),"") -> 90125
B32: Cross products x2, y | C32: =IFERROR(SUMPRODUCT('Enter data'!$N$24:$N$53,('Enter data'!$L$24:$L$53-$C$26)*('Enter data'!$M$24:$M$53-$C$27)),"") -> 4325
B33: Sum of squares of y | C33: =IFERROR(SUMPRODUCT('Enter data'!$N$24:$N$53,('Enter data'!$M$24:$M$53-$C$27)*('Enter data'!$M$24:$M$53-$C$27)),"") -> 6582500
B34: mL per centimetre of height | C34: =IFERROR(($C$31*$C$29-$C$32*$C$30)/($C$28*$C$29-$C$30^2),"") -> 48.182469
B35: Males minus females at the same height (mL) | C35: =IFERROR(($C$32*$C$28-$C$31*$C$30)/($C$28*$C$29-$C$30^2),"") -> 279.1607
B36: Intercept | C36: =IFERROR($C$27-$C$34*$C$25-$C$35*$C$26,"") -> -4249.1555
B37: Residual sum of squares | C37: =IFERROR($C$33-$C$34*$C$31-$C$35*$C$32,"") -> 1032685
B38: Residual standard deviation | C38: =IFERROR(SQRT($C$37/($C$24-3)),"") -> 221.75544
B39: R squared | C39: =IFERROR(1-$C$37/$C$33,"") -> 0.8431166
B40: Standard error of slope 1 | C40: =IFERROR($C$38*SQRT($C$29/($C$28*$C$29-$C$30^2)),"") -> 6.851138
B41: Standard error of slope 2 | C41: =IFERROR($C$38*SQRT($C$28/($C$28*$C$29-$C$30^2)),"") -> 110.18174
B42: 95% interval for slope 1, lower | C42: =IFERROR($C$34-TINV(0.05,$C$24-3)*$C$40,"") -> 33.934748
B43: 95% interval for slope 1, upper | C43: =IFERROR($C$34+TINV(0.05,$C$24-3)*$C$40,"") -> 62.43019
B45: Other measures
B46: Mean tidal volume (mL) | C46: =IFERROR(AVERAGE('Enter data'!$G$24:$G$53),"") -> 510.41667
...
