Workbook

Sheet Start here
B1: AP-07 Blood pressure and oxygen saturation: repeatability, posture, device agreement
B2: Excel version of the card. It does the same calculations as the R script ap07_bp_spo2.R.
B4: How to use this workbook
B5: 1. Go to the 'Enter data' sheet. Type only in the yellow cells with blue text. Grey cells are calculated for you.
B6: 2. Fill the blocks that apply. Leave rows you did not use empty. The grey italic row above each table is an example of the format and is not used.
B7: 3. Open the 'Results' sheet. Everything there is calculated. Yellow cells on that sheet are settings you may change.
B9: What the colours mean
B10: Yellow cell, blue text: you type here.
B11: Grey cell: a formula. Sheets are protected without a password so formulas are not overwritten by accident (Review > Unprotect Sheet).
B13: Assumptions and sources
B14: Teaching only; not medical advice; do not interpret anyone's values clinically. Use anonymous codes. Approval for student-subject activities is assumed to have been granted, and taking part is voluntary.
B15: Repeatability coefficient = 1.96 x sqrt(2) x within-subject sd. Device agreement: differences of subject means, limits = mean difference +/- 1.96 sd (Bland-Altman).
... B19: Compiled by Emmanuel G. Lozano, Department of Biology, College of Arts and Sciences, Pampanga State University. Original material is licensed CC BY-NC 4.0: credit required, non-commercial use only.

Sheet Enter data
A1: Enter your data
A2: Type only in yellow cells. Leave unused rows empty.
A4: 1. Repeatability: three seated systolic readings on device A
A5: Subject code | B5: Reading 1 (mmHg) | C5: Reading 2 | D5: Reading 3 | E5: Within-subject variance
A6: S1 | B6: 112 | C6: 115 | D6: 110
E7: =IF(COUNT(B7:D7)>=2,VAR(B7:D7),"")
E8: =IF(COUNT(B8:D8)>=2,VAR(B8:D8),"")
E9: =IF(COUNT(B9:D9)>=2,VAR(B9:D9),"")
E10: =IF(COUNT(B10:D10)>=2,VAR(B10:D10),"")
E11: =IF(COUNT(B11:D11)>=2,VAR(B11:D11),"")
E12: =IF(COUNT(B12:D12)>=2,VAR(B12:D12),"")
E13: =IF(COUNT(B13:D13)>=2,VAR(B13:D13),"")
E14: =IF(COUNT(B14:D14)>=2,VAR(B14:D14),"")
E15: =IF(COUNT(B15:D15)>=2,VAR(B15:D15),"")
E16: =IF(COUNT(B16:D16)>=2,VAR(B16:D16),"")
E17: =IF(COUNT(B17:D17)>=2,VAR(B17:D17),"")
E18: =IF(COUNT(B18:D18)>=2,VAR(B18:D18),"")
... E36: =IF(COUNT(B36:D36)>=2,VAR(B36:D36),"")
A39: 2. Posture (device A subject means)
A40: Subject code | B40: Seated systolic | C40: Standing systolic | D40: Seated heart rate | E40: Standing heart rate | F40: Systolic change (standing minus seated) | G40: Heart rate change
A41: S1 | B41: 112 | C41: 114 | D41: 72 | E41: 82
F42: =IF(AND(ISNUMBER(B42),ISNUMBER(C42)),C42-B42,"") | G42: =IF(AND(ISNUMBER(D42),ISNUMBER(E42)),E42-D42,"")
F43: =IF(AND(ISNUMBER(B43),ISNUMBER(C43)),C43-B43,"") | G43: =IF(AND(ISNUMBER(D43),ISNUMBER(E43)),E43-D43,"")
F44: =IF(AND(ISNUMBER(B44),ISNUMBER(C44)),C44-B44,"") | G44: =IF(AND(ISNUMBER(D44),ISNUMBER(E44)),E44-D44,"")
F45: =IF(AND(ISNUMBER(B45),ISNUMBER(C45)),C45-B45,"") | G45: =IF(AND(ISNUMBER(D45),ISNUMBER(E45)),E45-D45,"")
F46: =IF(AND(ISNUMBER(B46),ISNUMBER(C46)),C46-B46,"") | G46: =IF(AND(ISNUMBER(D46),ISNUMBER(E46)),E46-D46,"")
F47: =IF(AND(ISNUMBER(B47),ISNUMBER(C47)),C47-B47,"") | G47: =IF(AND(ISNUMBER(D47),ISNUMBER(E47)),E47-D47,"")
F48: =IF(AND(ISNUMBER(B48),ISNUMBER(C48)),C48-B48,"") | G48: =IF(AND(ISNUMBER(D48),ISNUMBER(E48)),E48-D48,"")
F49: =IF(AND(ISNUMBER(B49),ISNUMBER(C49)),C49-B49,"") | G49: =IF(AND(ISNUMBER(D49),ISNUMBER(E49)),E49-D49,"")
F50: =IF(AND(ISNUMBER(B50),ISNUMBER(C50)),C50-B50,"") | G50: =IF(AND(ISNUMBER(D50),ISNUMBER(E50)),E50-D50,"")
F51: =IF(AND(ISNUMBER(B51),ISNUMBER(C51)),C51-B51,"") | G51: =IF(AND(ISNUMBER(D51),ISNUMBER(E51)),E51-D51,"")
F52: =IF(AND(ISNUMBER(B52),ISNUMBER(C52)),C52-B52,"") | G52: =IF(AND(ISNUMBER(D52),ISNUMBER(E52)),E52-D52,"")
F53: =IF(AND(ISNUMBER(B53),ISNUMBER(C53)),C53-B53,"") | G53: =IF(AND(ISNUMBER(D53),ISNUMBER(E53)),E53-D53,"")
... F71: =IF(AND(ISNUMBER(B71),ISNUMBER(C71)),C71-B71,"") | G71: =IF(AND(ISNUMBER(D71),ISNUMBER(E71)),E71-D71,"")
A74: 3. Device agreement (seated systolic subject means)
A75: Subject code | B75: Device A | C75: Device B | D75: B minus A
A76: S1 | B76: 112 | C76: 116
D77: =IF(AND(ISNUMBER(B77),ISNUMBER(C77)),C77-B77,"")
D78: =IF(AND(ISNUMBER(B78),ISNUMBER(C78)),C78-B78,"")
D79: =IF(AND(ISNUMBER(B79),ISNUMBER(C79)),C79-B79,"")
...

Sheet Results
B1: Results
B2: Everything on this sheet is calculated. Change only the yellow settings.
B4: Repeatability of systolic pressure (device A, seated)
B5: Within-subject standard deviation (mmHg) | C5: =IFERROR(SQRT(AVERAGE('Enter data'!$E$7:$E$36)),"")
B6: Repeatability coefficient (mmHg) | C6: =IFERROR(1.96*SQRT(2)*$C$5,"")
B8: Standard error of a person's mean by number of readings
B9: Readings | C9: Standard error (mmHg)
B10: 1 | C10: =IFERROR($C$5/SQRT(B10),"")
B11: 2 | C11: =IFERROR($C$5/SQRT(B11),"")
B12: 3 | C12: =IFERROR($C$5/SQRT(B12),"")
B13: 5 | C13: =IFERROR($C$5/SQRT(B13),"")
B16: Systolic pressure: standing minus seated (paired t test)
B17: Subjects | C17: =IFERROR(COUNT('Enter data'!$F$42:$F$71),"") -> 0
B18: Mean change | C18: =IFERROR(AVERAGE('Enter data'!$F$42:$F$71),"")
B19: Standard deviation of changes | C19: =IFERROR(STDEV('Enter data'!$F$42:$F$71),"")
B20: 95% interval, lower | C20: =IFERROR($C$18-TINV(0.05,$C$17-1)*$C$19/SQRT($C$17),"")
B21: 95% interval, upper | C21: =IFERROR($C$18+TINV(0.05,$C$17-1)*$C$19/SQRT($C$17),"")
B22: p value | C22: =IFERROR(TDIST(ABS($C$18/($C$19/SQRT($C$17))),$C$17-1,2),"")
B24: Heart rate: standing minus seated (paired t test)
B25: Subjects | C25: =IFERROR(COUNT('Enter data'!$G$42:$G$71),"") -> 0
B26: Mean change | C26: =IFERROR(AVERAGE('Enter data'!$G$42:$G$71),"")
B27: Standard deviation of changes | C27: =IFERROR(STDEV('Enter data'!$G$42:$G$71),"")
B28: 95% interval, lower | C28: =IFERROR($C$26-TINV(0.05,$C$25-1)*$C$27/SQRT($C$25),"")
B29: 95% interval, upper | C29: =IFERROR($C$26+TINV(0.05,$C$25-1)*$C$27/SQRT($C$25),"")
B30: p value | C30: =IFERROR(TDIST(ABS($C$26/($C$27/SQRT($C$25))),$C$25-1,2),"")
B32: Device agreement (Bland-Altman)
B33: Subjects | C33: =IFERROR(COUNT('Enter data'!$D$77:$D$106),"") -> 0
B34: Mean difference, B minus A (mmHg) | C34: =IFERROR(AVERAGE('Enter data'!$D$77:$D$106),"")
B35: Standard deviation of differences | C35: =IFERROR(STDEV('Enter data'!$D$77:$D$106),"")
B36: 95% limit of agreement, lower | C36: =IFERROR($C$34-1.96*$C$35,"")
B37: 95% limit of agreement, upper | C37: =IFERROR($C$34+1.96*$C$35,"")
B38: Correlation between devices | C38: =IFERROR(CORREL('Enter data'!$B$77:$B$106,'Enter data'!$C$77:$C$106),"") | D38: High correlation can hide a constant offset.
