Workbook

Sheet Start here
B1: BCH-05 Isoelectric point from a protein sequence
B2: Excel version of the card. It does the same calculations as the R script bch05_isoelectric_point.R.
B4: How to use this workbook
B5: 1. Go to the 'Enter data' sheet. Type only in the yellow cells with blue text. Grey cells are calculated for you.
B6: 2. Fill the blocks that apply. Leave rows you did not use empty. The grey italic row above each table is an example of the format and is not used.
B7: 3. Open the 'Results' sheet. Everything there is calculated. Yellow cells on that sheet are settings you may change.
B9: What the colours mean
B10: Yellow cell, blue text: you type here.
B11: Grey cell: a formula. Sheets are protected without a password so formulas are not overwritten by accident (Review > Unprotect Sheet).
B13: Assumptions and sources
B14: Paste one sequence (one-letter codes) in the yellow cell. Net charge is the sum of the fractions protonated (N-terminus, Lys, Arg, His) minus the fractions deprotonated (C-terminus, Asp, Glu, Cys, Tyr), from the Henderson-Hasselbalch relation. Interactions between groups are ignored.
B15: pK sets: EMBOSS (Rice, Longden, Bleasby 2000, Trends Genet 16:276-277) and the mean measured values of Grimsley, Gray, Pace (2009), Protein Sci 18:247-251 (Arg uses the EMBOSS value there). Cys and Tyr counts include all of them in the sequence.
... B23: Compiled by Emmanuel G. Lozano, Department of Biology, College of Arts and Sciences, Pampanga State University. Original material is licensed CC BY-NC 4.0: credit required, non-commercial use only.

Sheet Enter data
A1: Enter your data
A2: Type only in yellow cells. Leave unused rows empty.
A4: 1. Sequence (one-letter codes, letters only)
A5: Sequence
A6: PQGGGGWGQPHGGGWGQPHGGGGWGQGGSHSQG
A7: PQGGGGWGQPHGGGWGQPHGGGGWGQGGSHSQG

Sheet Results
B1: Results
B2: Everything on this sheet is calculated. Change only the yellow settings.
B4: Composition
B5: Lys (K) | C5: =IFERROR((LEN(UPPER('Enter data'!$A$7))-LEN(SUBSTITUTE(UPPER('Enter data'!$A$7),"K",""))),"") -> 0
B6: Arg (R) | C6: =IFERROR((LEN(UPPER('Enter data'!$A$7))-LEN(SUBSTITUTE(UPPER('Enter data'!$A$7),"R",""))),"") -> 0
B7: His (H) | C7: =IFERROR((LEN(UPPER('Enter data'!$A$7))-LEN(SUBSTITUTE(UPPER('Enter data'!$A$7),"H",""))),"") -> 3
B8: Asp (D) | C8: =IFERROR((LEN(UPPER('Enter data'!$A$7))-LEN(SUBSTITUTE(UPPER('Enter data'!$A$7),"D",""))),"") -> 0
B9: Glu (E) | C9: =IFERROR((LEN(UPPER('Enter data'!$A$7))-LEN(SUBSTITUTE(UPPER('Enter data'!$A$7),"E",""))),"") -> 0
B10: Cys (C) | C10: =IFERROR((LEN(UPPER('Enter data'!$A$7))-LEN(SUBSTITUTE(UPPER('Enter data'!$A$7),"C",""))),"") -> 0
B11: Tyr (Y) | C11: =IFERROR((LEN(UPPER('Enter data'!$A$7))-LEN(SUBSTITUTE(UPPER('Enter data'!$A$7),"Y",""))),"") -> 0
B12: Length | C12: =IFERROR(LEN(UPPER('Enter data'!$A$7)),"") -> 33
B14: pK values (N-terminus, C-terminus, Lys, Arg, His, Asp, Glu, Cys, Tyr)
B15: Group | C15: EMBOSS | D15: Grimsley
B16: N-terminus | C16: 8.6 | D16: 7.7
B17: C-terminus | C17: 3.6 | D17: 3.3
B18: Lys | C18: 10.8 | D18: 10.5
B19: Arg | C19: 12.5 | D19: 12.5
B20: His | C20: 6.5 | D20: 6.6
B21: Asp | C21: 3.9 | D21: 3.5
B22: Glu | C22: 4.1 | D22: 4.2
B23: Cys | C23: 8.5 | D23: 6.8
B24: Tyr | C24: 10.1 | D24: 10.3
B27: Net charge on a pH grid
B28: pH | C28: Net charge (EMBOSS) | D28: Net charge (Grimsley)
B29: 0 | C29: =IFERROR(1/(1+10^(B29-$C$16))+$C$5/(1+10^(B29-$C$18))+$C$6/(1+10^(B29-$C$19))+$C$7/(1+10^(B29-$C$20))-(1/(1+10^($C$17-B29))+$C$8/(1+10^($C$21-B29))+$C$9/(1+10^($C$22-B29))+$C$10/(1+10^($C$23-B29))+$C$11/(1+10^($C$24-B29))),"") -> 3.9997479 | D29: =IFERROR(1/(1+10^(B29-$D$16))+$C$5/(1+10^(B29-$D$18))+$C$6/(1+10^(B29-$D$19))+$C$7/(1+10^(B29-$D$20))-(1/(1+10^($D$17-B29))+$C$8/(1+10^($D$21-B29))+$C$9/(1+10^($D$22-B29))+$C$10/(1+10^($D$23-B29))+$C$11/(1+10^($D$24-B29))),"") -> 3.9994983
B30: 0.1 | C30: =IFERROR(1/(1+10^(B30-$C$16))+$C$5/(1+10^(B30-$C$18))+$C$6/(1+10^(B30-$C$19))+$C$7/(1+10^(B30-$C$20))-(1/(1+10^($C$17-B30))+$C$8/(1+10^($C$21-B30))+$C$9/(1+10^($C$22-B30))+$C$10/(1+10^($C$23-B30))+$C$11/(1+10^($C$24-B30))),"") -> 3.9996827 | D30: =IFERROR(1/(1+10^(B30-$D$16))+$C$5/(1+10^(B30-$D$18))+$C$6/(1+10^(B30-$D$19))+$C$7/(1+10^(B30-$D$20))-(1/(1+10^($D$17-B30))+$C$8/(1+10^($D$21-B30))+$C$9/(1+10^($D$22-B30))+$C$10/(1+10^($D$23-B30))+$C$11/(1+10^($D$24-B30))),"") -> 3.9993685
B31: 0.2 | C31: =IFERROR(1/(1+10^(B31-$C$16))+$C$5/(1+10^(B31-$C$18))+$C$6/(1+10^(B31-$C$19))+$C$7/(1+10^(B31-$C$20))-(1/(1+10^($C$17-B31))+$C$8/(1+10^($C$21-B31))+$C$9/(1+10^($C$22-B31))+$C$10/(1+10^($C$23-B31))+$C$11/(1+10^($C$24-B31))),"") -> 3.9996005 | D31: =IFERROR(1/(1+10^(B31-$D$16))+$C$5/(1+10^(B31-$D$18))+$C$6/(1+10^(B31-$D$19))+$C$7/(1+10^(B31-$D$20))-(1/(1+10^($D$17-B31))+$C$8/(1+10^($D$21-B31))+$C$9/(1+10^($D$22-B31))+$C$10/(1+10^($D$23-B31))+$C$11/(1+10^($D$24-B31))),"") -> 3.9992051
B32: 0.3 | C32: =IFERROR(1/(1+10^(B32-$C$16))+$C$5/(1+10^(B32-$C$18))+$C$6/(1+10^(B32-$C$19))+$C$7/(1+10^(B32-$C$20))-(1/(1+10^($C$17-B32))+$C$8/(1+10^($C$21-B32))+$C$9/(1+10^($C$22-B32))+$C$10/(1+10^($C$23-B32))+$C$11/(1+10^($C$24-B32))),"") -> 3.9994972 | D32: =IFERROR(1/(1+10^(B32-$D$16))+$C$5/(1+10^(B32-$D$18))+$C$6/(1+10^(B32-$D$19))+$C$7/(1+10^(B32-$D$20))-(1/(1+10^($D$17-B32))+$C$8/(1+10^($D$21-B32))+$C$9/(1+10^($D$22-B32))+$C$10/(1+10^($D$23-B32))+$C$11/(1+10^($D$24-B32))),"") -> 3.9989995
B33: 0.4 | C33: =IFERROR(1/(1+10^(B33-$C$16))+$C$5/(1+10^(B33-$C$18))+$C$6/(1+10^(B33-$C$19))+$C$7/(1+10^(B33-$C$20))-(1/(1+10^($C$17-B33))+$C$8/(1+10^($C$21-B33))+$C$9/(1+10^($C$22-B33))+$C$10/(1+10^($C$23-B33))+$C$11/(1+10^($C$24-B33))),"") -> 3.9993671 | D33: =IFERROR(1/(1+10^(B33-$D$16))+$C$5/(1+10^(B33-$D$18))+$C$6/(1+10^(B33-$D$19))+$C$7/(1+10^(B33-$D$20))-(1/(1+10^($D$17-B33))+$C$8/(1+10^($D$21-B33))+$C$9/(1+10^($D$22-B33))+$C$10/(1+10^($D$23-B33))+$C$11/(1+10^($D$24-B33))),"") -> 3.9987407
B34: 0.5 | C34: =IFERROR(1/(1+10^(B34-$C$16))+$C$5/(1+10^(B34-$C$18))+$C$6/(1+10^(B34-$C$19))+$C$7/(1+10^(B34-$C$20))-(1/(1+10^($C$17-B34))+$C$8/(1+10^($C$21-B34))+$C$9/(1+10^($C$22-B34))+$C$10/(1+10^($C$23-B34))+$C$11/(1+10^($C$24-B34))),"") -> 3.9992033 | D34: =IFERROR(1/(1+10^(B34-$D$16))+$C$5/(1+10^(B34-$D$18))+$C$6/(1+10^(B34-$D$19))+$C$7/(1+10^(B34-$D$20))-(1/(1+10^($D$17-B34))+$C$8/(1+10^($D$21-B34))+$C$9/(1+10^($D$22-B34))+$C$10/(1+10^($D$23-B34))+$C$11/(1+10^($D$24-B34))),"") -> 3.9984152
B35: 0.6 | C35: =IFERROR(1/(1+10^(B35-$C$16))+$C$5/(1+10^(B35-$C$18))+$C$6/(1+10^(B35-$C$19))+$C$7/(1+10^(B35-$C$20))-(1/(1+10^($C$17-B35))+$C$8/(1+10^($C$21-B35))+$C$9/(1+10^($C$22-B35))+$C$10/(1+10^($C$23-B35))+$C$11/(1+10^($C$24-B35))),"") -> 3.9989972 | D35: =IFERROR(1/(1+10^(B35-$D$16))+$C$5/(1+10^(B35-$D$18))+$C$6/(1+10^(B35-$D$19))+$C$7/(1+10^(B35-$D$20))-(1/(1+10^($D$17-B35))+$C$8/(1+10^($D$21-B35))+$C$9/(1+10^($D$22-B35))+$C$10/(1+10^($D$23-B35))+$C$11/(1+10^($D$24-B35))),"") -> 3.9980056
B36: 0.7 | C36: =IFERROR(1/(1+10^(B36-$C$16))+$C$5/(1+10^(B36-$C$18))+$C$6/(1+10^(B36-$C$19))+$C$7/(1+10^(B36-$C$20))-(1/(1+10^($C$17-B36))+$C$8/(1+10^($C$21-B36))+$C$9/(1+10^($C$22-B36))+$C$10/(1+10^($C$23-B36))+$C$11/(1+10^($C$24-B36))),"") -> 3.9987379 | D36: =IFERROR(1/(1+10^(B36-$D$16))+$C$5/(1+10^(B36-$D$18))+$C$6/(1+10^(B36-$D$19))+$C$7/(1+10^(B36-$D$20))-(1/(1+10^($D$17-B36))+$C$8/(1+10^($D$21-B36))+$C$9/(1+10^($D$22-B36))+$C$10/(1+10^($D$23-B36))+$C$11/(1+10^($D$24-B36))),"") -> 3.9974905
B37: 0.8 | C37: =IFERROR(1/(1+10^(B37-$C$16))+$C$5/(1+10^(B37-$C$18))+$C$6/(1+10^(B37-$C$19))+$C$7/(1+10^(B37-$C$20))-(1/(1+10^($C$17-B37))+$C$8/(1+10^($C$21-B37))+$C$9/(1+10^($C$22-B37))+$C$10/(1+10^($C$23-B37))+$C$11/(1+10^($C$24-B37))),"") -> 3.9984116 | D37: =IFERROR(1/(1+10^(B37-$D$16))+$C$5/(1+10^(B37-$D$18))+$C$6/(1+10^(B37-$D$19))+$C$7/(1+10^(B37-$D$20))-(1/(1+10^($D$17-B37))+$C$8/(1+10^($D$21-B37))+$C$9/(1+10^($D$22-B37))+$C$10/(1+10^($D$23-B37))+$C$11/(1+10^($D$24-B37))),"") -> 3.9968428
B38: 0.9 | C38: =IFERROR(1/(1+10^(B38-$C$16))+$C$5/(1+10^(B38-$C$18))+$C$6/(1+10^(B38-$C$19))+$C$7/(1+10^(B38-$C$20))-(1/(1+10^($C$17-B38))+$C$8/(1+10^($C$21-B38))+$C$9/(1+10^($C$22-B38))+$C$10/(1+10^($C$23-B38))+$C$11/(1+10^($C$24-B38))),"") -> 3.9980012 | D38: =IFERROR(1/(1+10^(B38-$D$16))+$C$5/(1+10^(B38-$D$18))+$C$6/(1+10^(B38-$D$19))+$C$7/(1+10^(B38-$D$20))-(1/(1+10^($D$17-B38))+$C$8/(1+10^($D$21-B38))+$C$9/(1+10^($D$22-B38))+$C$10/(1+10^($D$23-B38))+$C$11/(1+10^($D$24-B38))),"") -> 3.9960286
B39: 1 | C39: =IFERROR(1/(1+10^(B39-$C$16))+$C$5/(1+10^(B39-$C$18))+$C$6/(1+10^(B39-$C$19))+$C$7/(1+10^(B39-$C$20))-(1/(1+10^($C$17-B39))+$C$8/(1+10^($C$21-B39))+$C$9/(1+10^($C$22-B39))+$C$10/(1+10^($C$23-B39))+$C$11/(1+10^($C$24-B39))),"") -> 3.9974849 | D39: =IFERROR(1/(1+10^(B39-$D$16))+$C$5/(1+10^(B39-$D$18))+$C$6/(1+10^(B39-$D$19))+$C$7/(1+10^(B39-$D$20))-(1/(1+10^($D$17-B39))+$C$8/(1+10^($D$21-B39))+$C$9/(1+10^($D$22-B39))+$C$10/(1+10^($D$23-B39))+$C$11/(1+10^($D$24-B39))),"") -> 3.9950054
B40: 1.1 | C40: =IFERROR(1/(1+10^(B40-$C$16))+$C$5/(1+10^(B40-$C$18))+$C$6/(1+10^(B40-$C$19))+$C$7/(1+10^(B40-$C$20))-(1/(1+10^($C$17-B40))+$C$8/(1+10^($C$21-B40))+$C$9/(1+10^($C$22-B40))+$C$10/(1+10^($C$23-B40))+$C$11/(1+10^($C$24-B40))),"") -> 3.9968357 | D40: =IFERROR(1/(1+10^(B40-$D$16))+$C$5/(1+10^(B40-$D$18))+$C$6/(1+10^(B40-$D$19))+$C$7/(1+10^(B40-$D$20))-(1/(1+10^($D$17-B40))+$C$8/(1+10^($D$21-B40))+$C$9/(1+10^($D$22-B40))+$C$10/(1+10^($D$23-B40))+$C$11/(1+10^($D$24-B40))),"") -> 3.9937202
... B169: 14 | C169: =IFERROR(1/(1+10^(B169-$C$16))+$C$5/(1+10^(B169-$C$18))+$C$6/(1+10^(B169-$C$19))+$C$7/(1+10^(B169-$C$20))-(1/(1+10^($C$17-B169))+$C$8/(1+10^($C$21-B169))+$C$9/(1+10^($C$22-B169))+$C$10/(1+10^($C$23-B169))+$C$11/(1+10^($C$24-B169))),"") -> -0.99999592 | D169: =IFERROR(1/(1+10^(B169-$D$16))+$C$5/(1+10^(B169-$D$18))+$C$6/(1+10^(B169-$D$19))+$C$7/(1+10^(B169-$D$20))-(1/(1+10^($D$17-B169))+$C$8/(1+10^($D$21-B169))+$C$9/(1+10^($D$22-B169))+$C$10/(1+10^($D$23-B169))+$C$11/(1+10^($D$24-B169))),"") -> -0.99999938
B172: Isoelectric point
B173: pI with the EMBOSS pK values | C173: =IFERROR(INDEX($B$29:$B$169,MATCH(0,$C$29:$C$169,-1))+INDEX($C$29:$C$169,MATCH(0,$C$29:$C$169,-1))*(INDEX($B$29:$B$169,MATCH(0,$C$29:$C$169,-1)+1)-INDEX($B$29:$B$169,MATCH(0,$C$29:$C$169,-1)))/(INDEX($C$29:$C$169,MATCH(0,$C$29:$C$169,-1))-INDEX($C$29:$C$169,MATCH(0,$C$29:$C$169,-1)+1)),"") -> 7.8111232
B174: pI with the Grimsley pK values | C174: =IFERROR(INDEX($B$29:$B$169,MATCH(0,$D$29:$D$169,-1))+INDEX($D$29:$D$169,MATCH(0,$D$29:$D$169,-1))*(INDEX($B$29:$B$169,MATCH(0,$D$29:$D$169,-1)+1)-INDEX($B$29:$B$169,MATCH(0,$D$29:$D$169,-1)))/(INDEX($D$29:$D$169,MATCH(0,$D$29:$D$169,-1))-INDEX($D$29:$D$169,MATCH(0,$D$29:$D$169,-1)+1)),"") -> 7.4598782
...
