Workbook

Sheet Start here
B1: BCH-03 Sugar content of beverages by refractometry
B2: Excel version of the card. It does the same calculations as the R script bch03_refractometry.R.
B4: How to use this workbook
B5: 1. Go to the 'Enter data' sheet. Type only in the yellow cells with blue text. Grey cells are calculated for you.
B6: 2. Fill the blocks that apply. Leave rows you did not use empty. The grey italic row above each table is an example of the format and is not used.
B7: 3. Open the 'Results' sheet. Everything there is calculated. Yellow cells on that sheet are settings you may change.
B9: What the colours mean
B10: Yellow cell, blue text: you type here.
B11: Grey cell: a formula. Sheets are protected without a password so formulas are not overwritten by accident (Review > Unprotect Sheet).
B13: Assumptions and sources
B14: A Brix scale is percent sucrose by mass. Fit reading = intercept + slope x sucrose %, then convert each beverage reading with sucrose % = (reading - intercept) / slope.
B15: Grams per 100 mL = percent by mass x solution density; density is approximated as 0.9982 + 0.0038 x percent (within about 0.6 percent below 20 percent w/w).
... B20: Compiled by Emmanuel G. Lozano, Department of Biology, College of Arts and Sciences, Pampanga State University. Original material is licensed CC BY-NC 4.0: credit required, non-commercial use only.

Sheet Enter data
A1: Enter your data
A2: Type only in yellow cells. Leave unused rows empty.
A4: 1. Sucrose standards
A5: Sucrose (% by mass) | B5: Refractometer reading
A6: 10 | B6: 10.1
A21: 2. Beverages (one row per reading)
A22: Beverage | B22: Refractometer reading | C22: Label sugar (g per 100 mL)
A23: cola | B23: 10.6 | C23: 10.6

Sheet Results
B1: Results
B2: Everything on this sheet is calculated. Change only the yellow settings.
B4: Calibration line (reading = intercept + slope x sucrose %)
B5: Points used | C5: =IFERROR(SUMPRODUCT(--ISNUMBER('Enter data'!$A$7:$A$18),--ISNUMBER('Enter data'!$B$7:$B$18)),"") -> 0
B6: Slope (reading units per %) | C6: =IFERROR(SLOPE('Enter data'!$B$7:$B$18,'Enter data'!$A$7:$A$18),"")
B7: Intercept (reading units per %) | C7: =IFERROR(INTERCEPT('Enter data'!$B$7:$B$18,'Enter data'!$A$7:$A$18),"")
B8: R squared | C8: =IFERROR(RSQ('Enter data'!$B$7:$B$18,'Enter data'!$A$7:$A$18),"")
B9: Residual standard deviation | C9: =IFERROR(STEYX('Enter data'!$B$7:$B$18,'Enter data'!$A$7:$A$18),"")
B10: Standard error of the slope | C10: =IFERROR($C$9/SQRT(DEVSQ('Enter data'!$A$7:$A$18)),"")
B11: 95% interval for the slope, lower | C11: =IFERROR($C$6-TINV(0.05,$C$5-2)*$C$10,"")
B12: 95% interval for the slope, upper | C12: =IFERROR($C$6+TINV(0.05,$C$5-2)*$C$10,"")
B13: Reading of distilled water (should be 0) | C13: =IFERROR(IFERROR(INDEX('Enter data'!$B$7:$B$18,MATCH(0,'Enter data'!$A$7:$A$18,0)),"no 0% standard"),"") -> no 0% standard
B15: Beverages
B16: Beverage | C16: Reading | D16: Sucrose (% by mass) | E16: g per 100 mL | F16: Label | G16: Difference from label
B17: =IFERROR(IF(ISNUMBER('Enter data'!$B$24),'Enter data'!$A$24,""),"") | C17: =IFERROR(IF(ISNUMBER('Enter data'!$B$24),'Enter data'!$B$24,""),"") | D17: =IFERROR(IF(ISNUMBER('Enter data'!$B$24),('Enter data'!$B$24-$C$7)/$C$6,""),"") | E17: =IFERROR(IF(ISNUMBER(D17),D17*(0.9982+0.0038*D17),""),"") | F17: =IFERROR(IF(ISNUMBER('Enter data'!$C$24),'Enter data'!$C$24,""),"") | G17: =IFERROR(IF(AND(ISNUMBER(E17),ISNUMBER(F17)),E17-F17,""),"")
B18: =IFERROR(IF(ISNUMBER('Enter data'!$B$25),'Enter data'!$A$25,""),"") | C18: =IFERROR(IF(ISNUMBER('Enter data'!$B$25),'Enter data'!$B$25,""),"") | D18: =IFERROR(IF(ISNUMBER('Enter data'!$B$25),('Enter data'!$B$25-$C$7)/$C$6,""),"") | E18: =IFERROR(IF(ISNUMBER(D18),D18*(0.9982+0.0038*D18),""),"") | F18: =IFERROR(IF(ISNUMBER('Enter data'!$C$25),'Enter data'!$C$25,""),"") | G18: =IFERROR(IF(AND(ISNUMBER(E18),ISNUMBER(F18)),E18-F18,""),"")
B19: =IFERROR(IF(ISNUMBER('Enter data'!$B$26),'Enter data'!$A$26,""),"") | C19: =IFERROR(IF(ISNUMBER('Enter data'!$B$26),'Enter data'!$B$26,""),"") | D19: =IFERROR(IF(ISNUMBER('Enter data'!$B$26),('Enter data'!$B$26-$C$7)/$C$6,""),"") | E19: =IFERROR(IF(ISNUMBER(D19),D19*(0.9982+0.0038*D19),""),"") | F19: =IFERROR(IF(ISNUMBER('Enter data'!$C$26),'Enter data'!$C$26,""),"") | G19: =IFERROR(IF(AND(ISNUMBER(E19),ISNUMBER(F19)),E19-F19,""),"")
B20: =IFERROR(IF(ISNUMBER('Enter data'!$B$27),'Enter data'!$A$27,""),"") | C20: =IFERROR(IF(ISNUMBER('Enter data'!$B$27),'Enter data'!$B$27,""),"") | D20: =IFERROR(IF(ISNUMBER('Enter data'!$B$27),('Enter data'!$B$27-$C$7)/$C$6,""),"") | E20: =IFERROR(IF(ISNUMBER(D20),D20*(0.9982+0.0038*D20),""),"") | F20: =IFERROR(IF(ISNUMBER('Enter data'!$C$27),'Enter data'!$C$27,""),"") | G20: =IFERROR(IF(AND(ISNUMBER(E20),ISNUMBER(F20)),E20-F20,""),"")
B21: =IFERROR(IF(ISNUMBER('Enter data'!$B$28),'Enter data'!$A$28,""),"") | C21: =IFERROR(IF(ISNUMBER('Enter data'!$B$28),'Enter data'!$B$28,""),"") | D21: =IFERROR(IF(ISNUMBER('Enter data'!$B$28),('Enter data'!$B$28-$C$7)/$C$6,""),"") | E21: =IFERROR(IF(ISNUMBER(D21),D21*(0.9982+0.0038*D21),""),"") | F21: =IFERROR(IF(ISNUMBER('Enter data'!$C$28),'Enter data'!$C$28,""),"") | G21: =IFERROR(IF(AND(ISNUMBER(E21),ISNUMBER(F21)),E21-F21,""),"")
B22: =IFERROR(IF(ISNUMBER('Enter data'!$B$29),'Enter data'!$A$29,""),"") | C22: =IFERROR(IF(ISNUMBER('Enter data'!$B$29),'Enter data'!$B$29,""),"") | D22: =IFERROR(IF(ISNUMBER('Enter data'!$B$29),('Enter data'!$B$29-$C$7)/$C$6,""),"") | E22: =IFERROR(IF(ISNUMBER(D22),D22*(0.9982+0.0038*D22),""),"") | F22: =IFERROR(IF(ISNUMBER('Enter data'!$C$29),'Enter data'!$C$29,""),"") | G22: =IFERROR(IF(AND(ISNUMBER(E22),ISNUMBER(F22)),E22-F22,""),"")
B23: =IFERROR(IF(ISNUMBER('Enter data'!$B$30),'Enter data'!$A$30,""),"") | C23: =IFERROR(IF(ISNUMBER('Enter data'!$B$30),'Enter data'!$B$30,""),"") | D23: =IFERROR(IF(ISNUMBER('Enter data'!$B$30),('Enter data'!$B$30-$C$7)/$C$6,""),"") | E23: =IFERROR(IF(ISNUMBER(D23),D23*(0.9982+0.0038*D23),""),"") | F23: =IFERROR(IF(ISNUMBER('Enter data'!$C$30),'Enter data'!$C$30,""),"") | G23: =IFERROR(IF(AND(ISNUMBER(E23),ISNUMBER(F23)),E23-F23,""),"")
B24: =IFERROR(IF(ISNUMBER('Enter data'!$B$31),'Enter data'!$A$31,""),"") | C24: =IFERROR(IF(ISNUMBER('Enter data'!$B$31),'Enter data'!$B$31,""),"") | D24: =IFERROR(IF(ISNUMBER('Enter data'!$B$31),('Enter data'!$B$31-$C$7)/$C$6,""),"") | E24: =IFERROR(IF(ISNUMBER(D24),D24*(0.9982+0.0038*D24),""),"") | F24: =IFERROR(IF(ISNUMBER('Enter data'!$C$31),'Enter data'!$C$31,""),"") | G24: =IFERROR(IF(AND(ISNUMBER(E24),ISNUMBER(F24)),E24-F24,""),"")
B25: =IFERROR(IF(ISNUMBER('Enter data'!$B$32),'Enter data'!$A$32,""),"") | C25: =IFERROR(IF(ISNUMBER('Enter data'!$B$32),'Enter data'!$B$32,""),"") | D25: =IFERROR(IF(ISNUMBER('Enter data'!$B$32),('Enter data'!$B$32-$C$7)/$C$6,""),"") | E25: =IFERROR(IF(ISNUMBER(D25),D25*(0.9982+0.0038*D25),""),"") | F25: =IFERROR(IF(ISNUMBER('Enter data'!$C$32),'Enter data'!$C$32,""),"") | G25: =IFERROR(IF(AND(ISNUMBER(E25),ISNUMBER(F25)),E25-F25,""),"")
B26: =IFERROR(IF(ISNUMBER('Enter data'!$B$33),'Enter data'!$A$33,""),"") | C26: =IFERROR(IF(ISNUMBER('Enter data'!$B$33),'Enter data'!$B$33,""),"") | D26: =IFERROR(IF(ISNUMBER('Enter data'!$B$33),('Enter data'!$B$33-$C$7)/$C$6,""),"") | E26: =IFERROR(IF(ISNUMBER(D26),D26*(0.9982+0.0038*D26),""),"") | F26: =IFERROR(IF(ISNUMBER('Enter data'!$C$33),'Enter data'!$C$33,""),"") | G26: =IFERROR(IF(AND(ISNUMBER(E26),ISNUMBER(F26)),E26-F26,""),"")
B27: =IFERROR(IF(ISNUMBER('Enter data'!$B$34),'Enter data'!$A$34,""),"") | C27: =IFERROR(IF(ISNUMBER('Enter data'!$B$34),'Enter data'!$B$34,""),"") | D27: =IFERROR(IF(ISNUMBER('Enter data'!$B$34),('Enter data'!$B$34-$C$7)/$C$6,""),"") | E27: =IFERROR(IF(ISNUMBER(D27),D27*(0.9982+0.0038*D27),""),"") | F27: =IFERROR(IF(ISNUMBER('Enter data'!$C$34),'Enter data'!$C$34,""),"") | G27: =IFERROR(IF(AND(ISNUMBER(E27),ISNUMBER(F27)),E27-F27,""),"")
B28: =IFERROR(IF(ISNUMBER('Enter data'!$B$35),'Enter data'!$A$35,""),"") | C28: =IFERROR(IF(ISNUMBER('Enter data'!$B$35),'Enter data'!$B$35,""),"") | D28: =IFERROR(IF(ISNUMBER('Enter data'!$B$35),('Enter data'!$B$35-$C$7)/$C$6,""),"") | E28: =IFERROR(IF(ISNUMBER(D28),D28*(0.9982+0.0038*D28),""),"") | F28: =IFERROR(IF(ISNUMBER('Enter data'!$C$35),'Enter data'!$C$35,""),"") | G28: =IFERROR(IF(AND(ISNUMBER(E28),ISNUMBER(F28)),E28-F28,""),"")
B29: =IFERROR(IF(ISNUMBER('Enter data'!$B$36),'Enter data'!$A$36,""),"") | C29: =IFERROR(IF(ISNUMBER('Enter data'!$B$36),'Enter data'!$B$36,""),"") | D29: =IFERROR(IF(ISNUMBER('Enter data'!$B$36),('Enter data'!$B$36-$C$7)/$C$6,""),"") | E29: =IFERROR(IF(ISNUMBER(D29),D29*(0.9982+0.0038*D29),""),"") | F29: =IFERROR(IF(ISNUMBER('Enter data'!$C$36),'Enter data'!$C$36,""),"") | G29: =IFERROR(IF(AND(ISNUMBER(E29),ISNUMBER(F29)),E29-F29,""),"")
B30: =IFERROR(IF(ISNUMBER('Enter data'!$B$37),'Enter data'!$A$37,""),"") | C30: =IFERROR(IF(ISNUMBER('Enter data'!$B$37),'Enter data'!$B$37,""),"") | D30: =IFERROR(IF(ISNUMBER('Enter data'!$B$37),('Enter data'!$B$37-$C$7)/$C$6,""),"") | E30: =IFERROR(IF(ISNUMBER(D30),D30*(0.9982+0.0038*D30),""),"") | F30: =IFERROR(IF(ISNUMBER('Enter data'!$C$37),'Enter data'!$C$37,""),"") | G30: =IFERROR(IF(AND(ISNUMBER(E30),ISNUMBER(F30)),E30-F30,""),"")
B31: =IFERROR(IF(ISNUMBER('Enter data'!$B$38),'Enter data'!$A$38,""),"") | C31: =IFERROR(IF(ISNUMBER('Enter data'!$B$38),'Enter data'!$B$38,""),"") | D31: =IFERROR(IF(ISNUMBER('Enter data'!$B$38),('Enter data'!$B$38-$C$7)/$C$6,""),"") | E31: =IFERROR(IF(ISNUMBER(D31),D31*(0.9982+0.0038*D31),""),"") | F31: =IFERROR(IF(ISNUMBER('Enter data'!$C$38),'Enter data'!$C$38,""),"") | G31: =IFERROR(IF(AND(ISNUMBER(E31),ISNUMBER(F31)),E31-F31,""),"")
B32: =IFERROR(IF(ISNUMBER('Enter data'!$B$39),'Enter data'!$A$39,""),"") | C32: =IFERROR(IF(ISNUMBER('Enter data'!$B$39),'Enter data'!$B$39,""),"") | D32: =IFERROR(IF(ISNUMBER('Enter data'!$B$39),('Enter data'!$B$39-$C$7)/$C$6,""),"") | E32: =IFERROR(IF(ISNUMBER(D32),D32*(0.9982+0.0038*D32),""),"") | F32: =IFERROR(IF(ISNUMBER('Enter data'!$C$39),'Enter data'!$C$39,""),"") | G32: =IFERROR(IF(AND(ISNUMBER(E32),ISNUMBER(F32)),E32-F32,""),"")
B33: =IFERROR(IF(ISNUMBER('Enter data'!$B$40),'Enter data'!$A$40,""),"") | C33: =IFERROR(IF(ISNUMBER('Enter data'!$B$40),'Enter data'!$B$40,""),"") | D33: =IFERROR(IF(ISNUMBER('Enter data'!$B$40),('Enter data'!$B$40-$C$7)/$C$6,""),"") | E33: =IFERROR(IF(ISNUMBER(D33),D33*(0.9982+0.0038*D33),""),"") | F33: =IFERROR(IF(ISNUMBER('Enter data'!$C$40),'Enter data'!$C$40,""),"") | G33: =IFERROR(IF(AND(ISNUMBER(E33),ISNUMBER(F33)),E33-F33,""),"")
B34: =IFERROR(IF(ISNUMBER('Enter data'!$B$41),'Enter data'!$A$41,""),"") | C34: =IFERROR(IF(ISNUMBER('Enter data'!$B$41),'Enter data'!$B$41,""),"") | D34: =IFERROR(IF(ISNUMBER('Enter data'!$B$41),('Enter data'!$B$41-$C$7)/$C$6,""),"") | E34: =IFERROR(IF(ISNUMBER(D34),D34*(0.9982+0.0038*D34),""),"") | F34: =IFERROR(IF(ISNUMBER('Enter data'!$C$41),'Enter data'!$C$41,""),"") | G34: =IFERROR(IF(AND(ISNUMBER(E34),ISNUMBER(F34)),E34-F34,""),"")
B35: =IFERROR(IF(ISNUMBER('Enter data'!$B$42),'Enter data'!$A$42,""),"") | C35: =IFERROR(IF(ISNUMBER('Enter data'!$B$42),'Enter data'!$B$42,""),"") | D35: =IFERROR(IF(ISNUMBER('Enter data'!$B$42),('Enter data'!$B$42-$C$7)/$C$6,""),"") | E35: =IFERROR(IF(ISNUMBER(D35),D35*(0.9982+0.0038*D35),""),"") | F35: =IFERROR(IF(ISNUMBER('Enter data'!$C$42),'Enter data'!$C$42,""),"") | G35: =IFERROR(IF(AND(ISNUMBER(E35),ISNUMBER(F35)),E35-F35,""),"")
B36: =IFERROR(IF(ISNUMBER('Enter data'!$B$43),'Enter data'!$A$43,""),"") | C36: =IFERROR(IF(ISNUMBER('Enter data'!$B$43),'Enter data'!$B$43,""),"") | D36: =IFERROR(IF(ISNUMBER('Enter data'!$B$43),('Enter data'!$B$43-$C$7)/$C$6,""),"") | E36: =IFERROR(IF(ISNUMBER(D36),D36*(0.9982+0.0038*D36),""),"") | F36: =IFERROR(IF(ISNUMBER('Enter data'!$C$43),'Enter data'!$C$43,""),"") | G36: =IFERROR(IF(AND(ISNUMBER(E36),ISNUMBER(F36)),E36-F36,""),"")
B37: =IFERROR(IF(ISNUMBER('Enter data'!$B$44),'Enter data'!$A$44,""),"") | C37: =IFERROR(IF(ISNUMBER('Enter data'!$B$44),'Enter data'!$B$44,""),"") | D37: =IFERROR(IF(ISNUMBER('Enter data'!$B$44),('Enter data'!$B$44-$C$7)/$C$6,""),"") | E37: =IFERROR(IF(ISNUMBER(D37),D37*(0.9982+0.0038*D37),""),"") | F37: =IFERROR(IF(ISNUMBER('Enter data'!$C$44),'Enter data'!$C$44,""),"") | G37: =IFERROR(IF(AND(ISNUMBER(E37),ISNUMBER(F37)),E37-F37,""),"")
B38: =IFERROR(IF(ISNUMBER('Enter data'!$B$45),'Enter data'!$A$45,""),"") | C38: =IFERROR(IF(ISNUMBER('Enter data'!$B$45),'Enter data'!$B$45,""),"") | D38: =IFERROR(IF(ISNUMBER('Enter data'!$B$45),('Enter data'!$B$45-$C$7)/$C$6,""),"") | E38: =IFERROR(IF(ISNUMBER(D38),D38*(0.9982+0.0038*D38),""),"") | F38: =IFERROR(IF(ISNUMBER('Enter data'!$C$45),'Enter data'!$C$45,""),"") | G38: =IFERROR(IF(AND(ISNUMBER(E38),ISNUMBER(F38)),E38-F38,""),"")
B39: =IFERROR(IF(ISNUMBER('Enter data'!$B$46),'Enter data'!$A$46,""),"") | C39: =IFERROR(IF(ISNUMBER('Enter data'!$B$46),'Enter data'!$B$46,""),"") | D39: =IFERROR(IF(ISNUMBER('Enter data'!$B$46),('Enter data'!$B$46-$C$7)/$C$6,""),"") | E39: =IFERROR(IF(ISNUMBER(D39),D39*(0.9982+0.0038*D39),""),"") | F39: =IFERROR(IF(ISNUMBER('Enter data'!$C$46),'Enter data'!$C$46,""),"") | G39: =IFERROR(IF(AND(ISNUMBER(E39),ISNUMBER(F39)),E39-F39,""),"")
B40: =IFERROR(IF(ISNUMBER('Enter data'!$B$47),'Enter data'!$A$47,""),"") | C40: =IFERROR(IF(ISNUMBER('Enter data'!$B$47),'Enter data'!$B$47,""),"") | D40: =IFERROR(IF(ISNUMBER('Enter data'!$B$47),('Enter data'!$B$47-$C$7)/$C$6,""),"") | E40: =IFERROR(IF(ISNUMBER(D40),D40*(0.9982+0.0038*D40),""),"") | F40: =IFERROR(IF(ISNUMBER('Enter data'!$C$47),'Enter data'!$C$47,""),"") | G40: =IFERROR(IF(AND(ISNUMBER(E40),ISNUMBER(F40)),E40-F40,""),"")
B41: =IFERROR(IF(ISNUMBER('Enter data'!$B$48),'Enter data'!$A$48,""),"") | C41: =IFERROR(IF(ISNUMBER('Enter data'!$B$48),'Enter data'!$B$48,""),"") | D41: =IFERROR(IF(ISNUMBER('Enter data'!$B$48),('Enter data'!$B$48-$C$7)/$C$6,""),"") | E41: =IFERROR(IF(ISNUMBER(D41),D41*(0.9982+0.0038*D41),""),"") | F41: =IFERROR(IF(ISNUMBER('Enter data'!$C$48),'Enter data'!$C$48,""),"") | G41: =IFERROR(IF(AND(ISNUMBER(E41),ISNUMBER(F41)),E41-F41,""),"")
B42: =IFERROR(IF(ISNUMBER('Enter data'!$B$49),'Enter data'!$A$49,""),"") | C42: =IFERROR(IF(ISNUMBER('Enter data'!$B$49),'Enter data'!$B$49,""),"") | D42: =IFERROR(IF(ISNUMBER('Enter data'!$B$49),('Enter data'!$B$49-$C$7)/$C$6,""),"") | E42: =IFERROR(IF(ISNUMBER(D42),D42*(0.9982+0.0038*D42),""),"") | F42: =IFERROR(IF(ISNUMBER('Enter data'!$C$49),'Enter data'!$C$49,""),"") | G42: =IFERROR(IF(AND(ISNUMBER(E42),ISNUMBER(F42)),E42-F42,""),"")
...
