Workbook

Sheet Start here
B1: BOT-05 Stem anatomy: vascular bundle density and vessel width
B2: Excel version of the card. It does the same calculations as the R script bot05_vascular_anatomy.R.
B4: How to use this workbook
B5: 1. Go to the 'Enter data' sheet. Type only in the yellow cells with blue text. Grey cells are calculated for you.
B6: 2. Fill the blocks that apply. Leave rows you did not use empty. The grey italic row above each table is an example of the format and is not used.
B7: 3. Open the 'Results' sheet. Everything there is calculated. Yellow cells on that sheet are settings you may change.
B9: What the colours mean
B10: Yellow cell, blue text: you type here.
B11: Grey cell: a formula. Sheets are protected without a password so formulas are not overwritten by accident (Review > Unprotect Sheet).
B13: Assumptions and sources
B14: Field area = pi x (diameter / 2)^2; bundle density = bundles / field area, in bundles per mm2.
B15: Sections from one stem are not independent replicates: with only a few plants per group the comparison below overstates the evidence. Report the plant means as well.
... B22: Compiled by Emmanuel G. Lozano, Department of Biology, College of Arts and Sciences, Pampanga State University. Original material is licensed CC BY-NC 4.0: credit required, non-commercial use only.

Sheet Enter data
A1: Enter your data
A2: Type only in yellow cells. Leave unused rows empty.
A4: 1. Group A sections (for example monocot stem)
A5: Plant | B5: Bundles in field | C5: Field diameter (mm) | D5: Density (bundles per mm2)
A6: stem 1 | B6: 21 | C6: 1.8
A7: stem 1 | B7: 33 | C7: 1.8 | D7: =IF(AND(ISNUMBER(B7),ISNUMBER(C7)),B7/(PI()*(C7/2)^2),"") -> 12.968181
A8: stem 2 | B8: 28 | C8: 1.8 | D8: =IF(AND(ISNUMBER(B8),ISNUMBER(C8)),B8/(PI()*(C8/2)^2),"") -> 11.003305
A9: stem 1 | B9: 17 | C9: 1.8 | D9: =IF(AND(ISNUMBER(B9),ISNUMBER(C9)),B9/(PI()*(C9/2)^2),"") -> 6.6805779
A10: stem 2 | B10: 26 | C10: 1.8 | D10: =IF(AND(ISNUMBER(B10),ISNUMBER(C10)),B10/(PI()*(C10/2)^2),"") -> 10.217354
A11: stem 1 | B11: 30 | C11: 1.8 | D11: =IF(AND(ISNUMBER(B11),ISNUMBER(C11)),B11/(PI()*(C11/2)^2),"") -> 11.789255
A12: stem 2 | B12: 26 | C12: 1.8 | D12: =IF(AND(ISNUMBER(B12),ISNUMBER(C12)),B12/(PI()*(C12/2)^2),"") -> 10.217354
A13: stem 1 | B13: 31 | C13: 1.8 | D13: =IF(AND(ISNUMBER(B13),ISNUMBER(C13)),B13/(PI()*(C13/2)^2),"") -> 12.18223
A14: stem 2 | B14: 29 | C14: 1.8 | D14: =IF(AND(ISNUMBER(B14),ISNUMBER(C14)),B14/(PI()*(C14/2)^2),"") -> 11.39628
A15: stem 1 | B15: 35 | C15: 1.8 | D15: =IF(AND(ISNUMBER(B15),ISNUMBER(C15)),B15/(PI()*(C15/2)^2),"") -> 13.754131
A16: stem 2 | B16: 35 | C16: 1.8 | D16: =IF(AND(ISNUMBER(B16),ISNUMBER(C16)),B16/(PI()*(C16/2)^2),"") -> 13.754131
A17: stem 1 | B17: 31 | C17: 1.8 | D17: =IF(AND(ISNUMBER(B17),ISNUMBER(C17)),B17/(PI()*(C17/2)^2),"") -> 12.18223
A18: stem 2 | B18: 28 | C18: 1.8 | D18: =IF(AND(ISNUMBER(B18),ISNUMBER(C18)),B18/(PI()*(C18/2)^2),"") -> 11.003305
D19: =IF(AND(ISNUMBER(B19),ISNUMBER(C19)),B19/(PI()*(C19/2)^2),"")
D20: =IF(AND(ISNUMBER(B20),ISNUMBER(C20)),B20/(PI()*(C20/2)^2),"")
D21: =IF(AND(ISNUMBER(B21),ISNUMBER(C21)),B21/(PI()*(C21/2)^2),"")
D22: =IF(AND(ISNUMBER(B22),ISNUMBER(C22)),B22/(PI()*(C22/2)^2),"")
D23: =IF(AND(ISNUMBER(B23),ISNUMBER(C23)),B23/(PI()*(C23/2)^2),"")
D24: =IF(AND(ISNUMBER(B24),ISNUMBER(C24)),B24/(PI()*(C24/2)^2),"")
D25: =IF(AND(ISNUMBER(B25),ISNUMBER(C25)),B25/(PI()*(C25/2)^2),"")
D26: =IF(AND(ISNUMBER(B26),ISNUMBER(C26)),B26/(PI()*(C26/2)^2),"")
A29: 2. Group B sections (for example dicot stem)
A30: Plant | B30: Bundles in field | C30: Field diameter (mm) | D30: Density (bundles per mm2)
A31: stem 2 | B31: 8 | C31: 1.8
A32: stem 3 | B32: 9 | C32: 1.8 | D32: =IF(AND(ISNUMBER(B32),ISNUMBER(C32)),B32/(PI()*(C32/2)^2),"") -> 3.5367765
A33: stem 4 | B33: 6 | C33: 1.8 | D33: =IF(AND(ISNUMBER(B33),ISNUMBER(C33)),B33/(PI()*(C33/2)^2),"") -> 2.357851
A34: stem 3 | B34: 13 | C34: 1.8 | D34: =IF(AND(ISNUMBER(B34),ISNUMBER(C34)),B34/(PI()*(C34/2)^2),"") -> 5.1086772
A35: stem 4 | B35: 14 | C35: 1.8 | D35: =IF(AND(ISNUMBER(B35),ISNUMBER(C35)),B35/(PI()*(C35/2)^2),"") -> 5.5016524
A36: stem 3 | B36: 8 | C36: 1.8 | D36: =IF(AND(ISNUMBER(B36),ISNUMBER(C36)),B36/(PI()*(C36/2)^2),"") -> 3.1438013
A37: stem 4 | B37: 10 | C37: 1.8 | D37: =IF(AND(ISNUMBER(B37),ISNUMBER(C37)),B37/(PI()*(C37/2)^2),"") -> 3.9297517
A38: stem 3 | B38: 9 | C38: 1.8 | D38: =IF(AND(ISNUMBER(B38),ISNUMBER(C38)),B38/(PI()*(C38/2)^2),"") -> 3.5367765
A39: stem 4 | B39: 2 | C39: 1.8 | D39: =IF(AND(ISNUMBER(B39),ISNUMBER(C39)),B39/(PI()*(C39/2)^2),"") -> 0.78595034
A40: stem 3 | B40: 14 | C40: 1.8 | D40: =IF(AND(ISNUMBER(B40),ISNUMBER(C40)),B40/(PI()*(C40/2)^2),"") -> 5.5016524
A41: stem 4 | B41: 3 | C41: 1.8 | D41: =IF(AND(ISNUMBER(B41),ISNUMBER(C41)),B41/(PI()*(C41/2)^2),"") -> 1.1789255
A42: stem 3 | B42: 6 | C42: 1.8 | D42: =IF(AND(ISNUMBER(B42),ISNUMBER(C42)),B42/(PI()*(C42/2)^2),"") -> 2.357851
A43: stem 4 | B43: 14 | C43: 1.8 | D43: =IF(AND(ISNUMBER(B43),ISNUMBER(C43)),B43/(PI()*(C43/2)^2),"") -> 5.5016524
...

Sheet Results
B1: Results
B2: Everything on this sheet is calculated. Change only the yellow settings.
B4: Bundle density (bundles per mm2)
B5: Group | C5: n | D5: Mean | E5: SD | F5: SE | G5: Min | H5: Max
B6: =IFERROR("Group A","") -> Group A | C6: =IFERROR(COUNT('Enter data'!$D$7:$D$26),"") -> 12 | D6: =IFERROR(AVERAGE('Enter data'!$D$7:$D$26),"") -> 11.429028 | E6: =IFERROR(STDEV('Enter data'!$D$7:$D$26),"") -> 1.9139019 | F6: =IFERROR(STDEV('Enter data'!$D$7:$D$26)/SQRT(COUNT('Enter data'!$D$7:$D$26)),"") -> 0.55249589 | G6: =IFERROR(MIN('Enter data'!$D$7:$D$26),"") -> 6.6805779 | H6: =IFERROR(MAX('Enter data'!$D$7:$D$26),"") -> 13.754131
B7: =IFERROR("Group B","") -> Group B | C7: =IFERROR(COUNT('Enter data'!$D$32:$D$51),"") -> 12 | D7: =IFERROR(AVERAGE('Enter data'!$D$32:$D$51),"") -> 3.5367765 | E7: =IFERROR(STDEV('Enter data'!$D$32:$D$51),"") -> 1.6588106 | F7: =IFERROR(STDEV('Enter data'!$D$32:$D$51)/SQRT(COUNT('Enter data'!$D$32:$D$51)),"") -> 0.47885737 | G7: =IFERROR(MIN('Enter data'!$D$32:$D$51),"") -> 0.78595034 | H7: =IFERROR(MAX('Enter data'!$D$32:$D$51),"") -> 5.5016524
B10: Comparison of the two groups (Welch t test)
B11: Difference in means (group 1 minus group 2) | C11: =IFERROR($D$6-$D$7,"") -> 7.8922513
B12: Standard error of the difference | C12: =IFERROR(SQRT($F$6^2+$F$7^2),"") -> 0.73113343
B13: Degrees of freedom (Welch) | C13: =IFERROR((($E$6^2/$C$6+$E$7^2/$C$7)^2/(($E$6^2/$C$6)^2/($C$6-1)+($E$7^2/$C$7)^2/($C$7-1))),"") -> 21.564707
B14: p value (two-sided) | C14: =IFERROR(TTEST('Enter data'!$D$7:$D$26,'Enter data'!$D$32:$D$51,2,3),"") -> 3.7031422e-10
B15: 95% interval for the difference, lower | C15: =IFERROR($C$11-TINV(0.05,$C$13)*$C$12,"") -> 6.3717761
B16: 95% interval for the difference, upper | C16: =IFERROR($C$11+TINV(0.05,$C$13)*$C$12,"") -> 9.4127265
B18: Vessel width (micrometres), optional
B19: Mean, group A | C19: =IFERROR(AVERAGE('Enter data'!$A$57:$A$86),"") -> 85.6
B20: Mean, group B | C20: =IFERROR(AVERAGE('Enter data'!$B$57:$B$86),"") -> 52.7
B21: p value (Welch t test) | C21: =IFERROR(TTEST('Enter data'!$A$57:$A$86,'Enter data'!$B$57:$B$86,2,3),"") -> 1.5553963e-05
