Workbook

Sheet Start here
B1: DEV-03 Apical dominance and lateral bud outgrowth
B2: Excel version of the card. It does the same calculations as the R script dev03_apical_dominance.R.
B4: How to use this workbook
B5: 1. Go to the 'Enter data' sheet. Type only in the yellow cells with blue text. Grey cells are calculated for you.
B6: 2. Fill the blocks that apply. Leave rows you did not use empty. The grey italic row above each table is an example of the format and is not used.
B7: 3. Open the 'Results' sheet. Everything there is calculated. Yellow cells on that sheet are settings you may change.
B9: What the colours mean
B10: Yellow cell, blue text: you type here.
B11: Grey cell: a formula. Sheets are protected without a password so formulas are not overwritten by accident (Review > Unprotect Sheet).
B13: Assumptions and sources
B14: Assign plants to treatments at random before cutting anything (for example with =RAND() next to the plant list and sorting). Enter the longest lateral shoot (mm) and the number of laterals over 5 mm on the last day.
B15: Type the treatment names in the yellow cells of the names block (for example intact, decapitated, decapitated with auxin).
... B22: Compiled by Emmanuel G. Lozano, Department of Biology, College of Arts and Sciences, Pampanga State University. Original material is licensed CC BY-NC 4.0: credit required, non-commercial use only.

Sheet Enter data
A1: Enter your data
A2: Type only in yellow cells. Leave unused rows empty.
A4: 1. Treatment names
A5: Treatment 1 | B5: Treatment 2 | C5: Treatment 3
A6: intact | B6: decapitated | C6: decapitated + auxin
A9: 2. Plants of treatment 1
A10: Plant | B10: Longest lateral on the last day (mm) | C10: Laterals over 5 mm (count)
A11: P1 | B11: 27.6 | C11: 3
A12: P1 | B12: 2 | C12: 0
A13: P2 | B13: 1.9 | C13: 0
A14: P3 | B14: 1.6 | C14: 0
A15: P4 | B15: 0.9 | C15: 0
A16: P5 | B16: 1.9 | C16: 0
A17: P6 | B17: 1.8 | C17: 0
A18: P7 | B18: 1.6 | C18: 0
A19: P8 | B19: 1.3 | C19: 0
A20: P9 | B20: 2 | C20: 0
A21: P10 | B21: 2.2 | C21: 0
A29: 3. Plants of treatment 2
A30: Plant | B30: Longest lateral on the last day (mm) | C30: Laterals over 5 mm (count)
A31: P1 | B31: 27.6 | C31: 3
A32: P1 | B32: 27.9 | C32: 4
A33: P2 | B33: 25.9 | C33: 4
A34: P3 | B34: 24.1 | C34: 4
A35: P4 | B35: 34.7 | C35: 4
A36: P5 | B36: 24.8 | C36: 4
A37: P6 | B37: 18.1 | C37: 3
A38: P7 | B38: 31 | C38: 4
A39: P8 | B39: 26.2 | C39: 4
A40: P9 | B40: 7.7 | C40: 1
A41: P10 | B41: 15.2 | C41: 3
A49: 4. Plants of treatment 3
A50: Plant | B50: Longest lateral on the last day (mm) | C50: Laterals over 5 mm (count)
A51: P1 | B51: 27.6 | C51: 3
A52: P1 | B52: 6 | C52: 1
A53: P2 | B53: 4.2 | C53: 0
A54: P3 | B54: 5.3 | C54: 1
A55: P4 | B55: 7.6 | C55: 1
A56: P5 | B56: 6.1 | C56: 1
A57: P6 | B57: 4.5 | C57: 0
...

Sheet Results
B1: Results
B2: Everything on this sheet is calculated. Change only the yellow settings.
B4: Longest lateral on the last day (mm)
B5: Group | C5: n | D5: Mean | E5: SD | F5: SE | G5: Min | H5: Max
B6: =IFERROR('Enter data'!$A$6,"") -> intact | C6: =IFERROR(COUNT('Enter data'!$B$12:$B$26),"") -> 10 | D6: =IFERROR(AVERAGE('Enter data'!$B$12:$B$26),"") -> 1.72 | E6: =IFERROR(STDEV('Enter data'!$B$12:$B$26),"") -> 0.38528489 | F6: =IFERROR(STDEV('Enter data'!$B$12:$B$26)/SQRT(COUNT('Enter data'!$B$12:$B$26)),"") -> 0.12183778 | G6: =IFERROR(MIN('Enter data'!$B$12:$B$26),"") -> 0.9 | H6: =IFERROR(MAX('Enter data'!$B$12:$B$26),"") -> 2.2
B7: =IFERROR('Enter data'!$B$6,"") -> decapitated | C7: =IFERROR(COUNT('Enter data'!$B$32:$B$46),"") -> 10 | D7: =IFERROR(AVERAGE('Enter data'!$B$32:$B$46),"") -> 23.56 | E7: =IFERROR(STDEV('Enter data'!$B$32:$B$46),"") -> 7.9148524 | F7: =IFERROR(STDEV('Enter data'!$B$32:$B$46)/SQRT(COUNT('Enter data'!$B$32:$B$46)),"") -> 2.5028961 | G7: =IFERROR(MIN('Enter data'!$B$32:$B$46),"") -> 7.7 | H7: =IFERROR(MAX('Enter data'!$B$32:$B$46),"") -> 34.7
B8: =IFERROR('Enter data'!$C$6,"") -> decapitated + auxin | C8: =IFERROR(COUNT('Enter data'!$B$52:$B$66),"") -> 10 | D8: =IFERROR(AVERAGE('Enter data'!$B$52:$B$66),"") -> 5.54 | E8: =IFERROR(STDEV('Enter data'!$B$52:$B$66),"") -> 1.1568156 | F8: =IFERROR(STDEV('Enter data'!$B$52:$B$66)/SQRT(COUNT('Enter data'!$B$52:$B$66)),"") -> 0.3658172 | G8: =IFERROR(MIN('Enter data'!$B$52:$B$66),"") -> 4.2 | H8: =IFERROR(MAX('Enter data'!$B$52:$B$66),"") -> 7.6
B11: One-way analysis of variance
B12: Total observations | C12: =IFERROR(SUM($C$6:$C$8),"") -> 30
B13: Grand mean | C13: =IFERROR(SUMPRODUCT($C$6:$C$8,$D$6:$D$8)/$C$12,"") -> 10.273333
B14: Sum of squares between groups | C14: =IFERROR(SUMPRODUCT($C$6:$C$8,($D$6:$D$8-$C$13)^2),"") -> 2720.9947
B15: Sum of squares within groups | C15: =IFERROR(SUMPRODUCT($C$6:$C$8-1,$E$6:$E$8^2),"") -> 577.184
B16: F ratio | C16: =IFERROR(($C$14/(3-1))/($C$15/($C$12-3)),"") -> 63.642492
B17: p value | C17: =IFERROR(FDIST($C$16,3-1,$C$12-3),"") -> 6.0400624e-11
B18: Pair (Welch t tests) | C18: Difference in means | D18: p (unadjusted) | E18: p (Bonferroni)
B19: =IFERROR('Enter data'!$A$6&" vs "&'Enter data'!$B$6,"") -> intact vs decapitated | C19: =IFERROR($D$6-$D$7,"") -> -21.84 | D19: =IFERROR(TTEST('Enter data'!$B$12:$B$26,'Enter data'!$B$32:$B$46,2,3),"") -> 1.075857e-05 | E19: =IFERROR(MIN(1,3*D19),"") -> 3.2275711e-05
B20: =IFERROR('Enter data'!$A$6&" vs "&'Enter data'!$C$6,"") -> intact vs decapitated + auxin | C20: =IFERROR($D$6-$D$8,"") -> -3.82 | D20: =IFERROR(TTEST('Enter data'!$B$12:$B$26,'Enter data'!$B$52:$B$66,2,3),"") -> 8.2799099e-07 | E20: =IFERROR(MIN(1,3*D20),"") -> 2.483973e-06
B21: =IFERROR('Enter data'!$B$6&" vs "&'Enter data'!$C$6,"") -> decapitated vs decapitated + auxin | C21: =IFERROR($D$7-$D$8,"") -> 18.02 | D21: =IFERROR(TTEST('Enter data'!$B$32:$B$46,'Enter data'!$B$52:$B$66,2,3),"") -> 4.4556064e-05 | E21: =IFERROR(MIN(1,3*D21),"") -> 0.00013366819
B24: Share of plants with a lateral over 5 mm
B25: Treatment | C25: Plants | D25: With a lateral over 5 mm | E25: Share (%)
B26: =IFERROR('Enter data'!$A$6,"") -> intact | C26: =IFERROR(COUNT('Enter data'!$C$12:$C$26),"") -> 10 | D26: =IFERROR(COUNTIF('Enter data'!$C$12:$C$26,">0"),"") -> 0 | E26: =IFERROR(100*D26/C26,"") -> 0
B27: =IFERROR('Enter data'!$B$6,"") -> decapitated | C27: =IFERROR(COUNT('Enter data'!$C$32:$C$46),"") -> 10 | D27: =IFERROR(COUNTIF('Enter data'!$C$32:$C$46,">0"),"") -> 10 | E27: =IFERROR(100*D27/C27,"") -> 100
B28: =IFERROR('Enter data'!$C$6,"") -> decapitated + auxin | C28: =IFERROR(COUNT('Enter data'!$C$52:$C$66),"") -> 10 | D28: =IFERROR(COUNTIF('Enter data'!$C$52:$C$66,">0"),"") -> 6 | E28: =IFERROR(100*D28/C28,"") -> 60
