Workbook

Sheet Start here
B1: ECO-01 Quadrat sampling: density, frequency, cover, importance value
B2: Excel version of the card. It does the same calculations as the R script eco01_quadrat_sampling.R.
B4: How to use this workbook
B5: 1. Go to the 'Enter data' sheet. Type only in the yellow cells with blue text. Grey cells are calculated for you.
B6: 2. Fill the blocks that apply. Leave rows you did not use empty. The grey italic row above each table is an example of the format and is not used.
B7: 3. Open the 'Results' sheet. Everything there is calculated. Yellow cells on that sheet are settings you may change.
B9: What the colours mean
B10: Yellow cell, blue text: you type here.
B11: Grey cell: a formula. Sheets are protected without a password so formulas are not overwritten by accident (Review > Unprotect Sheet).
B13: Assumptions and sources
B14: Density = individuals / (quadrats x quadrat area). Frequency = % of quadrats in which the species occurs. Cover = mean percent cover per quadrat. Importance value = relative density + relative frequency + relative cover (each as % of the total over species).
B15: Enter one row per species per quadrat (include species with a count of 0). Type the number of quadrats sampled in each habitat on the Results sheet. Place quadrats at random.
... B23: Compiled by Emmanuel G. Lozano, Department of Biology, College of Arts and Sciences, Pampanga State University. Original material is licensed CC BY-NC 4.0: credit required, non-commercial use only.

Sheet Enter data
A1: Enter your data
A2: Type only in yellow cells. Leave unused rows empty.
A4: 1. Names: two habitats and up to 8 species
A5: Habitat 1 | B5: Habitat 2 | C5: Species 1 | D5: Species 2 | E5: Species 3 | F5: Species 4 | G5: Species 5 | H5: Species 6 | I5: Species 7 | J5: Species 8
A9: 2. Counts (one row per species per quadrat)
A10: Habitat | B10: Quadrat number | C10: Species | D10: Individuals counted | E10: Cover (%)
A11: grassland | B11: 1 | C11: grass A | D11: 14 | E11: 30

Sheet Results
B1: Results
B2: Everything on this sheet is calculated. Change only the yellow settings.
B4: Settings
B5: Quadrat area (m2) | C5: 1
B6: Quadrats sampled in habitat 1 | C6: 30
B7: Quadrats sampled in habitat 2 | C7: 30
B9: Habitat 1: species measures
B10: Species | C10: Density (per m2) | D10: Frequency (%) | E10: Mean cover (%) | F10: Relative density (%) | G10: Relative frequency (%) | H10: Relative cover (%) | I10: Importance value (out of 300)
B11: =IFERROR(IF('Enter data'!$C$6="","",'Enter data'!$C$6),"") | C11: =IFERROR(SUMIFS('Enter data'!$D$12:$D$411,'Enter data'!$A$12:$A$411,'Enter data'!$A$6,'Enter data'!$C$12:$C$411,'Enter data'!$C$6)/(Results!$C$6*Results!$C$5),"") -> 0 | D11: =IFERROR(100*COUNTIFS('Enter data'!$A$12:$A$411,'Enter data'!$A$6,'Enter data'!$C$12:$C$411,'Enter data'!$C$6,'Enter data'!$D$12:$D$411,">0")/Results!$C$6,"") -> 0 | E11: =IFERROR(SUMIFS('Enter data'!$E$12:$E$411,'Enter data'!$A$12:$A$411,'Enter data'!$A$6,'Enter data'!$C$12:$C$411,'Enter data'!$C$6)/Results!$C$6,"") -> 0 | F11: =IFERROR(IF(ISNUMBER(C11),100*C11/SUM(C$11:C$18),""),"") | G11: =IFERROR(IF(ISNUMBER(D11),100*D11/SUM(D$11:D$18),""),"") | H11: =IFERROR(IF(ISNUMBER(E11),100*E11/SUM(E$11:E$18),""),"") | I11: =IFERROR(IF(ISNUMBER(F11),F11+G11+H11,""),"")
B12: =IFERROR(IF('Enter data'!$D$6="","",'Enter data'!$D$6),"") | C12: =IFERROR(SUMIFS('Enter data'!$D$12:$D$411,'Enter data'!$A$12:$A$411,'Enter data'!$A$6,'Enter data'!$C$12:$C$411,'Enter data'!$D$6)/(Results!$C$6*Results!$C$5),"") -> 0 | D12: =IFERROR(100*COUNTIFS('Enter data'!$A$12:$A$411,'Enter data'!$A$6,'Enter data'!$C$12:$C$411,'Enter data'!$D$6,'Enter data'!$D$12:$D$411,">0")/Results!$C$6,"") -> 0 | E12: =IFERROR(SUMIFS('Enter data'!$E$12:$E$411,'Enter data'!$A$12:$A$411,'Enter data'!$A$6,'Enter data'!$C$12:$C$411,'Enter data'!$D$6)/Results!$C$6,"") -> 0 | F12: =IFERROR(IF(ISNUMBER(C12),100*C12/SUM(C$11:C$18),""),"") | G12: =IFERROR(IF(ISNUMBER(D12),100*D12/SUM(D$11:D$18),""),"") | H12: =IFERROR(IF(ISNUMBER(E12),100*E12/SUM(E$11:E$18),""),"") | I12: =IFERROR(IF(ISNUMBER(F12),F12+G12+H12,""),"")
B13: =IFERROR(IF('Enter data'!$E$6="","",'Enter data'!$E$6),"") | C13: =IFERROR(SUMIFS('Enter data'!$D$12:$D$411,'Enter data'!$A$12:$A$411,'Enter data'!$A$6,'Enter data'!$C$12:$C$411,'Enter data'!$E$6)/(Results!$C$6*Results!$C$5),"") -> 0 | D13: =IFERROR(100*COUNTIFS('Enter data'!$A$12:$A$411,'Enter data'!$A$6,'Enter data'!$C$12:$C$411,'Enter data'!$E$6,'Enter data'!$D$12:$D$411,">0")/Results!$C$6,"") -> 0 | E13: =IFERROR(SUMIFS('Enter data'!$E$12:$E$411,'Enter data'!$A$12:$A$411,'Enter data'!$A$6,'Enter data'!$C$12:$C$411,'Enter data'!$E$6)/Results!$C$6,"") -> 0 | F13: =IFERROR(IF(ISNUMBER(C13),100*C13/SUM(C$11:C$18),""),"") | G13: =IFERROR(IF(ISNUMBER(D13),100*D13/SUM(D$11:D$18),""),"") | H13: =IFERROR(IF(ISNUMBER(E13),100*E13/SUM(E$11:E$18),""),"") | I13: =IFERROR(IF(ISNUMBER(F13),F13+G13+H13,""),"")
B14: =IFERROR(IF('Enter data'!$F$6="","",'Enter data'!$F$6),"") | C14: =IFERROR(SUMIFS('Enter data'!$D$12:$D$411,'Enter data'!$A$12:$A$411,'Enter data'!$A$6,'Enter data'!$C$12:$C$411,'Enter data'!$F$6)/(Results!$C$6*Results!$C$5),"") -> 0 | D14: =IFERROR(100*COUNTIFS('Enter data'!$A$12:$A$411,'Enter data'!$A$6,'Enter data'!$C$12:$C$411,'Enter data'!$F$6,'Enter data'!$D$12:$D$411,">0")/Results!$C$6,"") -> 0 | E14: =IFERROR(SUMIFS('Enter data'!$E$12:$E$411,'Enter data'!$A$12:$A$411,'Enter data'!$A$6,'Enter data'!$C$12:$C$411,'Enter data'!$F$6)/Results!$C$6,"") -> 0 | F14: =IFERROR(IF(ISNUMBER(C14),100*C14/SUM(C$11:C$18),""),"") | G14: =IFERROR(IF(ISNUMBER(D14),100*D14/SUM(D$11:D$18),""),"") | H14: =IFERROR(IF(ISNUMBER(E14),100*E14/SUM(E$11:E$18),""),"") | I14: =IFERROR(IF(ISNUMBER(F14),F14+G14+H14,""),"")
B15: =IFERROR(IF('Enter data'!$G$6="","",'Enter data'!$G$6),"") | C15: =IFERROR(SUMIFS('Enter data'!$D$12:$D$411,'Enter data'!$A$12:$A$411,'Enter data'!$A$6,'Enter data'!$C$12:$C$411,'Enter data'!$G$6)/(Results!$C$6*Results!$C$5),"") -> 0 | D15: =IFERROR(100*COUNTIFS('Enter data'!$A$12:$A$411,'Enter data'!$A$6,'Enter data'!$C$12:$C$411,'Enter data'!$G$6,'Enter data'!$D$12:$D$411,">0")/Results!$C$6,"") -> 0 | E15: =IFERROR(SUMIFS('Enter data'!$E$12:$E$411,'Enter data'!$A$12:$A$411,'Enter data'!$A$6,'Enter data'!$C$12:$C$411,'Enter data'!$G$6)/Results!$C$6,"") -> 0 | F15: =IFERROR(IF(ISNUMBER(C15),100*C15/SUM(C$11:C$18),""),"") | G15: =IFERROR(IF(ISNUMBER(D15),100*D15/SUM(D$11:D$18),""),"") | H15: =IFERROR(IF(ISNUMBER(E15),100*E15/SUM(E$11:E$18),""),"") | I15: =IFERROR(IF(ISNUMBER(F15),F15+G15+H15,""),"")
B16: =IFERROR(IF('Enter data'!$H$6="","",'Enter data'!$H$6),"") | C16: =IFERROR(SUMIFS('Enter data'!$D$12:$D$411,'Enter data'!$A$12:$A$411,'Enter data'!$A$6,'Enter data'!$C$12:$C$411,'Enter data'!$H$6)/(Results!$C$6*Results!$C$5),"") -> 0 | D16: =IFERROR(100*COUNTIFS('Enter data'!$A$12:$A$411,'Enter data'!$A$6,'Enter data'!$C$12:$C$411,'Enter data'!$H$6,'Enter data'!$D$12:$D$411,">0")/Results!$C$6,"") -> 0 | E16: =IFERROR(SUMIFS('Enter data'!$E$12:$E$411,'Enter data'!$A$12:$A$411,'Enter data'!$A$6,'Enter data'!$C$12:$C$411,'Enter data'!$H$6)/Results!$C$6,"") -> 0 | F16: =IFERROR(IF(ISNUMBER(C16),100*C16/SUM(C$11:C$18),""),"") | G16: =IFERROR(IF(ISNUMBER(D16),100*D16/SUM(D$11:D$18),""),"") | H16: =IFERROR(IF(ISNUMBER(E16),100*E16/SUM(E$11:E$18),""),"") | I16: =IFERROR(IF(ISNUMBER(F16),F16+G16+H16,""),"")
B17: =IFERROR(IF('Enter data'!$I$6="","",'Enter data'!$I$6),"") | C17: =IFERROR(SUMIFS('Enter data'!$D$12:$D$411,'Enter data'!$A$12:$A$411,'Enter data'!$A$6,'Enter data'!$C$12:$C$411,'Enter data'!$I$6)/(Results!$C$6*Results!$C$5),"") -> 0 | D17: =IFERROR(100*COUNTIFS('Enter data'!$A$12:$A$411,'Enter data'!$A$6,'Enter data'!$C$12:$C$411,'Enter data'!$I$6,'Enter data'!$D$12:$D$411,">0")/Results!$C$6,"") -> 0 | E17: =IFERROR(SUMIFS('Enter data'!$E$12:$E$411,'Enter data'!$A$12:$A$411,'Enter data'!$A$6,'Enter data'!$C$12:$C$411,'Enter data'!$I$6)/Results!$C$6,"") -> 0 | F17: =IFERROR(IF(ISNUMBER(C17),100*C17/SUM(C$11:C$18),""),"") | G17: =IFERROR(IF(ISNUMBER(D17),100*D17/SUM(D$11:D$18),""),"") | H17: =IFERROR(IF(ISNUMBER(E17),100*E17/SUM(E$11:E$18),""),"") | I17: =IFERROR(IF(ISNUMBER(F17),F17+G17+H17,""),"")
B18: =IFERROR(IF('Enter data'!$J$6="","",'Enter data'!$J$6),"") | C18: =IFERROR(SUMIFS('Enter data'!$D$12:$D$411,'Enter data'!$A$12:$A$411,'Enter data'!$A$6,'Enter data'!$C$12:$C$411,'Enter data'!$J$6)/(Results!$C$6*Results!$C$5),"") -> 0 | D18: =IFERROR(100*COUNTIFS('Enter data'!$A$12:$A$411,'Enter data'!$A$6,'Enter data'!$C$12:$C$411,'Enter data'!$J$6,'Enter data'!$D$12:$D$411,">0")/Results!$C$6,"") -> 0 | E18: =IFERROR(SUMIFS('Enter data'!$E$12:$E$411,'Enter data'!$A$12:$A$411,'Enter data'!$A$6,'Enter data'!$C$12:$C$411,'Enter data'!$J$6)/Results!$C$6,"") -> 0 | F18: =IFERROR(IF(ISNUMBER(C18),100*C18/SUM(C$11:C$18),""),"") | G18: =IFERROR(IF(ISNUMBER(D18),100*D18/SUM(D$11:D$18),""),"") | H18: =IFERROR(IF(ISNUMBER(E18),100*E18/SUM(E$11:E$18),""),"") | I18: =IFERROR(IF(ISNUMBER(F18),F18+G18+H18,""),"")
B21: Habitat 2: species measures
B22: Species | C22: Density (per m2) | D22: Frequency (%) | E22: Mean cover (%) | F22: Relative density (%) | G22: Relative frequency (%) | H22: Relative cover (%) | I22: Importance value (out of 300)
B23: =IFERROR(IF('Enter data'!$C$6="","",'Enter data'!$C$6),"") | C23: =IFERROR(SUMIFS('Enter data'!$D$12:$D$411,'Enter data'!$A$12:$A$411,'Enter data'!$B$6,'Enter data'!$C$12:$C$411,'Enter data'!$C$6)/(Results!$C$7*Results!$C$5),"") -> 0 | D23: =IFERROR(100*COUNTIFS('Enter data'!$A$12:$A$411,'Enter data'!$B$6,'Enter data'!$C$12:$C$411,'Enter data'!$C$6,'Enter data'!$D$12:$D$411,">0")/Results!$C$7,"") -> 0 | E23: =IFERROR(SUMIFS('Enter data'!$E$12:$E$411,'Enter data'!$A$12:$A$411,'Enter data'!$B$6,'Enter data'!$C$12:$C$411,'Enter data'!$C$6)/Results!$C$7,"") -> 0 | F23: =IFERROR(IF(ISNUMBER(C23),100*C23/SUM(C$23:C$30),""),"") | G23: =IFERROR(IF(ISNUMBER(D23),100*D23/SUM(D$23:D$30),""),"") | H23: =IFERROR(IF(ISNUMBER(E23),100*E23/SUM(E$23:E$30),""),"") | I23: =IFERROR(IF(ISNUMBER(F23),F23+G23+H23,""),"")
B24: =IFERROR(IF('Enter data'!$D$6="","",'Enter data'!$D$6),"") | C24: =IFERROR(SUMIFS('Enter data'!$D$12:$D$411,'Enter data'!$A$12:$A$411,'Enter data'!$B$6,'Enter data'!$C$12:$C$411,'Enter data'!$D$6)/(Results!$C$7*Results!$C$5),"") -> 0 | D24: =IFERROR(100*COUNTIFS('Enter data'!$A$12:$A$411,'Enter data'!$B$6,'Enter data'!$C$12:$C$411,'Enter data'!$D$6,'Enter data'!$D$12:$D$411,">0")/Results!$C$7,"") -> 0 | E24: =IFERROR(SUMIFS('Enter data'!$E$12:$E$411,'Enter data'!$A$12:$A$411,'Enter data'!$B$6,'Enter data'!$C$12:$C$411,'Enter data'!$D$6)/Results!$C$7,"") -> 0 | F24: =IFERROR(IF(ISNUMBER(C24),100*C24/SUM(C$23:C$30),""),"") | G24: =IFERROR(IF(ISNUMBER(D24),100*D24/SUM(D$23:D$30),""),"") | H24: =IFERROR(IF(ISNUMBER(E24),100*E24/SUM(E$23:E$30),""),"") | I24: =IFERROR(IF(ISNUMBER(F24),F24+G24+H24,""),"")
B25: =IFERROR(IF('Enter data'!$E$6="","",'Enter data'!$E$6),"") | C25: =IFERROR(SUMIFS('Enter data'!$D$12:$D$411,'Enter data'!$A$12:$A$411,'Enter data'!$B$6,'Enter data'!$C$12:$C$411,'Enter data'!$E$6)/(Results!$C$7*Results!$C$5),"") -> 0 | D25: =IFERROR(100*COUNTIFS('Enter data'!$A$12:$A$411,'Enter data'!$B$6,'Enter data'!$C$12:$C$411,'Enter data'!$E$6,'Enter data'!$D$12:$D$411,">0")/Results!$C$7,"") -> 0 | E25: =IFERROR(SUMIFS('Enter data'!$E$12:$E$411,'Enter data'!$A$12:$A$411,'Enter data'!$B$6,'Enter data'!$C$12:$C$411,'Enter data'!$E$6)/Results!$C$7,"") -> 0 | F25: =IFERROR(IF(ISNUMBER(C25),100*C25/SUM(C$23:C$30),""),"") | G25: =IFERROR(IF(ISNUMBER(D25),100*D25/SUM(D$23:D$30),""),"") | H25: =IFERROR(IF(ISNUMBER(E25),100*E25/SUM(E$23:E$30),""),"") | I25: =IFERROR(IF(ISNUMBER(F25),F25+G25+H25,""),"")
B26: =IFERROR(IF('Enter data'!$F$6="","",'Enter data'!$F$6),"") | C26: =IFERROR(SUMIFS('Enter data'!$D$12:$D$411,'Enter data'!$A$12:$A$411,'Enter data'!$B$6,'Enter data'!$C$12:$C$411,'Enter data'!$F$6)/(Results!$C$7*Results!$C$5),"") -> 0 | D26: =IFERROR(100*COUNTIFS('Enter data'!$A$12:$A$411,'Enter data'!$B$6,'Enter data'!$C$12:$C$411,'Enter data'!$F$6,'Enter data'!$D$12:$D$411,">0")/Results!$C$7,"") -> 0 | E26: =IFERROR(SUMIFS('Enter data'!$E$12:$E$411,'Enter data'!$A$12:$A$411,'Enter data'!$B$6,'Enter data'!$C$12:$C$411,'Enter data'!$F$6)/Results!$C$7,"") -> 0 | F26: =IFERROR(IF(ISNUMBER(C26),100*C26/SUM(C$23:C$30),""),"") | G26: =IFERROR(IF(ISNUMBER(D26),100*D26/SUM(D$23:D$30),""),"") | H26: =IFERROR(IF(ISNUMBER(E26),100*E26/SUM(E$23:E$30),""),"") | I26: =IFERROR(IF(ISNUMBER(F26),F26+G26+H26,""),"")
B27: =IFERROR(IF('Enter data'!$G$6="","",'Enter data'!$G$6),"") | C27: =IFERROR(SUMIFS('Enter data'!$D$12:$D$411,'Enter data'!$A$12:$A$411,'Enter data'!$B$6,'Enter data'!$C$12:$C$411,'Enter data'!$G$6)/(Results!$C$7*Results!$C$5),"") -> 0 | D27: =IFERROR(100*COUNTIFS('Enter data'!$A$12:$A$411,'Enter data'!$B$6,'Enter data'!$C$12:$C$411,'Enter data'!$G$6,'Enter data'!$D$12:$D$411,">0")/Results!$C$7,"") -> 0 | E27: =IFERROR(SUMIFS('Enter data'!$E$12:$E$411,'Enter data'!$A$12:$A$411,'Enter data'!$B$6,'Enter data'!$C$12:$C$411,'Enter data'!$G$6)/Results!$C$7,"") -> 0 | F27: =IFERROR(IF(ISNUMBER(C27),100*C27/SUM(C$23:C$30),""),"") | G27: =IFERROR(IF(ISNUMBER(D27),100*D27/SUM(D$23:D$30),""),"") | H27: =IFERROR(IF(ISNUMBER(E27),100*E27/SUM(E$23:E$30),""),"") | I27: =IFERROR(IF(ISNUMBER(F27),F27+G27+H27,""),"")
B28: =IFERROR(IF('Enter data'!$H$6="","",'Enter data'!$H$6),"") | C28: =IFERROR(SUMIFS('Enter data'!$D$12:$D$411,'Enter data'!$A$12:$A$411,'Enter data'!$B$6,'Enter data'!$C$12:$C$411,'Enter data'!$H$6)/(Results!$C$7*Results!$C$5),"") -> 0 | D28: =IFERROR(100*COUNTIFS('Enter data'!$A$12:$A$411,'Enter data'!$B$6,'Enter data'!$C$12:$C$411,'Enter data'!$H$6,'Enter data'!$D$12:$D$411,">0")/Results!$C$7,"") -> 0 | E28: =IFERROR(SUMIFS('Enter data'!$E$12:$E$411,'Enter data'!$A$12:$A$411,'Enter data'!$B$6,'Enter data'!$C$12:$C$411,'Enter data'!$H$6)/Results!$C$7,"") -> 0 | F28: =IFERROR(IF(ISNUMBER(C28),100*C28/SUM(C$23:C$30),""),"") | G28: =IFERROR(IF(ISNUMBER(D28),100*D28/SUM(D$23:D$30),""),"") | H28: =IFERROR(IF(ISNUMBER(E28),100*E28/SUM(E$23:E$30),""),"") | I28: =IFERROR(IF(ISNUMBER(F28),F28+G28+H28,""),"")
B29: =IFERROR(IF('Enter data'!$I$6="","",'Enter data'!$I$6),"") | C29: =IFERROR(SUMIFS('Enter data'!$D$12:$D$411,'Enter data'!$A$12:$A$411,'Enter data'!$B$6,'Enter data'!$C$12:$C$411,'Enter data'!$I$6)/(Results!$C$7*Results!$C$5),"") -> 0 | D29: =IFERROR(100*COUNTIFS('Enter data'!$A$12:$A$411,'Enter data'!$B$6,'Enter data'!$C$12:$C$411,'Enter data'!$I$6,'Enter data'!$D$12:$D$411,">0")/Results!$C$7,"") -> 0 | E29: =IFERROR(SUMIFS('Enter data'!$E$12:$E$411,'Enter data'!$A$12:$A$411,'Enter data'!$B$6,'Enter data'!$C$12:$C$411,'Enter data'!$I$6)/Results!$C$7,"") -> 0 | F29: =IFERROR(IF(ISNUMBER(C29),100*C29/SUM(C$23:C$30),""),"") | G29: =IFERROR(IF(ISNUMBER(D29),100*D29/SUM(D$23:D$30),""),"") | H29: =IFERROR(IF(ISNUMBER(E29),100*E29/SUM(E$23:E$30),""),"") | I29: =IFERROR(IF(ISNUMBER(F29),F29+G29+H29,""),"")
B30: =IFERROR(IF('Enter data'!$J$6="","",'Enter data'!$J$6),"") | C30: =IFERROR(SUMIFS('Enter data'!$D$12:$D$411,'Enter data'!$A$12:$A$411,'Enter data'!$B$6,'Enter data'!$C$12:$C$411,'Enter data'!$J$6)/(Results!$C$7*Results!$C$5),"") -> 0 | D30: =IFERROR(100*COUNTIFS('Enter data'!$A$12:$A$411,'Enter data'!$B$6,'Enter data'!$C$12:$C$411,'Enter data'!$J$6,'Enter data'!$D$12:$D$411,">0")/Results!$C$7,"") -> 0 | E30: =IFERROR(SUMIFS('Enter data'!$E$12:$E$411,'Enter data'!$A$12:$A$411,'Enter data'!$B$6,'Enter data'!$C$12:$C$411,'Enter data'!$J$6)/Results!$C$7,"") -> 0 | F30: =IFERROR(IF(ISNUMBER(C30),100*C30/SUM(C$23:C$30),""),"") | G30: =IFERROR(IF(ISNUMBER(D30),100*D30/SUM(D$23:D$30),""),"") | H30: =IFERROR(IF(ISNUMBER(E30),100*E30/SUM(E$23:E$30),""),"") | I30: =IFERROR(IF(ISNUMBER(F30),F30+G30+H30,""),"")
B33: Total individuals per quadrat
B34: Quadrat | C34: Habitat 1 | D34: Habitat 2
B35: 1 | C35: =IFERROR(IF(1<=Results!$C$6,SUMIFS('Enter data'!$D$12:$D$411,'Enter data'!$A$12:$A$411,'Enter data'!$A$6,'Enter data'!$B$12:$B$411,1),""),"") -> 0 | D35: =IFERROR(IF(1<=Results!$C$7,SUMIFS('Enter data'!$D$12:$D$411,'Enter data'!$A$12:$A$411,'Enter data'!$B$6,'Enter data'!$B$12:$B$411,1),""),"") -> 0
B36: 2 | C36: =IFERROR(IF(2<=Results!$C$6,SUMIFS('Enter data'!$D$12:$D$411,'Enter data'!$A$12:$A$411,'Enter data'!$A$6,'Enter data'!$B$12:$B$411,2),""),"") -> 0 | D36: =IFERROR(IF(2<=Results!$C$7,SUMIFS('Enter data'!$D$12:$D$411,'Enter data'!$A$12:$A$411,'Enter data'!$B$6,'Enter data'!$B$12:$B$411,2),""),"") -> 0
B37: 3 | C37: =IFERROR(IF(3<=Results!$C$6,SUMIFS('Enter data'!$D$12:$D$411,'Enter data'!$A$12:$A$411,'Enter data'!$A$6,'Enter data'!$B$12:$B$411,3),""),"") -> 0 | D37: =IFERROR(IF(3<=Results!$C$7,SUMIFS('Enter data'!$D$12:$D$411,'Enter data'!$A$12:$A$411,'Enter data'!$B$6,'Enter data'!$B$12:$B$411,3),""),"") -> 0
B38: 4 | C38: =IFERROR(IF(4<=Results!$C$6,SUMIFS('Enter data'!$D$12:$D$411,'Enter data'!$A$12:$A$411,'Enter data'!$A$6,'Enter data'!$B$12:$B$411,4),""),"") -> 0 | D38: =IFERROR(IF(4<=Results!$C$7,SUMIFS('Enter data'!$D$12:$D$411,'Enter data'!$A$12:$A$411,'Enter data'!$B$6,'Enter data'!$B$12:$B$411,4),""),"") -> 0
B39: 5 | C39: =IFERROR(IF(5<=Results!$C$6,SUMIFS('Enter data'!$D$12:$D$411,'Enter data'!$A$12:$A$411,'Enter data'!$A$6,'Enter data'!$B$12:$B$411,5),""),"") -> 0 | D39: =IFERROR(IF(5<=Results!$C$7,SUMIFS('Enter data'!$D$12:$D$411,'Enter data'!$A$12:$A$411,'Enter data'!$B$6,'Enter data'!$B$12:$B$411,5),""),"") -> 0
B40: 6 | C40: =IFERROR(IF(6<=Results!$C$6,SUMIFS('Enter data'!$D$12:$D$411,'Enter data'!$A$12:$A$411,'Enter data'!$A$6,'Enter data'!$B$12:$B$411,6),""),"") -> 0 | D40: =IFERROR(IF(6<=Results!$C$7,SUMIFS('Enter data'!$D$12:$D$411,'Enter data'!$A$12:$A$411,'Enter data'!$B$6,'Enter data'!$B$12:$B$411,6),""),"") -> 0
B41: 7 | C41: =IFERROR(IF(7<=Results!$C$6,SUMIFS('Enter data'!$D$12:$D$411,'Enter data'!$A$12:$A$411,'Enter data'!$A$6,'Enter data'!$B$12:$B$411,7),""),"") -> 0 | D41: =IFERROR(IF(7<=Results!$C$7,SUMIFS('Enter data'!$D$12:$D$411,'Enter data'!$A$12:$A$411,'Enter data'!$B$6,'Enter data'!$B$12:$B$411,7),""),"") -> 0
B42: 8 | C42: =IFERROR(IF(8<=Results!$C$6,SUMIFS('Enter data'!$D$12:$D$411,'Enter data'!$A$12:$A$411,'Enter data'!$A$6,'Enter data'!$B$12:$B$411,8),""),"") -> 0 | D42: =IFERROR(IF(8<=Results!$C$7,SUMIFS('Enter data'!$D$12:$D$411,'Enter data'!$A$12:$A$411,'Enter data'!$B$6,'Enter data'!$B$12:$B$411,8),""),"") -> 0
B43: 9 | C43: =IFERROR(IF(9<=Results!$C$6,SUMIFS('Enter data'!$D$12:$D$411,'Enter data'!$A$12:$A$411,'Enter data'!$A$6,'Enter data'!$B$12:$B$411,9),""),"") -> 0 | D43: =IFERROR(IF(9<=Results!$C$7,SUMIFS('Enter data'!$D$12:$D$411,'Enter data'!$A$12:$A$411,'Enter data'!$B$6,'Enter data'!$B$12:$B$411,9),""),"") -> 0
B44: 10 | C44: =IFERROR(IF(10<=Results!$C$6,SUMIFS('Enter data'!$D$12:$D$411,'Enter data'!$A$12:$A$411,'Enter data'!$A$6,'Enter data'!$B$12:$B$411,10),""),"") -> 0 | D44: =IFERROR(IF(10<=Results!$C$7,SUMIFS('Enter data'!$D$12:$D$411,'Enter data'!$A$12:$A$411,'Enter data'!$B$6,'Enter data'!$B$12:$B$411,10),""),"") -> 0
B45: 11 | C45: =IFERROR(IF(11<=Results!$C$6,SUMIFS('Enter data'!$D$12:$D$411,'Enter data'!$A$12:$A$411,'Enter data'!$A$6,'Enter data'!$B$12:$B$411,11),""),"") -> 0 | D45: =IFERROR(IF(11<=Results!$C$7,SUMIFS('Enter data'!$D$12:$D$411,'Enter data'!$A$12:$A$411,'Enter data'!$B$6,'Enter data'!$B$12:$B$411,11),""),"") -> 0
B46: 12 | C46: =IFERROR(IF(12<=Results!$C$6,SUMIFS('Enter data'!$D$12:$D$411,'Enter data'!$A$12:$A$411,'Enter data'!$A$6,'Enter data'!$B$12:$B$411,12),""),"") -> 0 | D46: =IFERROR(IF(12<=Results!$C$7,SUMIFS('Enter data'!$D$12:$D$411,'Enter data'!$A$12:$A$411,'Enter data'!$B$6,'Enter data'!$B$12:$B$411,12),""),"") -> 0
...
