Workbook

Sheet Start here
B1: ECO-04 Leaf-litter arthropods: richness, diversity and evenness
B2: Excel version of the card. It does the same calculations as the R script eco04_arthropod_diversity.R.
B4: How to use this workbook
B5: 1. Go to the 'Enter data' sheet. Type only in the yellow cells with blue text. Grey cells are calculated for you.
B6: 2. Fill the blocks that apply. Leave rows you did not use empty. The grey italic row above each table is an example of the format and is not used.
B7: 3. Open the 'Results' sheet. Everything there is calculated. Yellow cells on that sheet are settings you may change.
B9: What the colours mean
B10: Yellow cell, blue text: you type here.
B11: Grey cell: a formula. Sheets are protected without a password so formulas are not overwritten by accident (Review > Unprotect Sheet).
B13: Assumptions and sources
B14: One row per litter sample; one column per morphospecies (type the morphospecies names in the yellow header cells; use the same order for both sites). Samples are the replicates.
B15: Richness = morphospecies present. Shannon H = -sum(p ln p). Gini-Simpson = 1 - sum(p^2). Pielou evenness J = H / ln(richness). Bray-Curtis dissimilarity = sum |a - b| / sum (a + b) between pooled catches.
... B22: Compiled by Emmanuel G. Lozano, Department of Biology, College of Arts and Sciences, Pampanga State University. Original material is licensed CC BY-NC 4.0: credit required, non-commercial use only.

Sheet Enter data
A1: Enter your data
A2: Type only in yellow cells. Leave unused rows empty.
A4: 1. Site names
A5: Site 1 | B5: Site 2
A9: 2. Samples from site 1 (counts)
A10: Sample | B10: morphospecies 1 | C10: morphospecies 2 | D10: morphospecies 3 | E10: morphospecies 4 | F10: morphospecies 5 | G10: morphospecies 6 | H10: morphospecies 7 | I10: morphospecies 8 | J10: morphospecies 9 | K10: morphospecies 10 | L10: morphospecies 11 | M10: morphospecies 12 | N10: morphospecies 13 | O10: morphospecies 14 | P10: morphospecies 15 | Q10: Animals | R10: Richness | S10: Shannon H | T10: Gini-Simpson | U10: Pielou evenness
A11: sample 1 | B11: 5 | C11: 3 | D11: 2 | E11: 1 | F11: 1 | G11: 0 | H11: 0 | I11: 0 | J11: 0 | K11: 0 | L11: 0 | M11: 0 | N11: 0 | O11: 0 | P11: 0
Q12: =SUM(B12:P12) -> 0 | R12: =IF(Q12>0,COUNTIF(B12:P12,">0"),"") | S12: =IF(Q12>0,-SUMPRODUCT((B12:P12>0)*B12:P12/Q12*LN((B12:P12+(B12:P12=0))/Q12)),"") | T12: =IF(Q12>0,1-SUMPRODUCT((B12:P12/Q12)^2),"") | U12: =IF(AND(Q12>0,R12>1),S12/LN(R12),"")
Q13: =SUM(B13:P13) -> 0 | R13: =IF(Q13>0,COUNTIF(B13:P13,">0"),"") | S13: =IF(Q13>0,-SUMPRODUCT((B13:P13>0)*B13:P13/Q13*LN((B13:P13+(B13:P13=0))/Q13)),"") | T13: =IF(Q13>0,1-SUMPRODUCT((B13:P13/Q13)^2),"") | U13: =IF(AND(Q13>0,R13>1),S13/LN(R13),"")
Q14: =SUM(B14:P14) -> 0 | R14: =IF(Q14>0,COUNTIF(B14:P14,">0"),"") | S14: =IF(Q14>0,-SUMPRODUCT((B14:P14>0)*B14:P14/Q14*LN((B14:P14+(B14:P14=0))/Q14)),"") | T14: =IF(Q14>0,1-SUMPRODUCT((B14:P14/Q14)^2),"") | U14: =IF(AND(Q14>0,R14>1),S14/LN(R14),"")
Q15: =SUM(B15:P15) -> 0 | R15: =IF(Q15>0,COUNTIF(B15:P15,">0"),"") | S15: =IF(Q15>0,-SUMPRODUCT((B15:P15>0)*B15:P15/Q15*LN((B15:P15+(B15:P15=0))/Q15)),"") | T15: =IF(Q15>0,1-SUMPRODUCT((B15:P15/Q15)^2),"") | U15: =IF(AND(Q15>0,R15>1),S15/LN(R15),"")
Q16: =SUM(B16:P16) -> 0 | R16: =IF(Q16>0,COUNTIF(B16:P16,">0"),"") | S16: =IF(Q16>0,-SUMPRODUCT((B16:P16>0)*B16:P16/Q16*LN((B16:P16+(B16:P16=0))/Q16)),"") | T16: =IF(Q16>0,1-SUMPRODUCT((B16:P16/Q16)^2),"") | U16: =IF(AND(Q16>0,R16>1),S16/LN(R16),"")
Q17: =SUM(B17:P17) -> 0 | R17: =IF(Q17>0,COUNTIF(B17:P17,">0"),"") | S17: =IF(Q17>0,-SUMPRODUCT((B17:P17>0)*B17:P17/Q17*LN((B17:P17+(B17:P17=0))/Q17)),"") | T17: =IF(Q17>0,1-SUMPRODUCT((B17:P17/Q17)^2),"") | U17: =IF(AND(Q17>0,R17>1),S17/LN(R17),"")
Q18: =SUM(B18:P18) -> 0 | R18: =IF(Q18>0,COUNTIF(B18:P18,">0"),"") | S18: =IF(Q18>0,-SUMPRODUCT((B18:P18>0)*B18:P18/Q18*LN((B18:P18+(B18:P18=0))/Q18)),"") | T18: =IF(Q18>0,1-SUMPRODUCT((B18:P18/Q18)^2),"") | U18: =IF(AND(Q18>0,R18>1),S18/LN(R18),"")
Q19: =SUM(B19:P19) -> 0 | R19: =IF(Q19>0,COUNTIF(B19:P19,">0"),"") | S19: =IF(Q19>0,-SUMPRODUCT((B19:P19>0)*B19:P19/Q19*LN((B19:P19+(B19:P19=0))/Q19)),"") | T19: =IF(Q19>0,1-SUMPRODUCT((B19:P19/Q19)^2),"") | U19: =IF(AND(Q19>0,R19>1),S19/LN(R19),"")
Q20: =SUM(B20:P20) -> 0 | R20: =IF(Q20>0,COUNTIF(B20:P20,">0"),"") | S20: =IF(Q20>0,-SUMPRODUCT((B20:P20>0)*B20:P20/Q20*LN((B20:P20+(B20:P20=0))/Q20)),"") | T20: =IF(Q20>0,1-SUMPRODUCT((B20:P20/Q20)^2),"") | U20: =IF(AND(Q20>0,R20>1),S20/LN(R20),"")
Q21: =SUM(B21:P21) -> 0 | R21: =IF(Q21>0,COUNTIF(B21:P21,">0"),"") | S21: =IF(Q21>0,-SUMPRODUCT((B21:P21>0)*B21:P21/Q21*LN((B21:P21+(B21:P21=0))/Q21)),"") | T21: =IF(Q21>0,1-SUMPRODUCT((B21:P21/Q21)^2),"") | U21: =IF(AND(Q21>0,R21>1),S21/LN(R21),"")
A24: 3. Samples from site 2 (counts)
A25: Sample | B25: morphospecies 1 | C25: morphospecies 2 | D25: morphospecies 3 | E25: morphospecies 4 | F25: morphospecies 5 | G25: morphospecies 6 | H25: morphospecies 7 | I25: morphospecies 8 | J25: morphospecies 9 | K25: morphospecies 10 | L25: morphospecies 11 | M25: morphospecies 12 | N25: morphospecies 13 | O25: morphospecies 14 | P25: morphospecies 15 | Q25: Animals | R25: Richness | S25: Shannon H | T25: Gini-Simpson | U25: Pielou evenness
A26: sample 1 | B26: 5 | C26: 3 | D26: 2 | E26: 1 | F26: 1 | G26: 0 | H26: 0 | I26: 0 | J26: 0 | K26: 0 | L26: 0 | M26: 0 | N26: 0 | O26: 0 | P26: 0
Q27: =SUM(B27:P27) -> 0 | R27: =IF(Q27>0,COUNTIF(B27:P27,">0"),"") | S27: =IF(Q27>0,-SUMPRODUCT((B27:P27>0)*B27:P27/Q27*LN((B27:P27+(B27:P27=0))/Q27)),"") | T27: =IF(Q27>0,1-SUMPRODUCT((B27:P27/Q27)^2),"") | U27: =IF(AND(Q27>0,R27>1),S27/LN(R27),"")
Q28: =SUM(B28:P28) -> 0 | R28: =IF(Q28>0,COUNTIF(B28:P28,">0"),"") | S28: =IF(Q28>0,-SUMPRODUCT((B28:P28>0)*B28:P28/Q28*LN((B28:P28+(B28:P28=0))/Q28)),"") | T28: =IF(Q28>0,1-SUMPRODUCT((B28:P28/Q28)^2),"") | U28: =IF(AND(Q28>0,R28>1),S28/LN(R28),"")
Q29: =SUM(B29:P29) -> 0 | R29: =IF(Q29>0,COUNTIF(B29:P29,">0"),"") | S29: =IF(Q29>0,-SUMPRODUCT((B29:P29>0)*B29:P29/Q29*LN((B29:P29+(B29:P29=0))/Q29)),"") | T29: =IF(Q29>0,1-SUMPRODUCT((B29:P29/Q29)^2),"") | U29: =IF(AND(Q29>0,R29>1),S29/LN(R29),"")
Q30: =SUM(B30:P30) -> 0 | R30: =IF(Q30>0,COUNTIF(B30:P30,">0"),"") | S30: =IF(Q30>0,-SUMPRODUCT((B30:P30>0)*B30:P30/Q30*LN((B30:P30+(B30:P30=0))/Q30)),"") | T30: =IF(Q30>0,1-SUMPRODUCT((B30:P30/Q30)^2),"") | U30: =IF(AND(Q30>0,R30>1),S30/LN(R30),"")
Q31: =SUM(B31:P31) -> 0 | R31: =IF(Q31>0,COUNTIF(B31:P31,">0"),"") | S31: =IF(Q31>0,-SUMPRODUCT((B31:P31>0)*B31:P31/Q31*LN((B31:P31+(B31:P31=0))/Q31)),"") | T31: =IF(Q31>0,1-SUMPRODUCT((B31:P31/Q31)^2),"") | U31: =IF(AND(Q31>0,R31>1),S31/LN(R31),"")
Q32: =SUM(B32:P32) -> 0 | R32: =IF(Q32>0,COUNTIF(B32:P32,">0"),"") | S32: =IF(Q32>0,-SUMPRODUCT((B32:P32>0)*B32:P32/Q32*LN((B32:P32+(B32:P32=0))/Q32)),"") | T32: =IF(Q32>0,1-SUMPRODUCT((B32:P32/Q32)^2),"") | U32: =IF(AND(Q32>0,R32>1),S32/LN(R32),"")
Q33: =SUM(B33:P33) -> 0 | R33: =IF(Q33>0,COUNTIF(B33:P33,">0"),"") | S33: =IF(Q33>0,-SUMPRODUCT((B33:P33>0)*B33:P33/Q33*LN((B33:P33+(B33:P33=0))/Q33)),"") | T33: =IF(Q33>0,1-SUMPRODUCT((B33:P33/Q33)^2),"") | U33: =IF(AND(Q33>0,R33>1),S33/LN(R33),"")
Q34: =SUM(B34:P34) -> 0 | R34: =IF(Q34>0,COUNTIF(B34:P34,">0"),"") | S34: =IF(Q34>0,-SUMPRODUCT((B34:P34>0)*B34:P34/Q34*LN((B34:P34+(B34:P34=0))/Q34)),"") | T34: =IF(Q34>0,1-SUMPRODUCT((B34:P34/Q34)^2),"") | U34: =IF(AND(Q34>0,R34>1),S34/LN(R34),"")
Q35: =SUM(B35:P35) -> 0 | R35: =IF(Q35>0,COUNTIF(B35:P35,">0"),"") | S35: =IF(Q35>0,-SUMPRODUCT((B35:P35>0)*B35:P35/Q35*LN((B35:P35+(B35:P35=0))/Q35)),"") | T35: =IF(Q35>0,1-SUMPRODUCT((B35:P35/Q35)^2),"") | U35: =IF(AND(Q35>0,R35>1),S35/LN(R35),"")
Q36: =SUM(B36:P36) -> 0 | R36: =IF(Q36>0,COUNTIF(B36:P36,">0"),"") | S36: =IF(Q36>0,-SUMPRODUCT((B36:P36>0)*B36:P36/Q36*LN((B36:P36+(B36:P36=0))/Q36)),"") | T36: =IF(Q36>0,1-SUMPRODUCT((B36:P36/Q36)^2),"") | U36: =IF(AND(Q36>0,R36>1),S36/LN(R36),"")

Sheet Results
B1: Results
B2: Everything on this sheet is calculated. Change only the yellow settings.
B4: Richness per sample
B5: Group | C5: n | D5: Mean | E5: SD | F5: SE | G5: Min | H5: Max
B6: =IFERROR('Enter data'!$A$6,"") -> 0 | C6: =IFERROR(COUNT('Enter data'!$R$12:$R$21),"") -> 0 | D6: =IFERROR(AVERAGE('Enter data'!$R$12:$R$21),"") | E6: =IFERROR(STDEV('Enter data'!$R$12:$R$21),"") | F6: =IFERROR(STDEV('Enter data'!$R$12:$R$21)/SQRT(COUNT('Enter data'!$R$12:$R$21)),"") | G6: =IFERROR(MIN('Enter data'!$R$12:$R$21),"") -> 0 | H6: =IFERROR(MAX('Enter data'!$R$12:$R$21),"") -> 0
B7: =IFERROR('Enter data'!$B$6,"") -> 0 | C7: =IFERROR(COUNT('Enter data'!$R$27:$R$36),"") -> 0 | D7: =IFERROR(AVERAGE('Enter data'!$R$27:$R$36),"") | E7: =IFERROR(STDEV('Enter data'!$R$27:$R$36),"") | F7: =IFERROR(STDEV('Enter data'!$R$27:$R$36)/SQRT(COUNT('Enter data'!$R$27:$R$36)),"") | G7: =IFERROR(MIN('Enter data'!$R$27:$R$36),"") -> 0 | H7: =IFERROR(MAX('Enter data'!$R$27:$R$36),"") -> 0
B9: Difference in means (site 1 minus site 2) | C9: =IFERROR($D$6-$D$7,"")
B10: Standard error of the difference | C10: =IFERROR(SQRT($F$6^2+$F$7^2),"")
B11: Degrees of freedom (Welch) | C11: =IFERROR((($E$6^2/$C$6+$E$7^2/$C$7)^2/(($E$6^2/$C$6)^2/($C$6-1)+($E$7^2/$C$7)^2/($C$7-1))),"")
B12: p value (two-sided) | C12: =IFERROR(TTEST('Enter data'!$R$12:$R$21,'Enter data'!$R$27:$R$36,2,3),"")
B14: Shannon diversity per sample
B15: Group | C15: n | D15: Mean | E15: SD | F15: SE | G15: Min | H15: Max
B16: =IFERROR('Enter data'!$A$6,"") -> 0 | C16: =IFERROR(COUNT('Enter data'!$S$12:$S$21),"") -> 0 | D16: =IFERROR(AVERAGE('Enter data'!$S$12:$S$21),"") | E16: =IFERROR(STDEV('Enter data'!$S$12:$S$21),"") | F16: =IFERROR(STDEV('Enter data'!$S$12:$S$21)/SQRT(COUNT('Enter data'!$S$12:$S$21)),"") | G16: =IFERROR(MIN('Enter data'!$S$12:$S$21),"") -> 0 | H16: =IFERROR(MAX('Enter data'!$S$12:$S$21),"") -> 0
B17: =IFERROR('Enter data'!$B$6,"") -> 0 | C17: =IFERROR(COUNT('Enter data'!$S$27:$S$36),"") -> 0 | D17: =IFERROR(AVERAGE('Enter data'!$S$27:$S$36),"") | E17: =IFERROR(STDEV('Enter data'!$S$27:$S$36),"") | F17: =IFERROR(STDEV('Enter data'!$S$27:$S$36)/SQRT(COUNT('Enter data'!$S$27:$S$36)),"") | G17: =IFERROR(MIN('Enter data'!$S$27:$S$36),"") -> 0 | H17: =IFERROR(MAX('Enter data'!$S$27:$S$36),"") -> 0
B19: Difference in means (site 1 minus site 2) | C19: =IFERROR($D$16-$D$17,"")
B20: Standard error of the difference | C20: =IFERROR(SQRT($F$16^2+$F$17^2),"")
B21: Degrees of freedom (Welch) | C21: =IFERROR((($E$16^2/$C$16+$E$17^2/$C$17)^2/(($E$16^2/$C$16)^2/($C$16-1)+($E$17^2/$C$17)^2/($C$17-1))),"")
B22: p value (two-sided) | C22: =IFERROR(TTEST('Enter data'!$S$12:$S$21,'Enter data'!$S$27:$S$36,2,3),"")
B24: Pooled catches by morphospecies
B25: Morphospecies | C25: Site 1 total | D25: Site 2 total | E25: Absolute difference | F25: Sum
B26: =IFERROR('Enter data'!$B$10,"") -> morphospecies 1 | C26: =IFERROR(SUM('Enter data'!$B$12:$B$21),"") -> 0 | D26: =IFERROR(SUM('Enter data'!$B$27:$B$36),"") -> 0 | E26: =IFERROR(ABS(C26-D26),"") -> 0 | F26: =IFERROR(C26+D26,"") -> 0
B27: =IFERROR('Enter data'!$C$10,"") -> morphospecies 2 | C27: =IFERROR(SUM('Enter data'!$C$12:$C$21),"") -> 0 | D27: =IFERROR(SUM('Enter data'!$C$27:$C$36),"") -> 0 | E27: =IFERROR(ABS(C27-D27),"") -> 0 | F27: =IFERROR(C27+D27,"") -> 0
B28: =IFERROR('Enter data'!$D$10,"") -> morphospecies 3 | C28: =IFERROR(SUM('Enter data'!$D$12:$D$21),"") -> 0 | D28: =IFERROR(SUM('Enter data'!$D$27:$D$36),"") -> 0 | E28: =IFERROR(ABS(C28-D28),"") -> 0 | F28: =IFERROR(C28+D28,"") -> 0
B29: =IFERROR('Enter data'!$E$10,"") -> morphospecies 4 | C29: =IFERROR(SUM('Enter data'!$E$12:$E$21),"") -> 0 | D29: =IFERROR(SUM('Enter data'!$E$27:$E$36),"") -> 0 | E29: =IFERROR(ABS(C29-D29),"") -> 0 | F29: =IFERROR(C29+D29,"") -> 0
B30: =IFERROR('Enter data'!$F$10,"") -> morphospecies 5 | C30: =IFERROR(SUM('Enter data'!$F$12:$F$21),"") -> 0 | D30: =IFERROR(SUM('Enter data'!$F$27:$F$36),"") -> 0 | E30: =IFERROR(ABS(C30-D30),"") -> 0 | F30: =IFERROR(C30+D30,"") -> 0
B31: =IFERROR('Enter data'!$G$10,"") -> morphospecies 6 | C31: =IFERROR(SUM('Enter data'!$G$12:$G$21),"") -> 0 | D31: =IFERROR(SUM('Enter data'!$G$27:$G$36),"") -> 0 | E31: =IFERROR(ABS(C31-D31),"") -> 0 | F31: =IFERROR(C31+D31,"") -> 0
B32: =IFERROR('Enter data'!$H$10,"") -> morphospecies 7 | C32: =IFERROR(SUM('Enter data'!$H$12:$H$21),"") -> 0 | D32: =IFERROR(SUM('Enter data'!$H$27:$H$36),"") -> 0 | E32: =IFERROR(ABS(C32-D32),"") -> 0 | F32: =IFERROR(C32+D32,"") -> 0
B33: =IFERROR('Enter data'!$I$10,"") -> morphospecies 8 | C33: =IFERROR(SUM('Enter data'!$I$12:$I$21),"") -> 0 | D33: =IFERROR(SUM('Enter data'!$I$27:$I$36),"") -> 0 | E33: =IFERROR(ABS(C33-D33),"") -> 0 | F33: =IFERROR(C33+D33,"") -> 0
B34: =IFERROR('Enter data'!$J$10,"") -> morphospecies 9 | C34: =IFERROR(SUM('Enter data'!$J$12:$J$21),"") -> 0 | D34: =IFERROR(SUM('Enter data'!$J$27:$J$36),"") -> 0 | E34: =IFERROR(ABS(C34-D34),"") -> 0 | F34: =IFERROR(C34+D34,"") -> 0
B35: =IFERROR('Enter data'!$K$10,"") -> morphospecies 10 | C35: =IFERROR(SUM('Enter data'!$K$12:$K$21),"") -> 0 | D35: =IFERROR(SUM('Enter data'!$K$27:$K$36),"") -> 0 | E35: =IFERROR(ABS(C35-D35),"") -> 0 | F35: =IFERROR(C35+D35,"") -> 0
B36: =IFERROR('Enter data'!$L$10,"") -> morphospecies 11 | C36: =IFERROR(SUM('Enter data'!$L$12:$L$21),"") -> 0 | D36: =IFERROR(SUM('Enter data'!$L$27:$L$36),"") -> 0 | E36: =IFERROR(ABS(C36-D36),"") -> 0 | F36: =IFERROR(C36+D36,"") -> 0
B37: =IFERROR('Enter data'!$M$10,"") -> morphospecies 12 | C37: =IFERROR(SUM('Enter data'!$M$12:$M$21),"") -> 0 | D37: =IFERROR(SUM('Enter data'!$M$27:$M$36),"") -> 0 | E37: =IFERROR(ABS(C37-D37),"") -> 0 | F37: =IFERROR(C37+D37,"") -> 0
B38: =IFERROR('Enter data'!$N$10,"") -> morphospecies 13 | C38: =IFERROR(SUM('Enter data'!$N$12:$N$21),"") -> 0 | D38: =IFERROR(SUM('Enter data'!$N$27:$N$36),"") -> 0 | E38: =IFERROR(ABS(C38-D38),"") -> 0 | F38: =IFERROR(C38+D38,"") -> 0
B39: =IFERROR('Enter data'!$O$10,"") -> morphospecies 14 | C39: =IFERROR(SUM('Enter data'!$O$12:$O$21),"") -> 0 | D39: =IFERROR(SUM('Enter data'!$O$27:$O$36),"") -> 0 | E39: =IFERROR(ABS(C39-D39),"") -> 0 | F39: =IFERROR(C39+D39,"") -> 0
B40: =IFERROR('Enter data'!$P$10,"") -> morphospecies 15 | C40: =IFERROR(SUM('Enter data'!$P$12:$P$21),"") -> 0 | D40: =IFERROR(SUM('Enter data'!$P$27:$P$36),"") -> 0 | E40: =IFERROR(ABS(C40-D40),"") -> 0 | F40: =IFERROR(C40+D40,"") -> 0
B43: Pooled comparison
B44: Bray-Curtis dissimilarity (0 = identical, 1 = no shared morphospecies) | C44: =IFERROR(SUM($E$26:$E$40)/SUM($F$26:$F$40),"")
B45: Site 1: pooled richness | C45: =IFERROR(COUNTIF(C$26:C$40,">0"),"") -> 0
B46: Site 2: pooled richness | C46: =IFERROR(COUNTIF(D$26:D$40,">0"),"") -> 0
B47: Site 1: pooled Shannon H | C47: =IFERROR(-SUMPRODUCT((C$26:C$40>0)*C$26:C$40/SUM(C$26:C$40)*LN((C$26:C$40+(C$26:C$40=0))/SUM(C$26:C$40))),"")
...
