Workbook

Sheet Start here
B1: ZOO-05 Animal tissues: cell shape measurements
B2: Excel version of the card. It does the same calculations as the R script zoo05_cell_measurements.R.
B4: How to use this workbook
B5: 1. Go to the 'Enter data' sheet. Type only in the yellow cells with blue text. Grey cells are calculated for you.
B6: 2. Fill the blocks that apply. Leave rows you did not use empty. The grey italic row above each table is an example of the format and is not used.
B7: 3. Open the 'Results' sheet. Everything there is calculated. Yellow cells on that sheet are settings you may change.
B9: What the colours mean
B10: Yellow cell, blue text: you type here.
B11: Grey cell: a formula. Sheets are protected without a password so formulas are not overwritten by accident (Review > Unprotect Sheet).
B13: Assumptions and sources
B14: Ratio = long axis / short axis of each measured cell or nucleus as cut in the section. Ratios need no calibration; use the same unit for both axes.
B15: Choose cells cut through the nucleus, and describe where you measured.
... B22: Compiled by Emmanuel G. Lozano, Department of Biology, College of Arts and Sciences, Pampanga State University. Original material is licensed CC BY-NC 4.0: credit required, non-commercial use only.

Sheet Enter data
A1: Enter your data
A2: Type only in yellow cells. Leave unused rows empty.
A4: 1. Tissue names
A5: Tissue 1 | B5: Tissue 2 | C5: Tissue 3 | D5: Tissue 4
A9: 2. Cells of tissue 1
A10: Long axis | B10: Short axis | C10: Long / short
A11: 30 | B11: 4
C12: =IF(AND(ISNUMBER(A12),ISNUMBER(B12)),A12/B12,"")
C13: =IF(AND(ISNUMBER(A13),ISNUMBER(B13)),A13/B13,"")
C14: =IF(AND(ISNUMBER(A14),ISNUMBER(B14)),A14/B14,"")
C15: =IF(AND(ISNUMBER(A15),ISNUMBER(B15)),A15/B15,"")
C16: =IF(AND(ISNUMBER(A16),ISNUMBER(B16)),A16/B16,"")
C17: =IF(AND(ISNUMBER(A17),ISNUMBER(B17)),A17/B17,"")
C18: =IF(AND(ISNUMBER(A18),ISNUMBER(B18)),A18/B18,"")
C19: =IF(AND(ISNUMBER(A19),ISNUMBER(B19)),A19/B19,"")
C20: =IF(AND(ISNUMBER(A20),ISNUMBER(B20)),A20/B20,"")
C21: =IF(AND(ISNUMBER(A21),ISNUMBER(B21)),A21/B21,"")
C22: =IF(AND(ISNUMBER(A22),ISNUMBER(B22)),A22/B22,"")
C23: =IF(AND(ISNUMBER(A23),ISNUMBER(B23)),A23/B23,"")
... C41: =IF(AND(ISNUMBER(A41),ISNUMBER(B41)),A41/B41,"")
A44: 3. Cells of tissue 2
A45: Long axis | B45: Short axis | C45: Long / short
A46: 30 | B46: 4
C47: =IF(AND(ISNUMBER(A47),ISNUMBER(B47)),A47/B47,"")
C48: =IF(AND(ISNUMBER(A48),ISNUMBER(B48)),A48/B48,"")
C49: =IF(AND(ISNUMBER(A49),ISNUMBER(B49)),A49/B49,"")
C50: =IF(AND(ISNUMBER(A50),ISNUMBER(B50)),A50/B50,"")
C51: =IF(AND(ISNUMBER(A51),ISNUMBER(B51)),A51/B51,"")
C52: =IF(AND(ISNUMBER(A52),ISNUMBER(B52)),A52/B52,"")
C53: =IF(AND(ISNUMBER(A53),ISNUMBER(B53)),A53/B53,"")
C54: =IF(AND(ISNUMBER(A54),ISNUMBER(B54)),A54/B54,"")
C55: =IF(AND(ISNUMBER(A55),ISNUMBER(B55)),A55/B55,"")
C56: =IF(AND(ISNUMBER(A56),ISNUMBER(B56)),A56/B56,"")
C57: =IF(AND(ISNUMBER(A57),ISNUMBER(B57)),A57/B57,"")
C58: =IF(AND(ISNUMBER(A58),ISNUMBER(B58)),A58/B58,"")
... C76: =IF(AND(ISNUMBER(A76),ISNUMBER(B76)),A76/B76,"")
A79: 4. Cells of tissue 3
A80: Long axis | B80: Short axis | C80: Long / short
A81: 30 | B81: 4
C82: =IF(AND(ISNUMBER(A82),ISNUMBER(B82)),A82/B82,"")
...

Sheet Results
B1: Results
B2: Everything on this sheet is calculated. Change only the yellow settings.
B4: Long : short axis ratio by tissue
B5: Group | C5: n | D5: Mean | E5: SD | F5: SE | G5: Min | H5: Max
B6: =IFERROR('Enter data'!$A$6,"") -> 0 | C6: =IFERROR(COUNT('Enter data'!$C$12:$C$41),"") -> 0 | D6: =IFERROR(AVERAGE('Enter data'!$C$12:$C$41),"") | E6: =IFERROR(STDEV('Enter data'!$C$12:$C$41),"") | F6: =IFERROR(STDEV('Enter data'!$C$12:$C$41)/SQRT(COUNT('Enter data'!$C$12:$C$41)),"") | G6: =IFERROR(MIN('Enter data'!$C$12:$C$41),"") -> 0 | H6: =IFERROR(MAX('Enter data'!$C$12:$C$41),"") -> 0
B7: =IFERROR('Enter data'!$B$6,"") -> 0 | C7: =IFERROR(COUNT('Enter data'!$C$47:$C$76),"") -> 0 | D7: =IFERROR(AVERAGE('Enter data'!$C$47:$C$76),"") | E7: =IFERROR(STDEV('Enter data'!$C$47:$C$76),"") | F7: =IFERROR(STDEV('Enter data'!$C$47:$C$76)/SQRT(COUNT('Enter data'!$C$47:$C$76)),"") | G7: =IFERROR(MIN('Enter data'!$C$47:$C$76),"") -> 0 | H7: =IFERROR(MAX('Enter data'!$C$47:$C$76),"") -> 0
B8: =IFERROR('Enter data'!$C$6,"") -> 0 | C8: =IFERROR(COUNT('Enter data'!$C$82:$C$111),"") -> 0 | D8: =IFERROR(AVERAGE('Enter data'!$C$82:$C$111),"") | E8: =IFERROR(STDEV('Enter data'!$C$82:$C$111),"") | F8: =IFERROR(STDEV('Enter data'!$C$82:$C$111)/SQRT(COUNT('Enter data'!$C$82:$C$111)),"") | G8: =IFERROR(MIN('Enter data'!$C$82:$C$111),"") -> 0 | H8: =IFERROR(MAX('Enter data'!$C$82:$C$111),"") -> 0
B9: =IFERROR('Enter data'!$D$6,"") -> 0 | C9: =IFERROR(COUNT('Enter data'!$C$117:$C$146),"") -> 0 | D9: =IFERROR(AVERAGE('Enter data'!$C$117:$C$146),"") | E9: =IFERROR(STDEV('Enter data'!$C$117:$C$146),"") | F9: =IFERROR(STDEV('Enter data'!$C$117:$C$146)/SQRT(COUNT('Enter data'!$C$117:$C$146)),"") | G9: =IFERROR(MIN('Enter data'!$C$117:$C$146),"") -> 0 | H9: =IFERROR(MAX('Enter data'!$C$117:$C$146),"") -> 0
B12: One-way analysis of variance
B13: Total observations | C13: =IFERROR(SUM($C$6:$C$9),"") -> 0
B14: Grand mean | C14: =IFERROR(SUMPRODUCT($C$6:$C$9,$D$6:$D$9)/$C$13,"")
B15: Sum of squares between groups | C15: =IFERROR(SUMPRODUCT($C$6:$C$9,($D$6:$D$9-$C$14)^2),"")
B16: Sum of squares within groups | C16: =IFERROR(SUMPRODUCT($C$6:$C$9-1,$E$6:$E$9^2),"")
B17: F ratio | C17: =IFERROR(($C$15/(4-1))/($C$16/($C$13-4)),"")
B18: p value | C18: =IFERROR(FDIST($C$17,4-1,$C$13-4),"")
B19: Pair (Welch t tests) | C19: Difference in means | D19: p (unadjusted) | E19: p (Bonferroni)
B20: =IFERROR('Enter data'!$A$6&" vs "&'Enter data'!$B$6,"") -> vs | C20: =IFERROR($D$6-$D$7,"") | D20: =IFERROR(TTEST('Enter data'!$C$12:$C$41,'Enter data'!$C$47:$C$76,2,3),"") | E20: =IFERROR(MIN(1,6*D20),"")
B21: =IFERROR('Enter data'!$A$6&" vs "&'Enter data'!$C$6,"") -> vs | C21: =IFERROR($D$6-$D$8,"") | D21: =IFERROR(TTEST('Enter data'!$C$12:$C$41,'Enter data'!$C$82:$C$111,2,3),"") | E21: =IFERROR(MIN(1,6*D21),"")
B22: =IFERROR('Enter data'!$A$6&" vs "&'Enter data'!$D$6,"") -> vs | C22: =IFERROR($D$6-$D$9,"") | D22: =IFERROR(TTEST('Enter data'!$C$12:$C$41,'Enter data'!$C$117:$C$146,2,3),"") | E22: =IFERROR(MIN(1,6*D22),"")
B23: =IFERROR('Enter data'!$B$6&" vs "&'Enter data'!$C$6,"") -> vs | C23: =IFERROR($D$7-$D$8,"") | D23: =IFERROR(TTEST('Enter data'!$C$47:$C$76,'Enter data'!$C$82:$C$111,2,3),"") | E23: =IFERROR(MIN(1,6*D23),"")
B24: =IFERROR('Enter data'!$B$6&" vs "&'Enter data'!$D$6,"") -> vs | C24: =IFERROR($D$7-$D$9,"") | D24: =IFERROR(TTEST('Enter data'!$C$47:$C$76,'Enter data'!$C$117:$C$146,2,3),"") | E24: =IFERROR(MIN(1,6*D24),"")
B25: =IFERROR('Enter data'!$C$6&" vs "&'Enter data'!$D$6,"") -> vs | C25: =IFERROR($D$8-$D$9,"") | D25: =IFERROR(TTEST('Enter data'!$C$82:$C$111,'Enter data'!$C$117:$C$146,2,3),"") | E25: =IFERROR(MIN(1,6*D25),"")
B28: Observer agreement
B29: Cells measured twice | C29: =IFERROR(SUMPRODUCT(--ISNUMBER('Enter data'!$A$152:$A$181),--ISNUMBER('Enter data'!$B$152:$B$181)),"") -> 0
B30: Mean difference (B minus A) | C30: =IFERROR(AVERAGE('Enter data'!$B$152:$B$181)-AVERAGE('Enter data'!$A$152:$A$181),"")
B31: Correlation between observers | C31: =IFERROR(CORREL('Enter data'!$A$152:$A$181,'Enter data'!$B$152:$B$181),"")
