Workbook

Sheet Start here
B1: ZOO-02 Gut length, diet, and body size in market fish
B2: Excel version of the card. It does the same calculations as the R script gut_length_analysis.R.
B4: How to use this workbook
B5: 1. Go to the 'Enter data' sheet. Type only in the yellow cells with blue text. Grey cells are calculated for you.
B6: 2. Fill the blocks that apply. Leave rows you did not use empty. The grey italic row above each table is an example of the format and is not used.
B7: 3. Open the 'Results' sheet. Everything there is calculated. Yellow cells on that sheet are settings you may change.
B9: What the colours mean
B10: Yellow cell, blue text: you type here.
B11: Grey cell: a formula. Sheets are protected without a password so formulas are not overwritten by accident (Review > Unprotect Sheet).
B13: Assumptions and sources
B14: Relative gut length = gut length / standard length. The fish is the replicate.
B16: Differences from the R script on the card
... B21: Compiled by Emmanuel G. Lozano, Department of Biology, College of Arts and Sciences, Pampanga State University. Original material is licensed CC BY-NC 4.0: credit required, non-commercial use only.

Sheet Enter data
A1: Enter your data
A2: Type only in yellow cells. Leave unused rows empty.
A4: 1. Species names
A5: Species 1 | B5: Species 2 | C5: Species 3
A6: species A | B6: species B | C6: species C
A9: 2. Fish of species 1
A10: Standard length (mm) | B10: Gut length (mm) | C10: Relative gut length
A11: 180 | B11: 468
A12: 206 | B12: 490 | C12: =IF(AND(ISNUMBER(A12),ISNUMBER(B12)),B12/A12,"") -> 2.3786408
A13: 224 | B13: 605 | C13: =IF(AND(ISNUMBER(A13),ISNUMBER(B13)),B13/A13,"") -> 2.7008929
A14: 116 | B14: 284 | C14: =IF(AND(ISNUMBER(A14),ISNUMBER(B14)),B14/A14,"") -> 2.4482759
A15: 177 | B15: 519 | C15: =IF(AND(ISNUMBER(A15),ISNUMBER(B15)),B15/A15,"") -> 2.9322034
A16: 205 | B16: 602 | C16: =IF(AND(ISNUMBER(A16),ISNUMBER(B16)),B16/A16,"") -> 2.9365854
A17: 214 | B17: 656 | C17: =IF(AND(ISNUMBER(A17),ISNUMBER(B17)),B17/A17,"") -> 3.0654206
A18: 196 | B18: 508 | C18: =IF(AND(ISNUMBER(A18),ISNUMBER(B18)),B18/A18,"") -> 2.5918367
A19: 217 | B19: 642 | C19: =IF(AND(ISNUMBER(A19),ISNUMBER(B19)),B19/A19,"") -> 2.9585253
A20: 187 | B20: 442 | C20: =IF(AND(ISNUMBER(A20),ISNUMBER(B20)),B20/A20,"") -> 2.3636364
A21: 194 | B21: 463 | C21: =IF(AND(ISNUMBER(A21),ISNUMBER(B21)),B21/A21,"") -> 2.3865979
A22: 184 | B22: 482 | C22: =IF(AND(ISNUMBER(A22),ISNUMBER(B22)),B22/A22,"") -> 2.6195652
A23: 153 | B23: 409 | C23: =IF(AND(ISNUMBER(A23),ISNUMBER(B23)),B23/A23,"") -> 2.6732026
C24: =IF(AND(ISNUMBER(A24),ISNUMBER(B24)),B24/A24,"")
C25: =IF(AND(ISNUMBER(A25),ISNUMBER(B25)),B25/A25,"")
C26: =IF(AND(ISNUMBER(A26),ISNUMBER(B26)),B26/A26,"")
A29: 3. Fish of species 2
A30: Standard length (mm) | B30: Gut length (mm) | C30: Relative gut length
A31: 180 | B31: 468
A32: 140 | B32: 192 | C32: =IF(AND(ISNUMBER(A32),ISNUMBER(B32)),B32/A32,"") -> 1.3714286
A33: 137 | B33: 179 | C33: =IF(AND(ISNUMBER(A33),ISNUMBER(B33)),B33/A33,"") -> 1.3065693
A34: 189 | B34: 280 | C34: =IF(AND(ISNUMBER(A34),ISNUMBER(B34)),B34/A34,"") -> 1.4814815
A35: 158 | B35: 222 | C35: =IF(AND(ISNUMBER(A35),ISNUMBER(B35)),B35/A35,"") -> 1.4050633
A36: 210 | B36: 269 | C36: =IF(AND(ISNUMBER(A36),ISNUMBER(B36)),B36/A36,"") -> 1.2809524
A37: 190 | B37: 319 | C37: =IF(AND(ISNUMBER(A37),ISNUMBER(B37)),B37/A37,"") -> 1.6789474
A38: 188 | B38: 254 | C38: =IF(AND(ISNUMBER(A38),ISNUMBER(B38)),B38/A38,"") -> 1.3510638
A39: 185 | B39: 256 | C39: =IF(AND(ISNUMBER(A39),ISNUMBER(B39)),B39/A39,"") -> 1.3837838
A40: 202 | B40: 294 | C40: =IF(AND(ISNUMBER(A40),ISNUMBER(B40)),B40/A40,"") -> 1.4554455
A41: 176 | B41: 289 | C41: =IF(AND(ISNUMBER(A41),ISNUMBER(B41)),B41/A41,"") -> 1.6420455
A42: 207 | B42: 285 | C42: =IF(AND(ISNUMBER(A42),ISNUMBER(B42)),B42/A42,"") -> 1.3768116
A43: 167 | B43: 250 | C43: =IF(AND(ISNUMBER(A43),ISNUMBER(B43)),B43/A43,"") -> 1.497006
C44: =IF(AND(ISNUMBER(A44),ISNUMBER(B44)),B44/A44,"")
C45: =IF(AND(ISNUMBER(A45),ISNUMBER(B45)),B45/A45,"")
...

Sheet Results
B1: Results
B2: Everything on this sheet is calculated. Change only the yellow settings.
B4: Relative gut length by species
B5: Group | C5: n | D5: Mean | E5: SD | F5: SE | G5: Min | H5: Max
B6: =IFERROR('Enter data'!$A$6,"") -> species A | C6: =IFERROR(COUNT('Enter data'!$C$12:$C$26),"") -> 12 | D6: =IFERROR(AVERAGE('Enter data'!$C$12:$C$26),"") -> 2.6712819 | E6: =IFERROR(STDEV('Enter data'!$C$12:$C$26),"") -> 0.25176611 | F6: =IFERROR(STDEV('Enter data'!$C$12:$C$26)/SQRT(COUNT('Enter data'!$C$12:$C$26)),"") -> 0.072678617 | G6: =IFERROR(MIN('Enter data'!$C$12:$C$26),"") -> 2.3636364 | H6: =IFERROR(MAX('Enter data'!$C$12:$C$26),"") -> 3.0654206
B7: =IFERROR('Enter data'!$B$6,"") -> species B | C7: =IFERROR(COUNT('Enter data'!$C$32:$C$46),"") -> 12 | D7: =IFERROR(AVERAGE('Enter data'!$C$32:$C$46),"") -> 1.4358832 | E7: =IFERROR(STDEV('Enter data'!$C$32:$C$46),"") -> 0.12321783 | F7: =IFERROR(STDEV('Enter data'!$C$32:$C$46)/SQRT(COUNT('Enter data'!$C$32:$C$46)),"") -> 0.035569924 | G7: =IFERROR(MIN('Enter data'!$C$32:$C$46),"") -> 1.2809524 | H7: =IFERROR(MAX('Enter data'!$C$32:$C$46),"") -> 1.6789474
B8: =IFERROR('Enter data'!$C$6,"") -> species C | C8: =IFERROR(COUNT('Enter data'!$C$52:$C$66),"") -> 12 | D8: =IFERROR(AVERAGE('Enter data'!$C$52:$C$66),"") -> 0.79814956 | E8: =IFERROR(STDEV('Enter data'!$C$52:$C$66),"") -> 0.079679509 | F8: =IFERROR(STDEV('Enter data'!$C$52:$C$66)/SQRT(COUNT('Enter data'!$C$52:$C$66)),"") -> 0.023001493 | G8: =IFERROR(MIN('Enter data'!$C$52:$C$66),"") -> 0.64788732 | H8: =IFERROR(MAX('Enter data'!$C$52:$C$66),"") -> 0.91747573
B11: One-way analysis of variance
B12: Total observations | C12: =IFERROR(SUM($C$6:$C$8),"") -> 36
B13: Grand mean | C13: =IFERROR(SUMPRODUCT($C$6:$C$8,$D$6:$D$8)/$C$12,"") -> 1.6351049
B14: Sum of squares between groups | C14: =IFERROR(SUMPRODUCT($C$6:$C$8,($D$6:$D$8-$C$13)^2),"") -> 21.766156
B15: Sum of squares within groups | C15: =IFERROR(SUMPRODUCT($C$6:$C$8-1,$E$6:$E$8^2),"") -> 0.93409398
B16: F ratio | C16: =IFERROR(($C$14/(3-1))/($C$15/($C$12-3)),"") -> 384.4812
B17: p value | C17: =IFERROR(FDIST($C$16,3-1,$C$12-3),"") -> 1.3706888e-23
B18: Pair (Welch t tests) | C18: Difference in means | D18: p (unadjusted) | E18: p (Bonferroni)
B19: =IFERROR('Enter data'!$A$6&" vs "&'Enter data'!$B$6,"") -> species A vs species B | C19: =IFERROR($D$6-$D$7,"") -> 1.2353987 | D19: =IFERROR(TTEST('Enter data'!$C$12:$C$26,'Enter data'!$C$32:$C$46,2,3),"") -> 5.9490486e-11 | E19: =IFERROR(MIN(1,3*D19),"") -> 1.7847146e-10
B20: =IFERROR('Enter data'!$A$6&" vs "&'Enter data'!$C$6,"") -> species A vs species C | C20: =IFERROR($D$6-$D$8,"") -> 1.8731324 | D20: =IFERROR(TTEST('Enter data'!$C$12:$C$26,'Enter data'!$C$52:$C$66,2,3),"") -> 2.1344433e-12 | E20: =IFERROR(MIN(1,3*D20),"") -> 6.4033299e-12
B21: =IFERROR('Enter data'!$B$6&" vs "&'Enter data'!$C$6,"") -> species B vs species C | C21: =IFERROR($D$7-$D$8,"") -> 0.63773366 | D21: =IFERROR(TTEST('Enter data'!$C$32:$C$46,'Enter data'!$C$52:$C$66,2,3),"") -> 5.9521432e-12 | E21: =IFERROR(MIN(1,3*D21),"") -> 1.785643e-11
B24: Relative gut length against standard length within each species
B25: Species | C25: Correlation | D25: Fish | E25: t | F25: p
B26: =IFERROR(IF('Enter data'!$A$6="","",'Enter data'!$A$6),"") -> species A | C26: =IFERROR(CORREL('Enter data'!$A$12:$A$26,'Enter data'!$C$12:$C$26),"") -> 0.36050499 | D26: =IFERROR(COUNT('Enter data'!$C$12:$C$26),"") -> 12 | E26: =IFERROR(C26*SQRT((D26-2)/(1-C26^2)),"") -> 1.222201 | F26: =IFERROR(TDIST(ABS(E26),D26-2,2),"") -> 0.24965762
B27: =IFERROR(IF('Enter data'!$B$6="","",'Enter data'!$B$6),"") -> species B | C27: =IFERROR(CORREL('Enter data'!$A$32:$A$46,'Enter data'!$C$32:$C$46),"") -> 0.09983245 | D27: =IFERROR(COUNT('Enter data'!$C$32:$C$46),"") -> 12 | E27: =IFERROR(C27*SQRT((D27-2)/(1-C27^2)),"") -> 0.31728299 | F27: =IFERROR(TDIST(ABS(E27),D27-2,2),"") -> 0.75755422
B28: =IFERROR(IF('Enter data'!$C$6="","",'Enter data'!$C$6),"") -> species C | C28: =IFERROR(CORREL('Enter data'!$A$52:$A$66,'Enter data'!$C$52:$C$66),"") -> 0.45189152 | D28: =IFERROR(COUNT('Enter data'!$C$52:$C$66),"") -> 12 | E28: =IFERROR(C28*SQRT((D28-2)/(1-C28^2)),"") -> 1.6018943 | F28: =IFERROR(TDIST(ABS(E28),D28-2,2),"") -> 0.14026149
